Workbook

Sheet Teams
A2: Selecties | B2: S1S2 | G2: =AVERAGE(D4:D22,G4:G22) -> #DIV/0! | I2: JOW | N2: =AVERAGE(K4:K22,N4:N22) -> #DIV/0! | P2: A1A2 | U2: =AVERAGE(R4:R22,U4:U22) -> #DIV/0!
B3: =CONCATENATE("Dames (",COUNTA(C4:C19),")") -> Dames (1) | E3: =CONCATENATE("Heren (",COUNTA(F4:F19),")") -> Heren (1) | I3: =CONCATENATE("Dames (",COUNTA(J4:J19),")") -> Dames (1) | L3: =CONCATENATE("Heren (",COUNTA(M4:M19),")") -> Heren (1) | P3: =CONCATENATE("Dames (",COUNTA(Q4:Q19),")") -> Dames (1) | S3: =CONCATENATE("Heren (",COUNTA(T4:T19),")") -> Heren (1)
B4: {=_xlfn._xlws.FILTER(Spelerslijst!$B:$B,Spelerslijst!$G:$G=B$2,"")} | C4: {=_xlfn._xlws.FILTER(Spelerslijst!$C:$C,Spelerslijst!$G:$G=B$2,"")} | D4: {=_xlfn._xlws.FILTER(Spelerslijst!$D:$D,Spelerslijst!$G:$G=B$2,"")} | E4: {=_xlfn._xlws.FILTER(Spelerslijst!$K:$K,Spelerslijst!$P:$P=B$2,"")} | F4: {=_xlfn._xlws.FILTER(Spelerslijst!$L:$L,Spelerslijst!$P:$P=B$2,"")} | G4: {=_xlfn._xlws.FILTER(Spelerslijst!$M:$M,Spelerslijst!$P:$P=B$2,"")} | I4: {=_xlfn._xlws.FILTER(Spelerslijst!$B:$B,Spelerslijst!$G:$G=I$2,"")} | J4: {=_xlfn._xlws.FILTER(Spelerslijst!$C:$C,Spelerslijst!$G:$G=I$2,"")} | K4: {=_xlfn._xlws.FILTER(Spelerslijst!$D:$D,Spelerslijst!$G:$G=I$2,"")} | L4: {=_xlfn._xlws.FILTER(Spelerslijst!$K:$K,Spelerslijst!$P:$P=I$2,"")} | M4: {=_xlfn._xlws.FILTER(Spelerslijst!$L:$L,Spelerslijst!$P:$P=I$2,"")} | N4: {=_xlfn._xlws.FILTER(Spelerslijst!$M:$M,Spelerslijst!$P:$P=I$2,"")} | P4: {=_xlfn._xlws.FILTER(Spelerslijst!$B:$B,Spelerslijst!$G:$G=P$2,"")} | Q4: {=_xlfn._xlws.FILTER(Spelerslijst!$C:$C,Spelerslijst!$G:$G=P$2,"")} | R4: {=_xlfn._xlws.FILTER(Spelerslijst!$D:$D,Spelerslijst!$G:$G=P$2,"")} | S4: {=_xlfn._xlws.FILTER(Spelerslijst!$K:$K,Spelerslijst!$P:$P=P$2,"")} | T4: {=_xlfn._xlws.FILTER(Spelerslijst!$L:$L,Spelerslijst!$P:$P=P$2,"")} | U4: {=_xlfn._xlws.FILTER(Spelerslijst!$M:$M,Spelerslijst!$P:$P=P$2,"")}
B20: {=_xlfn._xlws.FILTER(Staf!$C:$C,Staf!$B:$B=Teams!B2,"")} | C20: {=_xlfn._xlws.FILTER(Staf!$A:$A,Staf!$B:$B=Teams!B2,"")} | I20: {=_xlfn._xlws.FILTER(Staf!$C:$C,Staf!$B:$B=Teams!I2,"")} | J20: {=_xlfn._xlws.FILTER(Staf!$A:$A,Staf!$B:$B=Teams!I2,"")} | P20: {=_xlfn._xlws.FILTER(Staf!$C:$C,Staf!$B:$B=Teams!P2,"")} | Q20: {=_xlfn._xlws.FILTER(Staf!$A:$A,Staf!$B:$B=Teams!P2,"")}
A27: Senioren | B27: S1 | G27: =AVERAGE(D29:D38,G29:G38) -> 24 | I27: S2 | N27: =AVERAGE(K29:K38,N29:N38) -> 22.454545 | P27: S3 | U27: =AVERAGE(R29:R38,U29:U38) -> 29.1 | W27: S4 | AB27: =AVERAGE(Y29:Y38,AB29:AB38) -> 36.727273 | AD27: S5 | AI27: =AVERAGE(AF29:AF38,AI29:AI38) -> 21.888889 | AK27: S6 | AP27: =AVERAGE(AM29:AM38,AP29:AP38) -> 19.5 | AR27: S7 | AW27: =AVERAGE(AT29:AT38,AW29:AW38) -> 20 | AY27: MW1 | BD27: =AVERAGE(BA29:BA38,BD29:BD38) -> 42.833333
B28: =CONCATENATE("Dames (",COUNTA(C29:C36),")") -> Dames (5) | E28: =CONCATENATE("Heren (",COUNTA(F29:F36),")") -> Heren (5) | I28: =CONCATENATE("Dames (",COUNTA(J29:J36),")") -> Dames (5) | L28: =CONCATENATE("Heren (",COUNTA(M29:M36),")") -> Heren (6) | P28: =CONCATENATE("Dames (",COUNTA(Q29:Q36),")") -> Dames (5) | S28: =CONCATENATE("Heren (",COUNTA(T29:T36),")") -> Heren (5) | W28: =CONCATENATE("Dames (",COUNTA(X29:X36),")") -> Dames (5) | Z28: =CONCATENATE("Heren (",COUNTA(AA29:AA36),")") -> Heren (6) | AD28: =CONCATENATE("Dames (",COUNTA(AE29:AE36),")") -> Dames (5) | AG28: =CONCATENATE("Heren (",COUNTA(AH29:AH36),")") -> Heren (4) | AK28: =CONCATENATE("Dames (",COUNTA(AL29:AL36),")") -> Dames (6) | AN28: =CONCATENATE("Heren (",COUNTA(AO29:AO36),")") -> Heren (4) | AR28: =CONCATENATE("Dames (",COUNTA(AS29:AS36),")") -> Dames (6) | AU28: =CONCATENATE("Heren (",COUNTA(AV29:AV36),")") -> Heren (3) | AY28: =CONCATENATE("Dames (",COUNTA(AZ29:AZ36),")") -> Dames (6) | BB28: =CONCATENATE("Heren (",COUNTA(BC29:BC36),")") -> Heren (6)
B29: {=_xlfn._xlws.FILTER(Spelerslijst!$B:$B,Spelerslijst!$G:$G=B$27,"")} -> Broere, D. | C29: {=_xlfn._xlws.FILTER(Spelerslijst!$C:$C,Spelerslijst!$G:$G=B$27,"")} -> Dionne | D29: {=_xlfn._xlws.FILTER(Spelerslijst!$D:$D,Spelerslijst!$G:$G=B$27,"")} -> 22 | E29: {=_xlfn._xlws.FILTER(Spelerslijst!$K:$K,Spelerslijst!$P:$P=B$27,"")} -> Driesprong, B. | F29: {=_xlfn._xlws.FILTER(Spelerslijst!$L:$L,Spelerslijst!$P:$P=B$27,"")} -> Bart | G29: {=_xlfn._xlws.FILTER(Spelerslijst!$M:$M,Spelerslijst!$P:$P=B$27,"")} -> 23 | I29: {=_xlfn._xlws.FILTER(Spelerslijst!$B:$B,Spelerslijst!$G:$G=I$27,"")} -> Dijk, van D. | J29: {=_xlfn._xlws.FILTER(Spelerslijst!$C:$C,Spelerslijst!$G:$G=I$27,"")} -> Demi | K29: {=_xlfn._xlws.FILTER(Spelerslijst!$D:$D,Spelerslijst!$G:$G=I$27,"")} -> 20 | L29: {=_xlfn._xlws.FILTER(Spelerslijst!$K:$K,Spelerslijst!$P:$P=I$27,"")} -> Dijk, van J. | M29: {=_xlfn._xlws.FILTER(Spelerslijst!$L:$L,Spelerslijst!$P:$P=I$27,"")} -> Joeri | N29: {=_xlfn._xlws.FILTER(Spelerslijst!$M:$M,Spelerslijst!$P:$P=I$27,"")} -> 23 | P29: {=_xlfn._xlws.FILTER(Spelerslijst!$B:$B,Spelerslijst!$G:$G=P$27,"")} -> Ardon, E. | Q29: {=_xlfn._xlws.FILTER(Spelerslijst!$C:$C,Spelerslijst!$G:$G=P$27,"")} -> Esther | R29: {=_xlfn._xlws.FILTER(Spelerslijst!$D:$D,Spelerslijst!$G:$G=P$27,"")} -> 25 | S29: {=_xlfn._xlws.FILTER(Spelerslijst!$K:$K,Spelerslijst!$P:$P=P$27,"")} -> Booy, J | T29: {=_xlfn._xlws.FILTER(Spelerslijst!$L:$L,Spelerslijst!$P:$P=P$27,"")} -> Jan | U29: {=_xlfn._xlws.FILTER(Spelerslijst!$M:$M,Spelerslijst!$P:$P=P$27,"")} -> 31 | W29: {=_xlfn._xlws.FILTER(Spelerslijst!$B:$B,Spelerslijst!$G:$G=W$27,"")} -> Assem, van den L. | X29: {=_xlfn._xlws.FILTER(Spelerslijst!$C:$C,Spelerslijst!$G:$G=W$27,"")} -> Lisette | Y29: {=_xlfn._xlws.FILTER(Spelerslijst!$D:$D,Spelerslijst!$G:$G=W$27,"")} -> 38 | Z29: {=_xlfn._xlws.FILTER(Spelerslijst!$K:$K,Spelerslijst!$P:$P=W$27,"")} -> Boshoven, D. | AA29: {=_xlfn._xlws.FILTER(Spelerslijst!$L:$L,Spelerslijst!$P:$P=W$27,"")} -> Davy | AB29: {=_xlfn._xlws.FILTER(Spelerslijst!$M:$M,Spelerslijst!$P:$P=W$27,"")} -> 46 | AD29: {=_xlfn._xlws.FILTER(Spelerslijst!$B:$B,Spelerslijst!$G:$G=AD$27,"")} -> Bax, E. S. | AE29: {=_xlfn._xlws.FILTER(Spelerslijst!$C:$C,Spelerslijst!$G:$G=AD$27,"")} -> Erinn | AF29: {=_xlfn._xlws.FILTER(Spelerslijst!$D:$D,Spelerslijst!$G:$G=AD$27,"")} -> 23 | AG29: {=_xlfn._xlws.FILTER(Spelerslijst!$K:$K,Spelerslijst!$P:$P=AD$27,"")} -> Driel, van Q. | AH29: {=_xlfn._xlws.FILTER(Spelerslijst!$L:$L,Spelerslijst!$P:$P=AD$27,"")} -> Quinten | AI29: {=_xlfn._xlws.FILTER(Spelerslijst!$M:$M,Spelerslijst!$P:$P=AD$27,"")} -> 21 | AK29: {=_xlfn._xlws.FILTER(Spelerslijst!$B:$B,Spelerslijst!$G:$G=AK$27,"")} -> Dubbeld, S. | AL29: {=_xlfn._xlws.FILTER(Spelerslijst!$C:$C,Spelerslijst!$G:$G=AK$27,"")} -> Sanne | AM29: {=_xlfn._xlws.FILTER(Spelerslijst!$D:$D,Spelerslijst!$G:$G=AK$27,"")} -> 19 | AN29: {=_xlfn._xlws.FILTER(Spelerslijst!$K:$K,Spelerslijst!$P:$P=AK$27,"")} -> Baars, L.A. | AO29: {=_xlfn._xlws.FILTER(Spelerslijst!$L:$L,Spelerslijst!$P:$P=AK$27,"")} -> Luuk | AP29: {=_xlfn._xlws.FILTER(Spelerslijst!$M:$M,Spelerslijst!$P:$P=AK$27,"")} -> 20 | AR29: {=_xlfn._xlws.FILTER(Spelerslijst!$B:$B,Spelerslijst!$G:$G=AR$27,"")} -> Koote, L.D. | AS29: {=_xlfn._xlws.FILTER(Spelerslijst!$C:$C,Spelerslijst!$G:$G=AR$27,"")} -> Laura | AT29: {=_xlfn._xlws.FILTER(Spelerslijst!$D:$D,Spelerslijst!$G:$G=AR$27,"")} -> 19 | AU29: {=_xlfn._xlws.FILTER(Spelerslijst!$K:$K,Spelerslijst!$P:$P=AR$27,"")} -> Flach, J.H. | AV29: {=_xlfn._xlws.FILTER(Spelerslijst!$L:$L,Spelerslijst!$P:$P=AR$27,"")} -> Joram | AW29: {=_xlfn._xlws.FILTER(Spelerslijst!$M:$M,Spelerslijst!$P:$P=AR$27,"")} -> 22 | AY29: {=_xlfn._xlws.FILTER(Spelerslijst!$B:$B,Spelerslijst!$G:$G=AY$27,"")} -> Camphens-Moerman, B. | AZ29: {=_xlfn._xlws.FILTER(Spelerslijst!$C:$C,Spelerslijst!$G:$G=AY$27,"")} -> Barbara | BA29: {=_xlfn._xlws.FILTER(Spelerslijst!$D:$D,Spelerslijst!$G:$G=AY$27,"")} -> 40 | BB29: {=_xlfn._xlws.FILTER(Spelerslijst!$K:$K,Spelerslijst!$P:$P=AY$27,"")} -> Verwaal, J.P. | BC29: {=_xlfn._xlws.FILTER(Spelerslijst!$L:$L,Spelerslijst!$P:$P=AY$27,"")} -> Jan-Peter | BD29: {=_xlfn._xlws.FILTER(Spelerslijst!$M:$M,Spelerslijst!$P:$P=AY$27,"")} -> 52
B30: Dommisse, R. | C30: Robin | D30: 23 | E30: Gent, van L | F30: Lex | G30: 26 | I30: Oppe, M. | J30: Milou | K30: 19 | L30: Gent, van T. | M30: Tim | N30: 21 | P30: Ardon, L | Q30: Linda | R30: 29 | S30: Brugge, van der B.R. | T30: Bart | U30: 26 | W30: Laban-Sinke, I.W. | X30: Ingrid | Y30: 36 | Z30: Jong, de B. | AA30: Bas | AB30: 31 | AD30: Lacroes, M.J. | AE30: Jany | AF30: 23 | AG30: Dubbeld, R. | AH30: Ruben | AI30: 21 | AK30: Dubbeld, T. | AL30: Tessa | AM30: 21 | AN30: Boon, T. | AO30: Thijs | AP30: 18 | AR30: Pierse, A. | AS30: Anniek | AT30: 19 | AU30: Schindler, M. | AV30: Mark | AW30: 22 | AY30: Everaarts, D. | AZ30: Damaris | BA30: 42 | BB30: Belder, E. | BC30: Erwin | BD30: 44
B31: Klink, X | C31: Xanne | D31: 26 | E31: Klink, M | F31: Marijn | G31: 24 | I31: Schram, M.C. | J31: Merel | K31: 22 | L31: Groeneweg, T.D. | M31: Tim | N31: 20 | P31: Gurp, van M | Q31: Merel | R31: 29 | S31: Huijgen, J | T31: Jeroen | U31: 25 | W31: Noordam, M. | X31: Mirjam | Y31: 34 | Z31: Kuperus, S. | AA31: Steven | AB31: 31 | AD31: Schram, L.J. | AE31: Lara | AF31: 21 | AG31: Jong, de I.J. | AH31: Jouke | AI31: 23 | AK31: Friebel, A. | AL31: Angela | AM31: 19 | AN31: Klijn, C.L. | AO31: Calvin | AP31: 21 | AR31: Valk, M.E. | AS31: Marlies | AT31: 18 | AU31: Wijgaart, van de R.L.H. | AV31: Rick | AW31: 18 | AY31: Opstal-Haksteen, van T.K. | AZ31: Tamara | BA31: 33 | BB31: Jong, 't M. | BC31: Michiel | BD31: 40
B32: Seevinck, D. | C32: Djuna | D32: 20 | E32: Lansbergen, M | F32: Matthijs | G32: 31 | I32: Teerds, E.L. | J32: Eva | K32: 19 | L32: Kalkeren, van R. | M32: Robin | N32: 25 | P32: Leijdsman, R. | Q32: Robin | R32: 25 | S32: Isarin, T P | T32: Thomas | U32: 33 | W32: Ploeg, L | X32: Lieke | Y32: 35 | Z32: Laban, A.J. | AA32: Antjan | AB32: 41 | AD32: Slotboom, A. | AE32: Amber | AF32: 20 | AG32: Wolff, A. | AH32: Alexander | AI32: 25 | AK32: Hulsker, N.M. | AL32: Nina | AM32: 22 | AN32: Vlaming, de J.C. | AO32: Jens | AP32: 18 | AR32: Wit, de N.M.T. | AS32: Nadia | AT32: 20 | AY32: Veld, in 't D. | AZ32: Dorien | BA32: 36 | BB32: Kalkeren, van M. | BC32: Marco | BD32: 52
B33: Verweij, M. | C33: Mirthe | D33: 27 | E33: Oppe, M. | F33: Mees | G33: 18 | I33: Visser, R. | J33: Renske | K33: 23 | L33: Mans, B. | M33: Bob | N33: 25 | P33: Hussein, N. | Q33: Nada | R33: 31 | S33: Vlaming, de R. | T33: Roy | U33: 37 | W33: Wibbens, E. | X33: Esther | Y33: 29 | Z33: Noels, A. | AA33: Arjan | AB33: 41 | AD33: Dommisse, K. | AE33: Kim | AF33: 20 | AK33: Klink, S.L. | AL33: Suzanne | AM33: 18 | AR33: Wit, de S.E.E. | AS33: Syrah | AT33: 20 | AY33: Verheijde, P. | AZ33: Petra | BA33: 47 | BB33: Kooij, C.W. | BC33: Wilco | BD33: 46
L34: Naaktgeboren, S. | M34: Stefan | N34: 30 | Z34: Wit, de B. | AA34: Bart | AB34: 42 | AK34: Van der Laars, L. | AL34: Laura | AM34: 19 | AR34: Cetinkaya Vurel, B. | AS34: Billur | AT34: 22 | AY34: Zwanenburg-Moerman, D. | AZ34: Debita | BA34: 44 | BB34: Riet, R. | BC34: Ronald | BD34: 38
B37: {=_xlfn._xlws.FILTER(Staf!$C:$C,Staf!$B:$B=Teams!B27,"")} -> Coach S1 | C37: {=_xlfn._xlws.FILTER(Staf!$A:$A,Staf!$B:$B=Teams!B27,"")} -> Lion van der Klooster | I37: {=_xlfn._xlws.FILTER(Staf!$C:$C,Staf!$B:$B=Teams!I27,"")} -> Coach S2 | J37: {=_xlfn._xlws.FILTER(Staf!$A:$A,Staf!$B:$B=Teams!I27,"")} -> Erik vd Burgt | P37: {=_xlfn._xlws.FILTER(Staf!$C:$C,Staf!$B:$B=Teams!P27,"")} -> Begeleider | Q37: {=_xlfn._xlws.FILTER(Staf!$A:$A,Staf!$B:$B=Teams!P27,"")} -> Kim Ardon | W37: {=_xlfn._xlws.FILTER(Staf!$C:$C,Staf!$B:$B=Teams!W27,"")} -> Thuiscoach | X37: {=_xlfn._xlws.FILTER(Staf!$A:$A,Staf!$B:$B=Teams!W27,"")} -> Marco van Kalkeren | AD37: {=_xlfn._xlws.FILTER(Staf!$C:$C,Staf!$B:$B=Teams!AD27,"")} | AE37: {=_xlfn._xlws.FILTER(Staf!$A:$A,Staf!$B:$B=Teams!AD27,"")} | AK37: {=_xlfn._xlws.FILTER(Staf!$C:$C,Staf!$B:$B=Teams!AK27,"")} | AL37: {=_xlfn._xlws.FILTER(Staf!$A:$A,Staf!$B:$B=Teams!AK27,"")} | AR37: {=_xlfn._xlws.FILTER(Staf!$C:$C,Staf!$B:$B=Teams!AR27,"")} | AS37: {=_xlfn._xlws.FILTER(Staf!$A:$A,Staf!$B:$B=Teams!AR27,"")} | AY37: {=_xlfn._xlws.FILTER(Staf!$C:$C,Staf!$B:$B=Teams!AY27,"")} | AZ37: {=_xlfn._xlws.FILTER(Staf!$A:$A,Staf!$B:$B=Teams!AY27,"")}
B38: Assistent S1 | C38: Niels Molendijk
B39: Fysio | C39: Ruben Kamerbeek
B40: Verzorger | C40: Theo Anrochte
A41: A-Junioren | B41: A1 | G41: =AVERAGE(D43:D53,G43:G53) -> 17.6 | I41: A2 | N41: =AVERAGE(K43:K53,N43:N53) -> 16.8 | P41: A3 | U41: =AVERAGE(R43:R53,U43:U53) -> 16.083333 | W41: A4 | AB41: =AVERAGE(Y43:Y53,AB43:AB53) -> 17 | AD41: A5 | AI41: =AVERAGE(AF43:AF53,AI43:AI53) -> #DIV/0!
B42: =CONCATENATE("Dames (",COUNTA(C43:C51),")") -> Dames (5) | E42: =CONCATENATE("Heren (",COUNTA(F43:F51),")") -> Heren (5) | I42: =CONCATENATE("Dames (",COUNTA(J43:J51),")") -> Dames (5) | L42: =CONCATENATE("Heren (",COUNTA(M43:M51),")") -> Heren (5) | P42: =CONCATENATE("Dames (",COUNTA(Q43:Q51),")") -> Dames (9) | S42: =CONCATENATE("Heren (",COUNTA(T43:T51),")") -> Heren (3) | W42: =CONCATENATE("Dames (",COUNTA(X43:X51),")") -> Dames (4) | Z42: =CONCATENATE("Heren (",COUNTA(AA43:AA51),")") -> Heren (4) | AD42: =CONCATENATE("Dames (",COUNTA(AE43:AE51),")") -> Dames (1) | AG42: =CONCATENATE("Heren (",COUNTA(AH43:AH51),")") -> Heren (1)
B43: {=_xlfn._xlws.FILTER(Spelerslijst!$B:$B,Spelerslijst!$G:$G=B$41,"")} -> Driesprong, M. | C43: {=_xlfn._xlws.FILTER(Spelerslijst!$C:$C,Spelerslijst!$G:$G=B$41,"")} -> Meike | D43: {=_xlfn._xlws.FILTER(Spelerslijst!$D:$D,Spelerslijst!$G:$G=B$41,"")} -> 17 | E43: {=_xlfn._xlws.FILTER(Spelerslijst!$K:$K,Spelerslijst!$P:$P=B$41,"")} -> Alberts, S. | F43: {=_xlfn._xlws.FILTER(Spelerslijst!$L:$L,Spelerslijst!$P:$P=B$41,"")} -> Sem | G43: {=_xlfn._xlws.FILTER(Spelerslijst!$M:$M,Spelerslijst!$P:$P=B$41,"")} -> 17 | I43: {=_xlfn._xlws.FILTER(Spelerslijst!$B:$B,Spelerslijst!$G:$G=I$41,"")} -> Boshoven, S.A.E. | J43: {=_xlfn._xlws.FILTER(Spelerslijst!$C:$C,Spelerslijst!$G:$G=I$41,"")} -> Sara | K43: {=_xlfn._xlws.FILTER(Spelerslijst!$D:$D,Spelerslijst!$G:$G=I$41,"")} -> 16 | L43: {=_xlfn._xlws.FILTER(Spelerslijst!$K:$K,Spelerslijst!$P:$P=I$41,"")} -> Fasbender, T. | M43: {=_xlfn._xlws.FILTER(Spelerslijst!$L:$L,Spelerslijst!$P:$P=I$41,"")} -> Tijmen | N43: {=_xlfn._xlws.FILTER(Spelerslijst!$M:$M,Spelerslijst!$P:$P=I$41,"")} -> 18 | P43: {=_xlfn._xlws.FILTER(Spelerslijst!$B:$B,Spelerslijst!$G:$G=P$41,"")} -> Boeije, A.J. | Q43: {=_xlfn._xlws.FILTER(Spelerslijst!$C:$C,Spelerslijst!$G:$G=P$41,"")} -> Amber | R43: {=_xlfn._xlws.FILTER(Spelerslijst!$D:$D,Spelerslijst!$G:$G=P$41,"")} -> 16 | S43: {=_xlfn._xlws.FILTER(Spelerslijst!$K:$K,Spelerslijst!$P:$P=P$41,"")} -> IJben, C. | T43: {=_xlfn._xlws.FILTER(Spelerslijst!$L:$L,Spelerslijst!$P:$P=P$41,"")} -> Chris | U43: {=_xlfn._xlws.FILTER(Spelerslijst!$M:$M,Spelerslijst!$P:$P=P$41,"")} -> 16 | W43: {=_xlfn._xlws.FILTER(Spelerslijst!$B:$B,Spelerslijst!$G:$G=W$41,"")} -> Degenhardt, K | X43: {=_xlfn._xlws.FILTER(Spelerslijst!$C:$C,Spelerslijst!$G:$G=W$41,"")} -> Kim | Y43: {=_xlfn._xlws.FILTER(Spelerslijst!$D:$D,Spelerslijst!$G:$G=W$41,"")} -> 17 | Z43: {=_xlfn._xlws.FILTER(Spelerslijst!$K:$K,Spelerslijst!$P:$P=W$41,"")} -> Everaarts, J.D. | AA43: {=_xlfn._xlws.FILTER(Spelerslijst!$L:$L,Spelerslijst!$P:$P=W$41,"")} -> Jesse | AB43: {=_xlfn._xlws.FILTER(Spelerslijst!$M:$M,Spelerslijst!$P:$P=W$41,"")} -> 17 | AD43: {=_xlfn._xlws.FILTER(Spelerslijst!$B:$B,Spelerslijst!$G:$G=AD$41,"")} | AE43: {=_xlfn._xlws.FILTER(Spelerslijst!$C:$C,Spelerslijst!$G:$G=AD$41,"")} | AF43: {=_xlfn._xlws.FILTER(Spelerslijst!$D:$D,Spelerslijst!$G:$G=AD$41,"")} | AG43: {=_xlfn._xlws.FILTER(Spelerslijst!$K:$K,Spelerslijst!$P:$P=AD$41,"")} | AH43: {=_xlfn._xlws.FILTER(Spelerslijst!$L:$L,Spelerslijst!$P:$P=AD$41,"")} | AI43: {=_xlfn._xlws.FILTER(Spelerslijst!$M:$M,Spelerslijst!$P:$P=AD$41,"")}
B44: Fernhout, L. | C44: Loïs | D44: 18 | E44: Hoeve, ten M. | F44: Milan | G44: 18 | I44: Gent, van E. | J44: Elsemieke | K44: 17 | L44: Kuijper, D.V. | M44: David | N44: 18 | P44: Fasbender, L. | Q44: Lindi | R44: 16 | S44: Koornneef, W.J. | T44: Wouter | U44: 16 | W44: Dekker, D. | X44: Daniëlle | Y44: 17 | Z44: Klein, D.H. | AA44: Daan | AB44: 16
B45: Horst, ter B.A. | C45: Bridget | D45: 18 | E45: Hooijdonk, van O. | F45: Otte | G45: 18 | I45: Groeneweg, R.K. | J45: Roos | K45: 16 | L45: Lohuis, J.A. | M45: Jens | N45: 16 | P45: Horst, ter R.N. | Q45: Renee | R45: 16 | S45: Meijer, J.H. | T45: Joeke | U45: 16 | W45: Herremans, J. | X45: Jennifer | Y45: 18 | Z45: Lange, M.J.D. | AA45: Mathijs | AB45: 17
B46: Verbeek, Y. | C46: Yente | D46: 17 | E46: Timmer, J. | F46: Jordan | G46: 17 | I46: Mol, L.N.A. | J46: Laura | K46: 17 | L46: Seevinck, T. | M46: Tim | N46: 18 | P46: Jongh, de A. | Q46: Anouk | R46: 16 | W46: Witman, K. | X46: Kimberley | Y46: 17 | Z46: Verhagen, L.A.J. | AA46: Laurens | AB46: 17
B47: Volker, L.A. | C47: Lisa | D47: 18 | E47: Uijl, den D. | F47: Daniel | G47: 18 | I47: Wensen, van M. | J47: Maud | K47: 16 | L47: Wietses, J. | M47: Joël | N47: 16 | P47: Lievaart, C.A. | Q47: Carlijn | R47: 17
P48: Quarré, E.A. | Q48: Elena | R48: 16
P49: Raab, I.A.S. | Q49: Ilse | R49: 16
P50: Reus, de K. | Q50: Kim | R50: 17
P51: Wijngaarden, van B.D. | Q51: Bente | R51: 15
B52: {=_xlfn._xlws.FILTER(Staf!$C:$C,Staf!$B:$B=Teams!B41,"")} -> Coach A1 | C52: {=_xlfn._xlws.FILTER(Staf!$A:$A,Staf!$B:$B=Teams!B41,"")} -> Mark Morelissen | I52: {=_xlfn._xlws.FILTER(Staf!$C:$C,Staf!$B:$B=Teams!I41,"")} -> Coach A2 | J52: {=_xlfn._xlws.FILTER(Staf!$A:$A,Staf!$B:$B=Teams!I41,"")} -> Ruben Blokland | P52: {=_xlfn._xlws.FILTER(Staf!$C:$C,Staf!$B:$B=Teams!P41,"")} -> Trainer/Coach | Q52: {=_xlfn._xlws.FILTER(Staf!$A:$A,Staf!$B:$B=Teams!P41,"")} -> Olivier Klink | W52: {=_xlfn._xlws.FILTER(Staf!$C:$C,Staf!$B:$B=Teams!W41,"")} -> Trainer/Coach | X52: {=_xlfn._xlws.FILTER(Staf!$A:$A,Staf!$B:$B=Teams!W41,"")} -> Lex van Dalen | AD52: {=_xlfn._xlws.FILTER(Staf!$C:$C,Staf!$B:$B=Teams!AD41,"")} | AE52: {=_xlfn._xlws.FILTER(Staf!$A:$A,Staf!$B:$B=Teams!AD41,"")}
B53: Assistent A1 | C53: Ruben Blokland | P53: Trainer/Coach | Q53: Tim van Gent | W53: Trainer/Coach | X53: Robbert van Ameijden
A56: B-Aspiranten | B56: B1 | G56: =AVERAGE(D58:D67,G58:G67) -> 14.4 | I56: B2 | N56: =AVERAGE(K58:K67,N58:N67) -> 14 | P56: B3 | U56: =AVERAGE(R58:R67,U58:U67) -> 13.8 | W56: B4 | AB56: =AVERAGE(Y58:Y67,AB58:AB67) -> #DIV/0! | AD56: B5 | AH56: B5 | AI56: =AVERAGE(AF58:AF67,AI58:AI67) -> #DIV/0!
B57: =CONCATENATE("Dames (",COUNTA(C58:C65),")") -> Dames (5) | E57: =CONCATENATE("Heren (",COUNTA(F58:F65),")") -> Heren (5) | I57: =CONCATENATE("Dames (",COUNTA(J58:J65),")") -> Dames (5) | L57: =CONCATENATE("Heren (",COUNTA(M58:M65),")") -> Heren (4) | P57: =CONCATENATE("Dames (",COUNTA(Q58:Q65),")") -> Dames (3) | S57: =CONCATENATE("Heren (",COUNTA(T58:T65),")") -> Heren (7) | W57: =CONCATENATE("Dames (",COUNTA(X58:X65),")") -> Dames (1) | Z57: =CONCATENATE("Heren (",COUNTA(AA58:AA65),")") -> Heren (1) | AD57: =CONCATENATE("Dames (",COUNTA(AE58:AE65),")") -> Dames (1) | AG57: =CONCATENATE("Heren (",COUNTA(AH58:AH65),")") -> Heren (1)
B58: {=_xlfn._xlws.FILTER(Spelerslijst!$B:$B,Spelerslijst!$G:$G=B$56,"")} -> de Haas, A | C58: {=_xlfn._xlws.FILTER(Spelerslijst!$C:$C,Spelerslijst!$G:$G=B$56,"")} -> Amber | D58: {=_xlfn._xlws.FILTER(Spelerslijst!$D:$D,Spelerslijst!$G:$G=B$56,"")} -> 14 | E58: {=_xlfn._xlws.FILTER(Spelerslijst!$K:$K,Spelerslijst!$P:$P=B$56,"")} -> Bäcker, C.J. | F58: {=_xlfn._xlws.FILTER(Spelerslijst!$L:$L,Spelerslijst!$P:$P=B$56,"")} -> Tijn | G58: {=_xlfn._xlws.FILTER(Spelerslijst!$M:$M,Spelerslijst!$P:$P=B$56,"")} -> 14 | I58: {=_xlfn._xlws.FILTER(Spelerslijst!$B:$B,Spelerslijst!$G:$G=I$56,"")} -> Bouwknegt, L.V. | J58: {=_xlfn._xlws.FILTER(Spelerslijst!$C:$C,Spelerslijst!$G:$G=I$56,"")} -> Lianne | K58: {=_xlfn._xlws.FILTER(Spelerslijst!$D:$D,Spelerslijst!$G:$G=I$56,"")} -> 14 | L58: {=_xlfn._xlws.FILTER(Spelerslijst!$K:$K,Spelerslijst!$P:$P=I$56,"")} -> Altena, E.K. | M58: {=_xlfn._xlws.FILTER(Spelerslijst!$L:$L,Spelerslijst!$P:$P=I$56,"")} -> Evan | N58: {=_xlfn._xlws.FILTER(Spelerslijst!$M:$M,Spelerslijst!$P:$P=I$56,"")} -> 14 | P58: {=_xlfn._xlws.FILTER(Spelerslijst!$B:$B,Spelerslijst!$G:$G=P$56,"")} -> Broek, van de C. | Q58: {=_xlfn._xlws.FILTER(Spelerslijst!$C:$C,Spelerslijst!$G:$G=P$56,"")} -> Carlijn | R58: {=_xlfn._xlws.FILTER(Spelerslijst!$D:$D,Spelerslijst!$G:$G=P$56,"")} -> 13 | S58: {=_xlfn._xlws.FILTER(Spelerslijst!$K:$K,Spelerslijst!$P:$P=P$56,"")} -> Boshoven, C. | T58: {=_xlfn._xlws.FILTER(Spelerslijst!$L:$L,Spelerslijst!$P:$P=P$56,"")} -> Casper | U58: {=_xlfn._xlws.FILTER(Spelerslijst!$M:$M,Spelerslijst!$P:$P=P$56,"")} -> 13 | W58: {=_xlfn._xlws.FILTER(Spelerslijst!$B:$B,Spelerslijst!$G:$G=W$56,"")} | X58: {=_xlfn._xlws.FILTER(Spelerslijst!$C:$C,Spelerslijst!$G:$G=W$56,"")} | Y58: {=_xlfn._xlws.FILTER(Spelerslijst!$D:$D,Spelerslijst!$G:$G=W$56,"")} | Z58: {=_xlfn._xlws.FILTER(Spelerslijst!$K:$K,Spelerslijst!$P:$P=W$56,"")} | AA58: {=_xlfn._xlws.FILTER(Spelerslijst!$L:$L,Spelerslijst!$P:$P=W$56,"")} | AB58: {=_xlfn._xlws.FILTER(Spelerslijst!$M:$M,Spelerslijst!$P:$P=W$56,"")} | AD58: {=_xlfn._xlws.FILTER(Spelerslijst!$B:$B,Spelerslijst!$G:$G=AH$56,"")} | AE58: {=_xlfn._xlws.FILTER(Spelerslijst!$C:$C,Spelerslijst!$G:$G=AH$56,"")} | AF58: {=_xlfn._xlws.FILTER(Spelerslijst!$D:$D,Spelerslijst!$G:$G=AH$56,"")} | AG58: {=_xlfn._xlws.FILTER(Spelerslijst!$K:$K,Spelerslijst!$P:$P=AH$56,"")} | AH58: {=_xlfn._xlws.FILTER(Spelerslijst!$L:$L,Spelerslijst!$P:$P=AH$56,"")} | AI58: {=_xlfn._xlws.FILTER(Spelerslijst!$M:$M,Spelerslijst!$P:$P=AH$56,"")}
B59: Driesprong, J. | C59: Jana | D59: 14 | E59: Koster, S. | F59: Senne | G59: 16 | I59: Bozuwa, J. | J59: Julia | K59: 14 | L59: Burgt, van de S. | M59: Seth | N59: 15 | P59: Everdingen, van T. | Q59: Tessa | R59: 15 | S59: Figee, N | T59: Niek | U59: 13
B60: Manduapessy, M. | C60: Merel | D60: 14 | E60: Vaartmans, J.A. | F60: Jordi | G60: 15 | I60: Burgt, van de E. | J60: Elize | K60: 13 | L60: Felix, J. | M60: Jesper | N60: 14 | P60: Vreeling, A.J.P. | Q60: Anouk | R60: 14 | S60: Hashmei, A. | T60: Ali | U60: 14
B61: Mert, R. | C61: Rezzan | D61: 15 | E61: Valk, J.B. | F61: Jarno | G61: 14 | I61: Hoeve, ten S. | J61: Senne | K61: 15 | L61: Vliet, T.M. | M61: Tycho | N61: 14 | S61: Ibrahim, A. | T61: Abdi | U61: 14
B62: Wolleswinkel, I.M.S. | C62: Iza | D62: 14 | E62: Zwanenburg, J. | F62: Jack | G62: 14 | I62: Voorbij, D.M. | J62: Doeska | K62: 13 | S62: Jongh, de M. | T62: Matthijs | U62: 14
S63: Koornneef, T.J. | T63: Tommie | U63: 14
S64: Pille, M.A. | T64: Menno | U64: 14
B66: {=_xlfn._xlws.FILTER(Staf!$C:$C,Staf!$B:$B=Teams!B56,"")} -> Trainer/Coach | C66: {=_xlfn._xlws.FILTER(Staf!$A:$A,Staf!$B:$B=Teams!B56,"")} -> Marijn Klink | I66: {=_xlfn._xlws.FILTER(Staf!$C:$C,Staf!$B:$B=Teams!I56,"")} -> Trainer/Coach | J66: {=_xlfn._xlws.FILTER(Staf!$A:$A,Staf!$B:$B=Teams!I56,"")} -> Robert Koster | P66: {=_xlfn._xlws.FILTER(Staf!$C:$C,Staf!$B:$B=Teams!P56,"")} -> Trainer/Coach | Q66: {=_xlfn._xlws.FILTER(Staf!$A:$A,Staf!$B:$B=Teams!P56,"")} -> Bart Driesprong | W66: {=_xlfn._xlws.FILTER(Staf!$C:$C,Staf!$B:$B=Teams!W56,"")} | X66: {=_xlfn._xlws.FILTER(Staf!$A:$A,Staf!$B:$B=Teams!W56,"")} | AD66: {=_xlfn._xlws.FILTER(Staf!$C:$C,Staf!$B:$B=Teams!AD56,"")} | AE66: {=_xlfn._xlws.FILTER(Staf!$A:$A,Staf!$B:$B=Teams!AD56,"")}
B67: Trainer/Coach | C67: Xanne Klink | I67: Trainer/Coach | J67: Tim Groeneweg | P67: Trainer/Coach | Q67: Mark Schindler
...

Sheet Spelerslijst
A1: Rel.nr | B1: Naam & Initialen) | C1: Roepnaam | D1: Leeftijd Peildatum | E1: Geb datum | F1: Team op Peildatum | G1: Team 20-21 | H1: AR | J1: Rel.nr | K1: Naam & Initialen | L1: Roepnaam | M1: Leeftijd Peildatum | N1: Geb datum | O1: Team op Peildatum | P1: Team 20-21 | Q1: AR
A2: NJG13L1 | B2: Bakker-Verwaal, L. | C2: Lieke | D2: 38 | E2: 30344 | F2: Sen | G2: - | J2: NGP49B2 | K2: Ameijden, van R. | L2: Robbert | M2: 31 | N2: 32911 | O2: Sen | P2: -
A3: NJK42D1 | B3: Blom, M. | C3: Michelle | D3: 22 | E3: 36479 | F3: Sen | G3: - | J3: NFW42L1 | K3: Belder, S. | L3: Steven | M3: 40 | N3: 29709 | O3: Sen | P3: -
A4: NFW26V3 | B4: Boshoven-Valk, A. | C4: Annemarie | D4: 44 | E4: 28346 | F4: Sen | G4: - | J4: NFW42M8 | K4: Boer, de A | L4: Alexander | M4: 42 | N4: 29189 | O4: Sen | P4: -
A5: NLS54M7 | B5: Jacobs, K. | C5: Kimberly | D5: 36 | E5: 31375 | F5: Sen | G5: - | J5: NFX11D8 | K5: Dalen, van A.T.M. | L5: Lex | M5: 54 | N5: 24583 | O5: Sen | P5: -
A6: NLZ39C9 | B6: Ploeg- van Ballegooijen, I. | C6: Irene | D6: 34 | E6: 32045 | F6: Sen | G6: - | J6: NGT42V5 | K6: Draaijer, R. | L6: Rens | M6: 31 | N6: 33211 | O6: Sen | P6: -
A7: NLQ98H2 | B7: Valk-Helsloot, G. | C7: Gunilda | D7: 46 | E7: 27565 | F7: Sen | G7: - | J7: NJK05M3 | K7: Goudriaan, S | L7: Stefan | M7: 28 | N7: 34255 | O7: Sen | P7: -
A8: NFW28G4 | B8: Visser, H. | C8: Hilde | D8: 31 | E8: 33146 | F8: Sen | G8: - | J8: NJF34K6 | K8: Hendriks, T. | L8: Tom | M8: 25 | N8: 35092 | O8: Sen | P8: -
A9: NMN07F4 | B9: Boshoven, S.A.E. | C9: Sara | D9: 16 | E9: 38635 | F9: A | G9: A2 | J9: NFW28T5 | K9: Kleingeld, J | L9: Jasper | M9: 36 | N9: 31083 | O9: Sen | P9: -
A10: NGG54V3 | B10: Driesprong, M. | C10: Meike | D10: 17 | E10: 38011 | F10: A | G10: A1 | J10: NJX60W1 | K10: Klink, S. | L10: Stijn | M10: 21 | N10: 36833 | O10: Sen | P10: -
A11: NJX40G9 | B11: Fernhout, L. | C11: Loïs | D11: 18 | E11: 37684 | F11: A | G11: A1 | J11: NFS05D0 | K11: Naaktgeboren, D.J. | L11: Dio | M11: 55 | N11: 24133 | O11: Sen | P11: -
A12: NLX00H0 | B12: Gent, van E. | C12: Elsemieke | D12: 17 | E12: 38113 | F12: A | G12: A2 | J12: NFW29N6 | K12: Ploeg, H | L12: Henno | M12: 35 | N12: 31501 | O12: Sen | P12: -
A13: NMD22V1 | B13: Groeneweg, R.K. | C13: Roos | D13: 16 | E13: 38432 | F13: A | G13: A2 | J13: NFX74K6 | K13: Romijn, A. | L13: Aad | M13: 59 | N13: 22941 | O13: Sen | P13: -
... A160: NJC15T9 | B160: Borsboom, L. | C160: Lis | D160: 13 | E160: 39637 | F160: C | G160: Stopt | J160: NKH56N2 | K160: Wolff, A. | L160: Alexander | M160: 25 | N160: 35231 | O160: Sen | P160: S5
A161: NMM29Q6 | B161: Brouwer, N. | C161: Nynke | D161: 18 | E161: 37624 | F161: A | G161: Stopt
A162: NLB70G6 | B162: Dommisse, K. | C162: Kim | D162: 20 | E162: 36993 | F162: Sen | G162: S5
A163: NKW49Y8 | B163: Driesprong, A. | C163: Anne | D163: 21 | E163: 36727 | F163: Sen | G163: Stopt
A164: NLP89W4 | B164: Est, van S.K.E. | C164: Sarah | D164: 11 | E164: 40213 | F164: D | G164: Stopt
A165: NLT96R9 | B165: Fernhout, T. | C165: Tirsa | D165: 23 | E165: 35817 | F165: Sen | G165: Stopt
A166: NLV84M5 | B166: Geneugelijk, T. | C166: Tess | D166: 8 | E166: 41412 | F166: E | G166: Stopt
A167: NMH07D4 | B167: Jong, de C.C. | C167: Céline | D167: 21 | E167: 36849 | F167: Sen | G167: Stopt
A168: NMH36F0 | B168: Klerk, Ayda de | C168: Ayda | D168: 18 | E168: 37720 | F168: A | G168: Stopt
A169: NML06D5 | B169: Manduapessy, V.P. | C169: Vera | D169: 17 | E169: 38303 | F169: A | G169: Stopt
A170: NMK14K2 | B170: Morée, de J. | C170: Jessica | D170: 21 | E170: 36706 | F170: Sen | G170: Stopt
A171: NLL20B6 | B171: Nelemans, I. | C171: Ingrid | D171: 54 | E171: 24525 | F171: Sen | G171: Stopt
A172: NJC46R3 | B172: Nijhoff, L. | C172: Liv | D172: 10 | E172: 40565 | F172: D | G172: Stopt
... A194: NMN85P8 | B194: Van Rijswijk, F. | C194: Fenna | D194: 9 | E194: 41068 | F194: E | G194: E6
A195: NMP10M9 | B195: Van den Bergh, M. | C195: Marit | D195: 11 | E195: 40541 | F195: D
A196: NMP73C8 | B196: Uljee, T. | C196: Tess | D196: 8 | E196: 41582 | F196: E | G196: E6

Sheet Staf
A1: Naam | B1: Team | C1: Functie | D1: eigen team
A2: Mark Morelissen | B2: A1 | C2: Coach A1 | D2: X
A3: Ruben Blokland | B3: A1 | C3: Assistent A1 | D3: X
A4: Ruben Blokland | B4: A2 | C4: Coach A2 | D4: X
A5: Olivier Klink | B5: A3 | C5: Trainer/Coach | D5: X
A6: Tim van Gent | B6: A3 | C6: Trainer/Coach | D6: S2
A7: Lex van Dalen | B7: A4 | C7: Trainer/Coach | D7: X
A8: Robbert van Ameijden | B8: A4 | C8: Trainer/Coach | D8: X
A9: Marijn Klink | B9: B1 | C9: Trainer/Coach | D9: S1/S2
A10: Xanne Klink | B10: B1 | C10: Trainer/Coach | D10: S1/S2
A11: Robert Koster | B11: B2 | C11: Trainer/Coach | D11: X
A12: Tim Groeneweg | B12: B2 | C12: Trainer/Coach | D12: S5
... A57: Marco van Kalkeren | B57: S4 | C57: Thuiscoach | D57: X
A58: Tom Hendriks | C58: Gestopt | D58: X
A59: Egbert Vos | C59: Gestopt | D59: X
A60: Rick Goudriaan | C60: Gestopt | D60: X

Sheet Stoppers
A1: Rel.nr | B1: Naam & Initialen) | C1: Roepnaam | D1: Leeftijd Peildatum | E1: Geb datum | F1: Team op Peildatum | G1: Team 20-21 | I1: Rel.nr | J1: Naam & Initialen) | K1: Roepnaam | L1: Leeftijd Peildatum | M1: Geb datum | N1: Team op Peildatum | O1: Team 20-21
A2: {=_xlfn._xlws.FILTER(Spelerslijst!A:A,Spelerslijst!$G:$G="Stopt","")} -> NJK08X9 | B2: {=_xlfn._xlws.FILTER(Spelerslijst!B:B,Spelerslijst!$G:$G="Stopt","")} -> Veld, in 't P.M. | C2: {=_xlfn._xlws.FILTER(Spelerslijst!C:C,Spelerslijst!$G:$G="Stopt","")} -> Puck | D2: {=_xlfn._xlws.FILTER(Spelerslijst!D:D,Spelerslijst!$G:$G="Stopt","")} -> 11 | E2: {=_xlfn._xlws.FILTER(Spelerslijst!E:E,Spelerslijst!$G:$G="Stopt","")} -> 40409 | F2: {=_xlfn._xlws.FILTER(Spelerslijst!F:F,Spelerslijst!$G:$G="Stopt","")} -> D | G2: {=_xlfn._xlws.FILTER(Spelerslijst!G:G,Spelerslijst!$G:$G="Stopt","")} -> Stopt | I2: {=_xlfn._xlws.FILTER(Spelerslijst!J:J,Spelerslijst!$P:$P="Stopt","")} -> NMD90G5 | J2: {=_xlfn._xlws.FILTER(Spelerslijst!K:K,Spelerslijst!$P:$P="Stopt","")} -> Hemert, van S. | K2: {=_xlfn._xlws.FILTER(Spelerslijst!L:L,Spelerslijst!$P:$P="Stopt","")} -> Stijn | L2: {=_xlfn._xlws.FILTER(Spelerslijst!M:M,Spelerslijst!$P:$P="Stopt","")} -> 9 | M2: {=_xlfn._xlws.FILTER(Spelerslijst!N:N,Spelerslijst!$P:$P="Stopt","")} -> 41179 | N2: {=_xlfn._xlws.FILTER(Spelerslijst!O:O,Spelerslijst!$P:$P="Stopt","")} -> E | O2: {=_xlfn._xlws.FILTER(Spelerslijst!P:P,Spelerslijst!$P:$P="Stopt","")} -> Stopt
A3: NJF85B1 | B3: Breekveldt, T. | C3: Tessa | D3: 9 | E3: 41123 | F3: E | G3: Stopt | I3: NJH76N5 | J3: Klink, O.C. | K3: Olivier | L3: 23 | M3: 36143 | N3: Sen | O3: Stopt
A4: NFX00K9 | B4: Muller, L. | C4: Lieve | D4: 6 | E4: 42021 | F4: F | G4: Stopt | I4: NLL19Y9 | J4: Altena, J.D. | K4: Jaron | L4: 20 | M4: 37170 | N4: Sen | O4: Stopt
A5: NLG58Z8 | B5: Canli, D. | C5: Dilan | D5: 19 | E5: 37333 | F5: Sen | G5: Stopt | I5: NKN65J2 | J5: Dalen, van F.G. | K5: Freek | L5: 18 | M5: 37823 | N5: A | O5: Stopt
A6: NJC15T9 | B6: Borsboom, L. | C6: Lis | D6: 13 | E6: 39637 | F6: C | G6: Stopt | I6: NMK07Q8 | J6: Geneugelijk, L. | K6: Luca | L6: 8 | M6: 41412 | N6: E | O6: Stopt
A7: NMM29Q6 | B7: Brouwer, N. | C7: Nynke | D7: 18 | E7: 37624 | F7: A | G7: Stopt | I7: NLX08F0 | J7: Hart, 't O.N.L.R | K7: Olav | L7: 11 | M7: 40291 | N7: D | O7: Stopt
A8: NKW49Y8 | B8: Driesprong, A. | C8: Anne | D8: 21 | E8: 36727 | F8: Sen | G8: Stopt | I8: NGT42Z3 | J8: Hoed, den W | K8: Wilbert | L8: 31 | M8: 33052 | N8: Sen | O8: Stopt
A9: NLP89W4 | B9: Est, van S.K.E. | C9: Sarah | D9: 11 | E9: 40213 | F9: D | G9: Stopt | I9: NJZ00Y7 | J9: Jager, de S. | K9: Sam | L9: 21 | M9: 36588 | N9: Sen | O9: Stopt
A10: NLT96R9 | B10: Fernhout, T. | C10: Tirsa | D10: 23 | E10: 35817 | F10: Sen | G10: Stopt | I10: NKM14K0 | J10: Jong, Erik de | K10: Erik | L10: 21 | M10: 36843 | N10: Sen | O10: Stopt
A11: NLV84M5 | B11: Geneugelijk, T. | C11: Tess | D11: 8 | E11: 41412 | F11: E | G11: Stopt | I11: NMK14M6 | J11: Klis, van der R. | K11: Roman | L11: 6 | M11: 42091 | N11: F | O11: Stopt
A12: NMH07D4 | B12: Jong, de C.C. | C12: Céline | D12: 21 | E12: 36849 | F12: Sen | G12: Stopt | I12: NLW81C7 | J12: Maas, J.G.T. | K12: Gijsbert | L12: 15 | M12: 38835 | N12: B | O12: Stopt
A13: NMH36F0 | B13: Klerk, Ayda de | C13: Ayda | D13: 18 | E13: 37720 | F13: A | G13: Stopt | I13: NKW21L3 | J13: Minkelis, van de J.W. | K13: Jonathan | L13: 17 | M13: 38317 | N13: A | O13: Stopt
A14: NML06D5 | B14: Manduapessy, V.P. | C14: Vera | D14: 17 | E14: 38303 | F14: A | G14: Stopt | I14: NLZ36K6 | J14: Muller, A.J. | K14: Joaz | L14: 11 | M14: 40405 | N14: D | O14: Stopt
... A18: NLP78L9 | B18: Nobel, M.H.M. | C18: Merle | D18: 15 | E18: 38847 | F18: B | G18: Stopt | I18: NKC46P6 | J18: Wall, van der J. | K18: Jeffrey | L18: 21 | M18: 36664 | N18: Sen | O18: Stopt
A19: NMC85Q4 | B19: Oostlander, E.P. | C19: Elise | D19: 19 | E19: 37494 | F19: Sen | G19: Stopt
A20: NKS24S7 | B20: Rasul, B. | C20: Bahar | D20: 9 | E20: 41152 | F20: E | G20: Stopt
A21: NKR24N1 | B21: Rijkers, I.B. | C21: Ilse | D21: 15 | E21: 38820 | F21: B | G21: Stopt
A22: NLZ81W0 | B22: Robbemond, J. | C22: Jente | D22: 13 | E22: 39709 | F22: C | G22: Stopt
A23: NLL19T4 | B23: Seijner, F.C. | C23: Fabiënne | D23: 18 | E23: 37673 | F23: A | G23: Stopt
A24: NKQ14R3 | B24: Spijk, van J.M. | C24: Jikke | D24: 18 | E24: 37868 | F24: A | G24: Stopt
A25: NKQ13Q3 | B25: Temme, J. | C25: Judith | D25: 19 | E25: 37448 | F25: Sen | G25: Stopt
A26: NKX36X8 | B26: Tijssen, N. | C26: Naomi | D26: 10 | E26: 40660 | F26: D | G26: Stopt
A27: NLP78N3 | B27: Timmer, E. | C27: Edith | D27: 15 | E27: 38929 | F27: B | G27: Stopt
A28: NKD20B1 | B28: Verkerke, J.D. | C28: Julia | D28: 15 | E28: 39044 | F28: B | G28: Stopt
A29: NLS76C3 | B29: Visser-Michelsen, D. | C29: Diana | D29: 29 | E29: 33777 | F29: Sen | G29: Stopt
A30: NFW15S4 | B30: Volker, K.N.N. | C30: Karlijn | D30: 16 | E30: 38417 | F30: A | G30: Stopt
... A34: NMN14R4 | B34: Zwoll, van S. | C34: Simone | D34: 27 | E34: 34635 | F34: Sen | G34: Stopt

Sheet vraagtekens
A1: Rel.nr | B1: Naam & Initialen) | C1: Roepnaam | D1: Leeftijd Peildatum | E1: Geb datum | F1: Team op Peildatum | G1: Team 20-21 | I1: Rel.nr | J1: Naam & Initialen) | K1: Roepnaam | L1: Leeftijd Peildatum | M1: Geb datum | N1: Team op Peildatum | O1: Team 20-21
A2: {=_xlfn._xlws.FILTER(Spelerslijst!A:A,Spelerslijst!$G:$G="?","")} | B2: {=_xlfn._xlws.FILTER(Spelerslijst!B:B,Spelerslijst!$G:$G="?","")} | C2: {=_xlfn._xlws.FILTER(Spelerslijst!C:C,Spelerslijst!$G:$G="?","")} | D2: {=_xlfn._xlws.FILTER(Spelerslijst!D:D,Spelerslijst!$G:$G="?","")} | E2: {=_xlfn._xlws.FILTER(Spelerslijst!E:E,Spelerslijst!$G:$G="?","")} | F2: {=_xlfn._xlws.FILTER(Spelerslijst!F:F,Spelerslijst!$G:$G="?","")} | G2: {=_xlfn._xlws.FILTER(Spelerslijst!G:G,Spelerslijst!$G:$G="?","")} | I2: {=_xlfn._xlws.FILTER(Spelerslijst!J:J,Spelerslijst!$P:$P="?","")} | J2: {=_xlfn._xlws.FILTER(Spelerslijst!K:K,Spelerslijst!$P:$P="?","")} | K2: {=_xlfn._xlws.FILTER(Spelerslijst!L:L,Spelerslijst!$P:$P="?","")} | L2: {=_xlfn._xlws.FILTER(Spelerslijst!M:M,Spelerslijst!$P:$P="?","")} | M2: {=_xlfn._xlws.FILTER(Spelerslijst!N:N,Spelerslijst!$P:$P="?","")} | N2: {=_xlfn._xlws.FILTER(Spelerslijst!O:O,Spelerslijst!$P:$P="?","")} | O2: {=_xlfn._xlws.FILTER(Spelerslijst!P:P,Spelerslijst!$P:$P="?","")}

Sheet streepjes

Sheet check bond 2206
A1: Check V | B1: Check M | C1: Check | D1: Relatiecode | E1: Volledige naam (1) | F1: Geboortedatum | G1: Geslacht | H1: Straatnaam | I1: Huisnummer | J1: Toevoeging | K1: Postcode | L1: Plaats | M1: Land | N1: Mobiel | O1: Telefoon | P1: E-mail | Q1: Status | R1: Bondssporten | S1: Lidmaatschapcode | T1: Verenigingssporten | U1: Lidsoort | V1: Contributiecategorie | W1: Lid sinds | X1: Afmelddatum
A2: =_xlfn.IFNA(VLOOKUP(D2,Spelerslijst!A:B,1,FALSE),FALSE) -> FALSE | B2: =_xlfn.IFNA(VLOOKUP(D2,Spelerslijst!J:K,1,FALSE),FALSE) -> NGT42Z3 | C2: =IF(AND(A2=FALSE,B2=FALSE),"Onbekend","") | D2: NGT42Z3 | E2: Hoed, Wilbert den | F2: 33052 | G2: M | H2: Schieweg | I2: 73 | J2: A3 | K2: 3038 AG | L2: ROTTERDAM | M2: Nederland | N2: 078-6213529 | O2: 078-6213529 | P2: wilbert_nr1@hotmail.com | Q2: af te melden | R2: Veld - Week, Zaal - Week | S2: 202 | T2: Algemeen reserve - Algemeen reserve - Week | U2: Bondslid | V2: Senior | W2: 35506 | X2: 44377
A3: =_xlfn.IFNA(VLOOKUP(D3,Spelerslijst!A:B,1,FALSE),FALSE) -> NMM29Q6 | B3: =_xlfn.IFNA(VLOOKUP(D3,Spelerslijst!J:K,1,FALSE),FALSE) -> FALSE | C3: =IF(AND(A3=FALSE,B3=FALSE),"Onbekend","") | D3: NMM29Q6 | E3: Vogelaar, Elin | F3: 43083 | G3: V | H3: Zinkweg | I3: 152 | K3: 3262 BG | L3: OUD-BEIJERLAND | M3: Nederland | N3: 06-15336761 | P3: maritteisarin@gmail.com | Q3: overschrijving spelactiviteit | R3: Kangoeroe Klup | S3: 240 | T3: Korfbal - Korfbal - Week | U3: Bondslid | V3: Kangoeroe | W3: 44326
A4: =_xlfn.IFNA(VLOOKUP(D4,Spelerslijst!A:B,1,FALSE),FALSE) -> FALSE | B4: =_xlfn.IFNA(VLOOKUP(D4,Spelerslijst!J:K,1,FALSE),FALSE) -> NLB70W8 | C4: =IF(AND(A4=FALSE,B4=FALSE),"Onbekend","") | D4: NLB70W8 | E4: Friebel, Luuk | F4: 36683 | G4: M | H4: Kuipershaven | I4: 1 | K4: 3311 AL | L4: DORDRECHT | M4: Nederland | N4: 06-39841583 | P4: luukfriebel@gmail.com | Q4: definitief | R4: Veld - Week, Zaal - Week | S4: 200 | T4: Korfbal - Korfbal - Week | U4: Bondslid | V4: Senior | W4: 41153
A5: =_xlfn.IFNA(VLOOKUP(D5,Spelerslijst!A:B,1,FALSE),FALSE) -> NLB70X5 | B5: =_xlfn.IFNA(VLOOKUP(D5,Spelerslijst!J:K,1,FALSE),FALSE) -> FALSE | C5: =IF(AND(A5=FALSE,B5=FALSE),"Onbekend","") | D5: NLB70X5 | E5: Friebel, Angela | F5: 37541 | G5: V | H5: Kuipershaven | I5: 1 | K5: 3311 AL | L5: DORDRECHT | M5: Nederland | N5: 06-25586186 | P5: angelafriebel02@gmail.com | Q5: definitief | R5: Veld - Week, Zaal - Week | S5: 210 | T5: Korfbal - Korfbal - Week | U5: Bondslid | V5: Junior | W5: 41153
A6: =_xlfn.IFNA(VLOOKUP(D6,Spelerslijst!A:B,1,FALSE),FALSE) -> NKB62K8 | B6: =_xlfn.IFNA(VLOOKUP(D6,Spelerslijst!J:K,1,FALSE),FALSE) -> FALSE | C6: =IF(AND(A6=FALSE,B6=FALSE),"Onbekend","") | D6: NKB62K8 | E6: Hulsker, Nina | F6: 36385 | G6: V | H6: Stooplaan | I6: 22 | K6: 3311 DM | L6: DORDRECHT | M6: Nederland | N6: 06-41774946 | O6: 078-6316490 | P6: ninahulsker@hotmail.com | Q6: definitief | R6: Veld - Week, Zaal - Week | S6: 200 | T6: Korfbal - Korfbal - Week | U6: Bondslid | V6: Senior | W6: 39296
A7: =_xlfn.IFNA(VLOOKUP(D7,Spelerslijst!A:B,1,FALSE),FALSE) -> FALSE | B7: =_xlfn.IFNA(VLOOKUP(D7,Spelerslijst!J:K,1,FALSE),FALSE) -> NLP77Y7 | C7: =IF(AND(A7=FALSE,B7=FALSE),"Onbekend","") | D7: NLP77Y7 | E7: Klein, Daan | F7: 38667 | G7: M | H7: Van Slingelandtlaan | I7: 11 | K7: 3311 DP | L7: DORDRECHT | M7: Nederland | N7: 06-21804332 | O7: 078-6147494 | P7: elinedejonge75@gmail.com | Q7: definitief | R7: Veld - Week, Zaal - Week | S7: 220 | T7: Korfbal - Korfbal - Week | U7: Bondslid | V7: Aspirant | W7: 42248
A8: =_xlfn.IFNA(VLOOKUP(D8,Spelerslijst!A:B,1,FALSE),FALSE) -> NML00R5 | B8: =_xlfn.IFNA(VLOOKUP(D8,Spelerslijst!J:K,1,FALSE),FALSE) -> FALSE | C8: =IF(AND(A8=FALSE,B8=FALSE),"Onbekend","") | D8: NML00R5 | E8: Bos, Bryanna | F8: 40373 | G8: V | H8: Grote Spuistraat | I8: 4 | K8: 3311 GE | L8: DORDRECHT | M8: Nederland | N8: 06-27617857 | P8: luthiendenheeten@gmail.com | Q8: definitief | R8: Veld - Week, Zaal - Week | S8: 230 | T8: Korfbal - Korfbal - Week | U8: Bondslid | V8: Pupil | W8: 44099
A9: =_xlfn.IFNA(VLOOKUP(D9,Spelerslijst!A:B,1,FALSE),FALSE) -> NMH36F0 | B9: =_xlfn.IFNA(VLOOKUP(D9,Spelerslijst!J:K,1,FALSE),FALSE) -> FALSE | C9: =IF(AND(A9=FALSE,B9=FALSE),"Onbekend","") | D9: NMH36F0 | E9: Vreeling, Anouk | F9: 39427 | G9: V | H9: Rozenhof | I9: 11 | K9: 3311 JT | L9: DORDRECHT | M9: Nederland | N9: 06-41809939 | P9: nellavreeling@gmail.com | Q9: definitief | R9: Veld - Week, Zaal - Week | S9: 220 | T9: Korfbal - Korfbal - Week | U9: Bondslid | V9: Aspirant | W9: 43748
A10: =_xlfn.IFNA(VLOOKUP(D10,Spelerslijst!A:B,1,FALSE),FALSE) -> NKT05Q7 | B10: =_xlfn.IFNA(VLOOKUP(D10,Spelerslijst!J:K,1,FALSE),FALSE) -> FALSE | C10: =IF(AND(A10=FALSE,B10=FALSE),"Onbekend","") | D10: NKT05Q7 | E10: Oostlander, Elise | F10: 37494 | G10: V | H10: Adriaan v Bleijenburgstr | I10: 14 | K10: 3311 LB | L10: DORDRECHT | M10: Nederland | N10: 06-38751645 | O10: 078-6350904 | P10: eliseoostlander@gmail.com | Q10: af te melden | R10: Veld - Week, Zaal - Week | S10: 210 | T10: Korfbal - Korfbal - Week | U10: Bondslid | V10: Junior | W10: 40452 | X10: 44377
A11: =_xlfn.IFNA(VLOOKUP(D11,Spelerslijst!A:B,1,FALSE),FALSE) -> NKJ95M4 | B11: =_xlfn.IFNA(VLOOKUP(D11,Spelerslijst!J:K,1,FALSE),FALSE) -> FALSE | C11: =IF(AND(A11=FALSE,B11=FALSE),"Onbekend","") | D11: NKJ95M4 | E11: Brouwer, Nynke | F11: 37624 | G11: V | H11: Koningin Wilhelminastr | I11: 38 | K11: 3311 LN | L11: DORDRECHT | M11: Nederland | N11: 06-24649690 | O11: 078-8437702 | P11: nynke.brouwer@hotmail.nl | Q11: definitief | R11: Veld - Week, Zaal - Week | S11: 210 | T11: Korfbal - Korfbal - Week | U11: Bondslid | V11: Junior | W11: 39753
A12: =_xlfn.IFNA(VLOOKUP(D12,Spelerslijst!A:B,1,FALSE),FALSE) -> NJK34W5 | B12: =_xlfn.IFNA(VLOOKUP(D12,Spelerslijst!J:K,1,FALSE),FALSE) -> FALSE | C12: =IF(AND(A12=FALSE,B12=FALSE),"Onbekend","") | D12: NJK34W5 | E12: Ploeg, Lieke | F12: 31732 | G12: V | H12: Clara en Mariahof | I12: 14 | K12: 3311 NC | L12: DORDRECHT | M12: Nederland | N12: 06-40775677 | P12: liekeploeg@gmail.com | Q12: definitief | R12: Veld - Week, Zaal - Week | S12: 200 | T12: Korfbal - Korfbal - Week | U12: Bondslid | V12: Senior | W12: 42461
A13: =_xlfn.IFNA(VLOOKUP(D13,Spelerslijst!A:B,1,FALSE),FALSE) -> FALSE | B13: =_xlfn.IFNA(VLOOKUP(D13,Spelerslijst!J:K,1,FALSE),FALSE) -> NKW21L3 | C13: =IF(AND(A13=FALSE,B13=FALSE),"Onbekend","") | D13: NKW21L3 | E13: Minkelis, Jonathan van de | F13: 38317 | G13: M | H13: Singel | I13: 22 | K13: 3311 SJ | L13: DORDRECHT | M13: Nederland | N13: 06-50561693 | O13: 078-6310318 | P13: jonathan.vandeminkelis@leerlingen.jdw.nl | Q13: af te melden | R13: Veld - Week, Zaal - Week | S13: 210 | T13: Korfbal - Korfbal - Week | U13: Bondslid | V13: Junior | W13: 40787 | X13: 44377
A14: =_xlfn.IFNA(VLOOKUP(D14,Spelerslijst!A:B,1,FALSE),FALSE) -> NLX64V0 | B14: =_xlfn.IFNA(VLOOKUP(D14,Spelerslijst!J:K,1,FALSE),FALSE) -> FALSE | C14: =IF(AND(A14=FALSE,B14=FALSE),"Onbekend","") | D14: NLX64V0 | E14: Boer, EsmÃ©e de | F14: 40328 | G14: V | H14: Steltenpad | I14: 10 | K14: 3311 SL | L14: DORDRECHT | M14: Nederland | N14: 06-26468565 | O14: 078-6136388 | P14: alexenannemarie@outlook.com | Q14: definitief | R14: Veld - Week, Zaal - Week | S14: 230 | T14: Korfbal - Korfbal - Week | U14: Bondslid | V14: Pupil | W14: 42912
A15: =_xlfn.IFNA(VLOOKUP(D15,Spelerslijst!A:B,1,FALSE),FALSE) -> NMG13P0 | B15: =_xlfn.IFNA(VLOOKUP(D15,Spelerslijst!J:K,1,FALSE),FALSE) -> FALSE | C15: =IF(AND(A15=FALSE,B15=FALSE),"Onbekend","") | D15: NMG13P0 | E15: Boer, Layla de | F15: 41474 | G15: V | H15: Steltenpad | I15: 10 | K15: 3311 SL | L15: DORDRECHT | M15: Nederland | N15: 06-26468565 | P15: alexenannemarie@outlook.com | Q15: definitief | R15: Veld - Week, Zaal - Week | S15: 230 | T15: Korfbal - Korfbal - Week | U15: Bondslid | V15: Pupil | W15: 43641
A16: =_xlfn.IFNA(VLOOKUP(D16,Spelerslijst!A:B,1,FALSE),FALSE) -> NFW26V3 | B16: =_xlfn.IFNA(VLOOKUP(D16,Spelerslijst!J:K,1,FALSE),FALSE) -> FALSE | C16: =IF(AND(A16=FALSE,B16=FALSE),"Onbekend","") | D16: NFW26V3 | E16: Assem, Lisette van den | F16: 30573 | G16: V | H16: Bethlehemplein | I16: 1 | K16: 3311 VB | L16: DORDRECHT | M16: Nederland | N16: 06-48937954 | O16: 06-48937954 | P16: lisette1983@msn.com | Q16: definitief | R16: Veld - Week, Zaal - Week | S16: 200 | T16: Korfbal - Korfbal - Week | U16: Bondslid | V16: Senior | W16: 32752
A17: =_xlfn.IFNA(VLOOKUP(D17,Spelerslijst!A:B,1,FALSE),FALSE) -> FALSE | B17: =_xlfn.IFNA(VLOOKUP(D17,Spelerslijst!J:K,1,FALSE),FALSE) -> NGW10M4 | C17: =IF(AND(A17=FALSE,B17=FALSE),"Onbekend","") | D17: NGW10M4 | E17: Jong, Bas de | F17: 33019 | G17: M | H17: Slikveld | I17: 42 | K17: 3311 VT | L17: DORDRECHT | M17: Nederland | N17: 06-15435426 | P17: basdejong1990@hotmail.com | Q17: definitief | R17: Veld - Week, Zaal - Week | S17: 200 | T17: Korfbal - Korfbal - Week | U17: Bondslid | V17: Senior | W17: 35746
A18: =_xlfn.IFNA(VLOOKUP(D18,Spelerslijst!A:B,1,FALSE),FALSE) -> NLX00J4 | B18: =_xlfn.IFNA(VLOOKUP(D18,Spelerslijst!J:K,1,FALSE),FALSE) -> FALSE | C18: =IF(AND(A18=FALSE,B18=FALSE),"Onbekend","") | D18: NLX00J4 | E18: Veld, Puck in 't | F18: 40409 | G18: V | H18: Twintighuizen | I18: 36 | K18: 3311 WX | L18: DORDRECHT | M18: Nederland | N18: 06-13307105 | P18: marianwibbens@hotmail.com | Q18: definitief | R18: Veld - Week, Zaal - Week | S18: 230 | T18: Korfbal - Korfbal - Week | U18: Bondslid | V18: Pupil | W18: 42877
A19: =_xlfn.IFNA(VLOOKUP(D19,Spelerslijst!A:B,1,FALSE),FALSE) -> NMF09H6 | B19: =_xlfn.IFNA(VLOOKUP(D19,Spelerslijst!J:K,1,FALSE),FALSE) -> FALSE | C19: =IF(AND(A19=FALSE,B19=FALSE),"Onbekend","") | D19: NMF09H6 | E19: Veld, Roos in 't | F19: 40995 | G19: V | H19: Twintighuizen | I19: 36 | K19: 3311 WX | L19: DORDRECHT | M19: Nederland | N19: 06-27026044 | O19: 06-27026044 | P19: e_int_veld@hotmail.com | Q19: definitief | R19: Veld - Week, Zaal - Week | S19: 230 | T19: Korfbal - Korfbal - Week | U19: Bondslid | V19: Pupil | W19: 43498
A20: =_xlfn.IFNA(VLOOKUP(D20,Spelerslijst!A:B,1,FALSE),FALSE) -> FALSE | B20: =_xlfn.IFNA(VLOOKUP(D20,Spelerslijst!J:K,1,FALSE),FALSE) -> NGP49B2 | C20: =IF(AND(A20=FALSE,B20=FALSE),"Onbekend","") | D20: NGP49B2 | E20: Ameijden, Robbert van | F20: 32911 | G20: M | H20: Kasperspad | I20: 33 | K20: 3311 ZE | L20: DORDRECHT | M20: Nederland | N20: 06-15161476 | P20: robbert1990@live.nl | Q20: definitief | R20: Veld - Week, Zaal - Week | S20: 202 | T20: Algemeen reserve - Algemeen reserve - Week | U20: Bondslid | V20: Senior | W20: 35447
A21: =_xlfn.IFNA(VLOOKUP(D21,Spelerslijst!A:B,1,FALSE),FALSE) -> NLN68P0 | B21: =_xlfn.IFNA(VLOOKUP(D21,Spelerslijst!J:K,1,FALSE),FALSE) -> FALSE | C21: =IF(AND(A21=FALSE,B21=FALSE),"Onbekend","") | D21: NLN68P0 | E21: Canli, Dilan | F21: 37333 | G21: V | H21: Marcellus Schampersstr | I21: 19 | K21: 3311 ZJ | L21: DORDRECHT | M21: Nederland | N21: 06-39118111 | P21: dilannetje@live.nl | Q21: definitief | R21: Veld - Week, Zaal - Week | S21: 210 | T21: Korfbal - Korfbal - Week | U21: Bondslid | V21: Junior | W21: 42095
A22: =_xlfn.IFNA(VLOOKUP(D22,Spelerslijst!A:B,1,FALSE),FALSE) -> FALSE | B22: =_xlfn.IFNA(VLOOKUP(D22,Spelerslijst!J:K,1,FALSE),FALSE) -> NLB70Y2 | C22: =IF(AND(A22=FALSE,B22=FALSE),"Onbekend","") | D22: NLB70Y2 | E22: Meijer, Joeke | F22: 38617 | G22: M | H22: Reeweg Oost | I22: 107 | K22: 3312 CL | L22: DORDRECHT | M22: Nederland | N22: 06-14990505 | O22: 078-6352444 | P22: jacco.yvette@gmail.com | Q22: definitief | R22: Veld - Week, Zaal - Week | S22: 220 | T22: Korfbal - Korfbal - Week | U22: Bondslid | V22: Aspirant | W22: 41153
A23: =_xlfn.IFNA(VLOOKUP(D23,Spelerslijst!A:B,1,FALSE),FALSE) -> NKS24M5 | B23: =_xlfn.IFNA(VLOOKUP(D23,Spelerslijst!J:K,1,FALSE),FALSE) -> FALSE | C23: =IF(AND(A23=FALSE,B23=FALSE),"Onbekend","") | D23: NKS24M5 | E23: Verbeek, Yente | F23: 38012 | G23: V | H23: Reeweg Oost | I23: 138 | K23: 3312 CT | L23: DORDRECHT | M23: Nederland | N23: 06-36397595 | O23: 078-7518742 | P23: yenteverbeek@gmail.com | Q23: definitief | R23: Veld - Week, Zaal - Week | S23: 210 | T23: Korfbal - Korfbal - Week | U23: Bondslid | V23: Junior | W23: 40422
A24: =_xlfn.IFNA(VLOOKUP(D24,Spelerslijst!A:B,1,FALSE),FALSE) -> FALSE | B24: =_xlfn.IFNA(VLOOKUP(D24,Spelerslijst!J:K,1,FALSE),FALSE) -> NFW26G8 | C24: =IF(AND(A24=FALSE,B24=FALSE),"Onbekend","") | D24: NFW26G8 | E24: Noels, Arjan | F24: 29523 | G24: M | H24: Bankastraat | I24: 322 | K24: 3312 GG | L24: DORDRECHT | M24: Nederland | N24: 078-8432770 | O24: 078-8432770 | P24: arjan.noels@upcmail.nl | Q24: definitief | R24: Veld - Week, Zaal - Week | S24: 200 | T24: Korfbal - Korfbal - Week | U24: Bondslid | V24: Senior | W24: 32051
A25: =_xlfn.IFNA(VLOOKUP(D25,Spelerslijst!A:B,1,FALSE),FALSE) -> NMJ53F3 | B25: =_xlfn.IFNA(VLOOKUP(D25,Spelerslijst!J:K,1,FALSE),FALSE) -> FALSE | C25: =IF(AND(A25=FALSE,B25=FALSE),"Onbekend","") | D25: NMJ53F3 | E25: Rooij, Eva van | F25: 41167 | G25: V | H25: Halmaheiraplein | I25: 4 | K25: 3312 GH | L25: DORDRECHT | M25: Nederland | N25: 06-10294549 | P25: jamila1982@hotmail.com | Q25: definitief | R25: Veld - Week, Zaal - Week | S25: 230 | T25: Korfbal - Korfbal - Week | U25: Bondslid | V25: Pupil | W25: 43890
A26: =_xlfn.IFNA(VLOOKUP(D26,Spelerslijst!A:B,1,FALSE),FALSE) -> NKL60P7 | B26: =_xlfn.IFNA(VLOOKUP(D26,Spelerslijst!J:K,1,FALSE),FALSE) -> FALSE | C26: =IF(AND(A26=FALSE,B26=FALSE),"Onbekend","") | D26: NKL60P7 | E26: Reus, Kim de | F26: 38159 | G26: V | H26: Medanstraat | I26: 7 | K26: 3312 GX | L26: DORDRECHT | M26: Nederland | N26: 078-6139393 | O26: 078-6139393 | P26: cvadr@telfort.nl | Q26: definitief | R26: Veld - Week, Zaal - Week | S26: 210 | T26: Korfbal - Korfbal - Week | U26: Bondslid | V26: Junior | W26: 39934
A27: =_xlfn.IFNA(VLOOKUP(D27,Spelerslijst!A:B,1,FALSE),FALSE) -> FALSE | B27: =_xlfn.IFNA(VLOOKUP(D27,Spelerslijst!J:K,1,FALSE),FALSE) -> NJF24X2 | C27: =IF(AND(A27=FALSE,B27=FALSE),"Onbekend","") | D27: NJF24X2 | E27: Kalkeren, Robin van | F27: 35246 | G27: M | H27: Boeroestraat | I27: 17 | K27: 3312 HA | L27: DORDRECHT | M27: Nederland | N27: 06-37433979 | O27: 06-37433979 | P27: robinvankalkeren@hotmail.com | Q27: definitief | R27: Veld - Week, Zaal - Week | S27: 200 | T27: Korfbal - Korfbal - Week | U27: Bondslid | V27: Senior | W27: 37650
A28: =_xlfn.IFNA(VLOOKUP(D28,Spelerslijst!A:B,1,FALSE),FALSE) -> NJH51Q1 | B28: =_xlfn.IFNA(VLOOKUP(D28,Spelerslijst!J:K,1,FALSE),FALSE) -> FALSE | C28: =IF(AND(A28=FALSE,B28=FALSE),"Onbekend","") | D28: NJH51Q1 | E28: Verweij, Mirthe | F28: 34650 | G28: V | H28: Boeroestraat | I28: 17 | K28: 3312 HA | L28: DORDRECHT | M28: Nederland | N28: 06-83200520 | P28: mirtheverweij94@gmail.com | Q28: definitief | R28: Veld - Week, Zaal - Week | S28: 200 | T28: Korfbal - Korfbal - Week | U28: Bondslid | V28: Senior | W28: 38200
A29: =_xlfn.IFNA(VLOOKUP(D29,Spelerslijst!A:B,1,FALSE),FALSE) -> FALSE | B29: =_xlfn.IFNA(VLOOKUP(D29,Spelerslijst!J:K,1,FALSE),FALSE) -> NKJ95G2 | C29: =IF(AND(A29=FALSE,B29=FALSE),"Onbekend","") | D29: NKJ95G2 | E29: Oppe, Mees | F29: 37683 | G29: M | H29: Boeroestraat | I29: 89 | K29: 3312 HB | L29: DORDRECHT | M29: Nederland | N29: 06-24179974 | O29: 078-6311330 | P29: mees.oppe@gmail.com | Q29: definitief | R29: Veld - Week, Zaal - Week | S29: 210 | T29: Korfbal - Korfbal - Week | U29: Bondslid | V29: Junior | W29: 39753
A30: =_xlfn.IFNA(VLOOKUP(D30,Spelerslijst!A:B,1,FALSE),FALSE) -> NKJ95L7 | B30: =_xlfn.IFNA(VLOOKUP(D30,Spelerslijst!J:K,1,FALSE),FALSE) -> FALSE | C30: =IF(AND(A30=FALSE,B30=FALSE),"Onbekend","") | D30: NKJ95L7 | E30: Oppe, Milou | F30: 37307 | G30: V | H30: Boeroestraat | I30: 89 | K30: 3312 HB | L30: DORDRECHT | M30: Nederland | N30: 06-24175062 | O30: 078-6311330 | P30: milou.oppe@gmail.com | Q30: definitief | R30: Veld - Week, Zaal - Week | S30: 210 | T30: Korfbal - Korfbal - Week | U30: Bondslid | V30: Junior | W30: 39753
A31: =_xlfn.IFNA(VLOOKUP(D31,Spelerslijst!A:B,1,FALSE),FALSE) -> FALSE | B31: =_xlfn.IFNA(VLOOKUP(D31,Spelerslijst!J:K,1,FALSE),FALSE) -> NJC17J5 | C31: =IF(AND(A31=FALSE,B31=FALSE),"Onbekend","") | D31: NJC17J5 | E31: Gent, Lex van | F31: 34711 | G31: M | H31: Boeroestraat | I31: 42 | K31: 3312 HC | L31: DORDRECHT | M31: Nederland | N31: 06-41457456 | O31: 078-8442745 | P31: lexvgent@gmail.com | Q31: definitief | R31: Veld - Week, Zaal - Week | S31: 200 | T31: Korfbal - Korfbal - Week | U31: Bondslid | V31: Senior | W31: 37153
A32: =_xlfn.IFNA(VLOOKUP(D32,Spelerslijst!A:B,1,FALSE),FALSE) -> NJF17P0 | B32: =_xlfn.IFNA(VLOOKUP(D32,Spelerslijst!J:K,1,FALSE),FALSE) -> FALSE | C32: =IF(AND(A32=FALSE,B32=FALSE),"Onbekend","") | D32: NJF17P0 | E32: Leijdsman, Robin | F32: 35195 | G32: V | H32: Boeroestraat | I32: 42 | K32: 3312 HC | L32: DORDRECHT | M32: Nederland | N32: 078-6166096 | O32: 078-6166096 | P32: robinleijdsman@gmail.com | Q32: definitief | R32: Veld - Week, Zaal - Week | S32: 200 | T32: Korfbal - Korfbal - Week | U32: Bondslid | V32: Senior | W32: 37502
A33: =_xlfn.IFNA(VLOOKUP(D33,Spelerslijst!A:B,1,FALSE),FALSE) -> FALSE | B33: =_xlfn.IFNA(VLOOKUP(D33,Spelerslijst!J:K,1,FALSE),FALSE) -> NKR24P5 | C33: =IF(AND(A33=FALSE,B33=FALSE),"Onbekend","") | D33: NKR24P5 | E33: Hoeve, Milan ten | F33: 37897 | G33: M | H33: Floresstraat | I33: 81 | K33: 3312 HG | L33: DORDRECHT | M33: Nederland | N33: 06-42203662 | O33: 078-6134080 | P33: milantenhoeve@kpnmail.nl | Q33: definitief | R33: Veld - Week, Zaal - Week | S33: 210 | T33: Korfbal - Korfbal - Week | U33: Bondslid | V33: Junior | W33: 40422
A34: =_xlfn.IFNA(VLOOKUP(D34,Spelerslijst!A:B,1,FALSE),FALSE) -> NLG57M4 | B34: =_xlfn.IFNA(VLOOKUP(D34,Spelerslijst!J:K,1,FALSE),FALSE) -> FALSE | C34: =IF(AND(A34=FALSE,B34=FALSE),"Onbekend","") | D34: NLG57M4 | E34: Hoeve, Senne ten | F34: 39006 | G34: V | H34: Floresstraat | I34: 81 | K34: 3312 HG | L34: DORDRECHT | M34: Nederland | N34: 06-38734564 | P34: fam.tenhoeve@kpnmail.nl | Q34: definitief | R34: Veld - Week, Zaal - Week | S34: 220 | T34: Korfbal - Korfbal - Week | U34: Bondslid | V34: Aspirant | W34: 41518
A35: =_xlfn.IFNA(VLOOKUP(D35,Spelerslijst!A:B,1,FALSE),FALSE) -> NLP78D3 | B35: =_xlfn.IFNA(VLOOKUP(D35,Spelerslijst!J:K,1,FALSE),FALSE) -> FALSE | C35: =IF(AND(A35=FALSE,B35=FALSE),"Onbekend","") | D35: NLP78D3 | E35: Linden, Benthe van der | F35: 39629 | G35: V | H35: Floresstraat | I35: 26 | K35: 3312 HH | L35: DORDRECHT | M35: Nederland | N35: 06-48507085 | O35: 078-6470115 | P35: maaike_mol86@hotmail.com | Q35: definitief | R35: Veld - Week, Zaal - Week | S35: 220 | T35: Korfbal - Korfbal - Week | U35: Bondslid | V35: Aspirant | W35: 42248
A36: =_xlfn.IFNA(VLOOKUP(D36,Spelerslijst!A:B,1,FALSE),FALSE) -> NMH37W2 | B36: =_xlfn.IFNA(VLOOKUP(D36,Spelerslijst!J:K,1,FALSE),FALSE) -> FALSE | C36: =IF(AND(A36=FALSE,B36=FALSE),"Onbekend","") | D36: NMH37W2 | E36: Linden, Ize van der | F36: 41662 | G36: V | H36: Floresstraat | I36: 26 | K36: 3312 HH | L36: DORDRECHT | M36: Nederland | N36: 06-48507085 | P36: maaike_mol86@hotmail.com | Q36: definitief | R36: Veld - Week, Zaal - Week | S36: 230 | T36: Korfbal - Korfbal - Week | U36: Bondslid | V36: Pupil | W36: 43749
A37: =_xlfn.IFNA(VLOOKUP(D37,Spelerslijst!A:B,1,FALSE),FALSE) -> NKK48D6 | B37: =_xlfn.IFNA(VLOOKUP(D37,Spelerslijst!J:K,1,FALSE),FALSE) -> FALSE | C37: =IF(AND(A37=FALSE,B37=FALSE),"Onbekend","") | D37: NKK48D6 | E37: Mol, Laura | F37: 38079 | G37: V | H37: Soembastraat | I37: 80 | K37: 3312 HW | L37: DORDRECHT | M37: Nederland | N37: 06-27437017 | O37: 078-6319949 | P37: lauraadrianamol@gmail.com | Q37: definitief | R37: Veld - Week, Zaal - Week | S37: 210 | T37: Korfbal - Korfbal - Week | U37: Bondslid | V37: Junior | W37: 39814
A38: =_xlfn.IFNA(VLOOKUP(D38,Spelerslijst!A:B,1,FALSE),FALSE) -> NLP78G4 | B38: =_xlfn.IFNA(VLOOKUP(D38,Spelerslijst!J:K,1,FALSE),FALSE) -> FALSE | C38: =IF(AND(A38=FALSE,B38=FALSE),"Onbekend","") | D38: NLP78G4 | E38: Bozuwa, Julia | F38: 39274 | G38: V | H38: Heysterbachstraat | I38: 77 | K38: 3312 JH | L38: DORDRECHT | M38: Nederland | N38: 06-42741987 | P38: barboos@kpnmail.nl | Q38: definitief | R38: Veld - Week, Zaal - Week | S38: 220 | T38: Korfbal - Korfbal - Week | U38: Bondslid | V38: Aspirant | W38: 42248
A39: =_xlfn.IFNA(VLOOKUP(D39,Spelerslijst!A:B,1,FALSE),FALSE) -> NLG58Z8 | B39: =_xlfn.IFNA(VLOOKUP(D39,Spelerslijst!J:K,1,FALSE),FALSE) -> FALSE | C39: =IF(AND(A39=FALSE,B39=FALSE),"Onbekend","") | D39: NLG58Z8 | E39: Nobel, Merle | F39: 38847 | G39: V | H39: Werkenmondestraat | I39: 8 | K39: 3312 JW | L39: DORDRECHT | M39: Nederland | N39: 06-14637415 | O39: 078-6351371 | P39: martinewimnobel@gmail.com | Q39: af te melden | R39: Veld - Week, Zaal - Week | S39: 220 | T39: Korfbal - Korfbal - Week | U39: Bondslid | V39: Aspirant | W39: 41518 | X39: 44377
A40: =_xlfn.IFNA(VLOOKUP(D40,Spelerslijst!A:B,1,FALSE),FALSE) -> FALSE | B40: =_xlfn.IFNA(VLOOKUP(D40,Spelerslijst!J:K,1,FALSE),FALSE) -> NMK85P5 | C40: =IF(AND(A40=FALSE,B40=FALSE),"Onbekend","") | D40: NMK85P5 | E40: Pichel, Timo | F40: 39996 | G40: M | H40: Wijnie Jabaaijlaan | I40: 15 | K40: 3312 KA | L40: DORDRECHT | M40: Nederland | N40: 06-20964405 | P40: ckv.ow@dpic.33mail.com | Q40: definitief | R40: Veld - Week, Zaal - Week | S40: 230 | T40: Korfbal - Korfbal - Week | U40: Bondslid | V40: Pupil | W40: 44089
...
