Workbook

Sheet Teamsamenstelling
A2: Selecties | B2: S1S2 | K2: =AVERAGE(F4:F24,K4:K24) -> 23.782727 | M2: U19 | V2: =AVERAGE(Q4:Q24,V4:V24) -> 17.663889 | X2: U17 | AG2: =AVERAGE(AB4:AB24,AG4:AG24) -> 15.826667 | AI2: U15 | AR2: =AVERAGE(AM4:AM24,AR4:AR24) -> #DIV/0!
B3: =CONCATENATE("Dames (",COUNTA(E4:E19),")") -> Dames (11) | G3: =CONCATENATE("Heren (",COUNTA(J4:J19),")") -> Heren (11) | M3: =CONCATENATE("Dames (",COUNTA(P4:P19),")") -> Dames (9) | R3: =CONCATENATE("Heren (",COUNTA(U4:U19),")") -> Heren (9) | X3: =CONCATENATE("Dames (",COUNTA(AA4:AA19),")") -> Dames (10) | AC3: =CONCATENATE("Heren (",COUNTA(AF4:AF19),")") -> Heren (8) | AI3: =CONCATENATE("Dames (",COUNTA(AL4:AL19),")") -> Dames (1) | AN3: =CONCATENATE("Heren (",COUNTA(AQ4:AQ19),")") -> Heren (1)
B4: {=_xlfn._xlws.FILTER(Spelerslijst!$B:$B,Spelerslijst!$F:$F=B$2,"")} -> Klooster, C. (Carmen) van der | C4: {=_xlfn._xlws.FILTER(Spelerslijst!$I:$I,Spelerslijst!$F:$F=B$2,"")} -> 0 | D4: {=_xlfn._xlws.FILTER(Spelerslijst!$J:$J,Spelerslijst!$F:$F=B$2,"")} -> 0 | E4: {=_xlfn._xlws.FILTER(Spelerslijst!$H:$H,Spelerslijst!$F:$F=B$2,"")} -> A1 | F4: {=_xlfn._xlws.FILTER(Spelerslijst!$D:$D,Spelerslijst!$F:$F=B$2,"")} -> 17.14 | G4: {=_xlfn._xlws.FILTER(Spelerslijst!$M:$M,Spelerslijst!$Q:$Q=B$2,"")} -> Strijen, L.A. van (Lars) | H4: {=_xlfn._xlws.FILTER(Spelerslijst!$T:$T,Spelerslijst!$Q:$Q=B$2,"")} -> 0 | I4: {=_xlfn._xlws.FILTER(Spelerslijst!$U:$U,Spelerslijst!$Q:$Q=B$2,"")} -> 0 | J4: {=_xlfn._xlws.FILTER(Spelerslijst!$S:$S,Spelerslijst!$Q:$Q=B$2,"")} -> 3 | K4: {=_xlfn._xlws.FILTER(Spelerslijst!$O:$O,Spelerslijst!$Q:$Q=B$2,"")} -> 35 | M4: {=_xlfn._xlws.FILTER(Spelerslijst!$B:$B,Spelerslijst!$F:$F=M$2,"")} -> Klooster, D. (Danique) van der | N4: {=_xlfn._xlws.FILTER(Spelerslijst!$I:$I,Spelerslijst!$F:$F=M$2,"")} -> 0 | O4: {=_xlfn._xlws.FILTER(Spelerslijst!$J:$J,Spelerslijst!$F:$F=M$2,"")} -> 0 | P4: {=_xlfn._xlws.FILTER(Spelerslijst!$H:$H,Spelerslijst!$F:$F=M$2,"")} -> B1 | Q4: {=_xlfn._xlws.FILTER(Spelerslijst!$D:$D,Spelerslijst!$F:$F=M$2,"")} -> 15.83 | R4: {=_xlfn._xlws.FILTER(Spelerslijst!$M:$M,Spelerslijst!$Q:$Q=M$2,"")} -> Dongen, F.P.B. (Freek) van | S4: {=_xlfn._xlws.FILTER(Spelerslijst!$T:$T,Spelerslijst!$Q:$Q=M$2,"")} -> 0 | T4: {=_xlfn._xlws.FILTER(Spelerslijst!$U:$U,Spelerslijst!$Q:$Q=M$2,"")} -> 0 | U4: {=_xlfn._xlws.FILTER(Spelerslijst!$S:$S,Spelerslijst!$Q:$Q=M$2,"")} -> A2 | V4: {=_xlfn._xlws.FILTER(Spelerslijst!$O:$O,Spelerslijst!$Q:$Q=M$2,"")} -> 18.69 | X4: {=_xlfn._xlws.FILTER(Spelerslijst!$B:$B,Spelerslijst!$F:$F=X$2,"")} -> Kleingeld, J.N. (Julia) | Y4: {=_xlfn._xlws.FILTER(Spelerslijst!$I:$I,Spelerslijst!$F:$F=X$2,"")} -> 0 | Z4: {=_xlfn._xlws.FILTER(Spelerslijst!$J:$J,Spelerslijst!$F:$F=X$2,"")} -> 0 | AA4: {=_xlfn._xlws.FILTER(Spelerslijst!$H:$H,Spelerslijst!$F:$F=X$2,"")} -> B1 | AB4: {=_xlfn._xlws.FILTER(Spelerslijst!$D:$D,Spelerslijst!$F:$F=X$2,"")} -> 15.27 | AC4: {=_xlfn._xlws.FILTER(Spelerslijst!$M:$M,Spelerslijst!$Q:$Q=X$2,"")} -> Pichel, T. (Timo) | AD4: {=_xlfn._xlws.FILTER(Spelerslijst!$T:$T,Spelerslijst!$Q:$Q=X$2,"")} -> 0 | AE4: {=_xlfn._xlws.FILTER(Spelerslijst!$U:$U,Spelerslijst!$Q:$Q=X$2,"")} -> 0 | AF4: {=_xlfn._xlws.FILTER(Spelerslijst!$S:$S,Spelerslijst!$Q:$Q=X$2,"")} -> B2 | AG4: {=_xlfn._xlws.FILTER(Spelerslijst!$O:$O,Spelerslijst!$Q:$Q=X$2,"")} -> 16.5 | AI4: {=_xlfn._xlws.FILTER(Spelerslijst!$B:$B,Spelerslijst!$F:$F=AI$2,"")} | AJ4: {=_xlfn._xlws.FILTER(Spelerslijst!$I:$I,Spelerslijst!$F:$F=AI$2,"")} | AK4: {=_xlfn._xlws.FILTER(Spelerslijst!$J:$J,Spelerslijst!$F:$F=AI$2,"")} | AL4: {=_xlfn._xlws.FILTER(Spelerslijst!$H:$H,Spelerslijst!$F:$F=AI$2,"")} | AM4: {=_xlfn._xlws.FILTER(Spelerslijst!$D:$D,Spelerslijst!$F:$F=AI$2,"")} | AN4: {=_xlfn._xlws.FILTER(Spelerslijst!$M:$M,Spelerslijst!$Q:$Q=AI$2,"")} | AO4: {=_xlfn._xlws.FILTER(Spelerslijst!$T:$T,Spelerslijst!$Q:$Q=AI$2,"")} | AP4: {=_xlfn._xlws.FILTER(Spelerslijst!$U:$U,Spelerslijst!$Q:$Q=AI$2,"")} | AQ4: {=_xlfn._xlws.FILTER(Spelerslijst!$S:$S,Spelerslijst!$Q:$Q=AI$2,"")} | AR4: {=_xlfn._xlws.FILTER(Spelerslijst!$O:$O,Spelerslijst!$Q:$Q=AI$2,"")}
B5: Fasbender, L. (Lindi) | C5: 0 | D5: 0 | E5: 2 | F5: 20.17 | G5: Klink, M (Marijn) | H5: 0 | I5: 0 | J5: 1 | K5: 28.67 | M5: Reuvers, L. (Lisa) | N5: 0 | O5: 0 | P5: A1 | Q5: 16.51 | R5: Bäcker, C.J. (Tijn) | S5: 0 | T5: 0 | U5: A2 | V5: 18.57 | X5: Stomp, N. (Noa) | Y5: 0 | Z5: 0 | AA5: B1 | AB5: 15.29 | AC5: Vliet, K.M. (Kian) | AD5: 0 | AE5: 0 | AF5: B1 | AG5: 16.33
B6: Boshoven, S.A.E. (Sara) | C6: 0 | D6: 0 | E6: 2 | F6: 20.23 | G6: Driesprong, B. (Bart) | H6: 0 | I6: 0 | J6: 1 | K6: 27.23 | M6: Burgt, E. (Elize) van de | N6: 0 | O6: 0 | P6: A2 | Q6: 17.02 | R6: Vliet, T. (Tycho) | S6: 0 | T6: 0 | U6: - | V6: 18.28 | X6: Burgt, F. (Feline) van de | Y6: 0 | Z6: 0 | AA6: B2 | AB6: 15.31 | AC6: Sempel, J.D. (Jasper) | AD6: 0 | AE6: 0 | AF6: B1 | AG6: 16.21
B7: Groeneweg, R.K. (Roos) | C7: 0 | D7: 0 | E7: 2 | F7: 20.78 | G7: Klink, O.C. (Olivier) | H7: 0 | I7: 0 | J7: 2 | K7: 27.05 | M7: Voorbij, D.M. (Doeska) | N7: 0 | O7: 0 | P7: A2 | Q7: 17.17 | R7: Zwanenburg, J. (Jack) | S7: 0 | T7: 0 | U7: A1 | V7: 18.25 | X7: Boer, E.M. (Esmée) de | Y7: 0 | Z7: 0 | AA7: C1 | AB7: 15.59 | AC7: Hovestadt, D. (Diederik) | AD7: 0 | AE7: 0 | AF7: B2 | AG7: 16.18
B8: Driesprong, M. (Meike) | C8: 0 | D8: 0 | E8: 1 | F8: 21.93 | G8: Gent, T. (Tim) van | H8: 0 | I8: 0 | J8: 1 | K8: 25.89 | M8: Linden, B.S. (Benthe) van der | N8: 0 | O8: 0 | P8: A2 | Q8: 17.5 | R8: Valk, J.B. (Jarno) | S8: 0 | T8: 0 | U8: A1 | V8: 18.22 | X8: Engelfriet, D. (Demi) | Y8: 0 | Z8: 0 | AA8: B1 | AB8: 15.59 | AC8: Bemer, J.L.E. (Jarno) | AD8: 0 | AE8: 0 | AF8: B2 | AG8: 16.03
B9: Fernhout, L. (Loïs) | C9: 0 | D9: 0 | E9: 2 | F9: 22.83 | G9: Groeneweg, T. (Tim) | H9: 0 | I9: 0 | J9: - | K9: 24.03 | M9: Verboom, S. (Stella) | N9: 0 | O9: 0 | P9: A2 | Q9: 17.69 | R9: Dekker, O.C. (Onno) den | S9: 0 | T9: 0 | U9: B1 | V9: 17.52 | X9: Jongkind, F.W.J. (Floortje) | Y9: 0 | Z9: 0 | AA9: B2 | AB9: 15.82 | AC9: Sas, N. (Niek) | AD9: 0 | AE9: 0 | AF9: B1 | AG9: 15.44
B10: Teerds, E.L. (Eva) | C10: 0 | D10: 0 | E10: 2 | F10: 23.19 | G10: Uijl, D. (Daniel) den | H10: 0 | I10: 0 | J10: 2 | K10: 22.42 | M10: Kilsdonk, S.A (Sophie) | N10: 0 | O10: 0 | P10: A2 | Q10: 17.75 | R10: Sas, M. (Maarten) | S10: 0 | T10: 0 | U10: A2 | V10: 17.35 | X10: Volker, T.N. (Tess) | Y10: 0 | Z10: 0 | AA10: C1 | AB10: 15.87 | AC10: Ven, J. (Jonas) van de | AD10: 0 | AE10: 0 | AF10: B2 | AG10: 15.36
B11: Oppe, M. (Milou) | C11: 0 | D11: 0 | E11: 1 | F11: 23.86 | G11: Timmer, J. (Jordan) | H11: 0 | I11: 0 | J11: 2 | K11: 21.93 | M11: Manduapessy, M. (Merel) | N11: 0 | O11: 0 | P11: A1 | Q11: 18.34 | R11: Camphens, T. (Tijn) | S11: 0 | T11: 0 | U11: A2 | V11: 17.19 | X11: Lindhout, D. (Demi) | Y11: 0 | Z11: 0 | AA11: B2 | AB11: 15.97 | AC11: Vos, T. (Thomas) | AD11: 0 | AE11: 0 | AF11: B2 | AG11: 15.27
B12: Dijk, D. (Demi) van | C12: 0 | D12: 0 | E12: 2 | F12: 24.87 | G12: Koster, S. (Senne) | H12: 0 | I12: 0 | J12: 2 | K12: 20.16 | M12: Haas, A. (Amber) de | N12: 0 | O12: 0 | P12: A1 | Q12: 18.91 | R12: Heersping, D.B.A.C. (Dani) | S12: 0 | T12: 0 | U12: A2 | V12: 17.16 | X12: Bemer, G.M.E. (Githa) | Y12: 0 | Z12: 0 | AA12: B2 | AB12: 16.03
B13: Dommisse, R. (Robin) | C13: 0 | D13: 0 | E13: - | F13: 27.13 | G13: Burgt, S. (Seth) van de | H13: 0 | I13: 0 | J13: A2 | K13: 19.18 | X13: Lohuis, F.A.C. (Floor) | Y13: 0 | Z13: 0 | AA13: B2 | AB13: 16.82
B14: Klink, X (Xanne) | C14: 0 | D14: 0 | E14: 1 | F14: 30.49 | G14: Vaartmans, J.A. (Jordi) | H14: 0 | I14: 0 | J14: A1 | K14: 19.04
B20: {=_xlfn._xlws.FILTER(Staf!$C:$C,Staf!$B:$B=Teamsamenstelling!B2,"")} -> Trainer/Coach S1 | G20: {=_xlfn._xlws.FILTER(Staf!$A:$A,Staf!$B:$B=Teamsamenstelling!B2,"")} -> Menno Kop | M20: {=_xlfn._xlws.FILTER(Staf!$C:$C,Staf!$B:$B=Teamsamenstelling!M2,"")} -> Trainer/Coach U19-1 | R20: {=_xlfn._xlws.FILTER(Staf!$A:$A,Staf!$B:$B=Teamsamenstelling!M2,"")} -> Arthyn Muller | X20: {=_xlfn._xlws.FILTER(Staf!$C:$C,Staf!$B:$B=Teamsamenstelling!X2,"")} -> Trainer/Coach U17-1 | AC20: {=_xlfn._xlws.FILTER(Staf!$A:$A,Staf!$B:$B=Teamsamenstelling!X2,"")} -> Jasper Kleingeld | AI20: {=_xlfn._xlws.FILTER(Staf!$C:$C,Staf!$B:$B=#REF!,"")} -> #REF! | AL20: {=_xlfn._xlws.FILTER(Staf!$A:$A,Staf!$B:$B=#REF!,"")} -> #REF!
B21: Trainer/Coach S1 | G21: Niels Mastijn | M21: Trainer/Coach U19-1 | R21: Lianne Stomp - vd Burgt | X21: Trainer/Coach U17-1 | AC21: Mees Oppe
B22: Trainer/Coach S2 | G22: Rene te Witt | M22: Trainer/Coach U19-2 | R22: Jens Lohuis | X22: Trainer/Coach U17-2 | AC22: Alex de Boer
B23: Teammanager S2 | G23: Fred Lichteveld | M23: Trainer/Coach U19-2 | R23: Joël Wietses | X23: Trainer/Coach U17-2 | AC23: Tom van de Ven
B24: Fysio | G24: Ruben Kamerbeek | X24: Teammanager U17 | AC24: Alex van de Klooster
B25: Verzorger | G25: Anouk de Jongh | X25: Ondersteuning U17 | AC25: Bas de Jong
B26: Analist S1 | G26: Joris van den Neucker
A29: Senioren | B29: S1 | K29: =AVERAGE(F31:F42,K31:K42) -> #DIV/0! | M29: S2 | V29: =AVERAGE(Q31:Q42,V31:V42) -> #DIV/0! | X29: S3 | AG29: =AVERAGE(AB31:AB42,AG31:AG42) -> 33.376154 | AI29: S4 | AR29: =AVERAGE(AM31:AM42,AR31:AR42) -> 28.753571 | AT29: S5 | BC29: =AVERAGE(AX31:AX42,BC31:BC42) -> 24.497 | BE29: S6 | BN29: =AVERAGE(BI31:BI42,BN31:BN42) -> 22.101333 | BP29: S7 | BY29: =AVERAGE(BT31:BT42,BY31:BY42) -> #DIV/0! | CA29: MW1 | CJ29: =AVERAGE(CE31:CE42,CJ31:CJ42) -> 40.26
B30: =CONCATENATE("Dames (",COUNTA(E31:E40),")") -> Dames (1) | G30: =CONCATENATE("Heren (",COUNTA(J31:J40),")") -> Heren (1) | M30: =CONCATENATE("Dames (",COUNTA(P31:P40),")") -> Dames (1) | R30: =CONCATENATE("Heren (",COUNTA(U31:U40),")") -> Heren (1) | X30: =CONCATENATE("Dames (",COUNTA(AA31:AA40),")") -> Dames (7) | AC30: =CONCATENATE("Heren (",COUNTA(AF31:AF40),")") -> Heren (6) | AI30: =CONCATENATE("Dames (",COUNTA(AL31:AL40),")") -> Dames (9) | AN30: =CONCATENATE("Heren (",COUNTA(AQ31:AQ40),")") -> Heren (5) | AT30: =CONCATENATE("Dames (",COUNTA(AW31:AW40),")") -> Dames (6) | AY30: =CONCATENATE("Heren (",COUNTA(BB31:BB40),")") -> Heren (4) | BE30: =CONCATENATE("Dames (",COUNTA(BH31:BH40),")") -> Dames (7) | BJ30: =CONCATENATE("Heren (",COUNTA(BM31:BM40),")") -> Heren (8) | BP30: =CONCATENATE("Dames (",COUNTA(BS31:BS40),")") -> Dames (1) | BU30: =CONCATENATE("Heren (",COUNTA(BX31:BX40),")") -> Heren (1) | CA30: =CONCATENATE("Dames (",COUNTA(CD31:CD40),")") -> Dames (5) | CF30: =CONCATENATE("Heren (",COUNTA(CI31:CI40),")") -> Heren (3)
B31: {=_xlfn._xlws.FILTER(Spelerslijst!$B:$B,Spelerslijst!$F:$F=B$29,"")} | C31: {=_xlfn._xlws.FILTER(Spelerslijst!$I:$I,Spelerslijst!$F:$F=B$29,"")} | D31: {=_xlfn._xlws.FILTER(Spelerslijst!$J:$J,Spelerslijst!$F:$F=B$29,"")} | E31: {=_xlfn._xlws.FILTER(Spelerslijst!$H:$H,Spelerslijst!$F:$F=B$29,"")} | F31: {=_xlfn._xlws.FILTER(Spelerslijst!$D:$D,Spelerslijst!$F:$F=B$29,"")} | G31: {=_xlfn._xlws.FILTER(Spelerslijst!$M:$M,Spelerslijst!$Q:$Q=B$29,"")} | H31: {=_xlfn._xlws.FILTER(Spelerslijst!$T:$T,Spelerslijst!$Q:$Q=B$29,"")} | I31: {=_xlfn._xlws.FILTER(Spelerslijst!$U:$U,Spelerslijst!$Q:$Q=B$29,"")} | J31: {=_xlfn._xlws.FILTER(Spelerslijst!$S:$S,Spelerslijst!$Q:$Q=B$29,"")} | K31: {=_xlfn._xlws.FILTER(Spelerslijst!$O:$O,Spelerslijst!$Q:$Q=B$29,"")} | M31: {=_xlfn._xlws.FILTER(Spelerslijst!$B:$B,Spelerslijst!$F:$F=M$29,"")} | N31: {=_xlfn._xlws.FILTER(Spelerslijst!$I:$I,Spelerslijst!$F:$F=M$29,"")} | O31: {=_xlfn._xlws.FILTER(Spelerslijst!$J:$J,Spelerslijst!$F:$F=M$29,"")} | P31: {=_xlfn._xlws.FILTER(Spelerslijst!$H:$H,Spelerslijst!$F:$F=M$29,"")} | Q31: {=_xlfn._xlws.FILTER(Spelerslijst!$D:$D,Spelerslijst!$F:$F=M$29,"")} | R31: {=_xlfn._xlws.FILTER(Spelerslijst!$M:$M,Spelerslijst!$Q:$Q=M$29,"")} | S31: {=_xlfn._xlws.FILTER(Spelerslijst!$T:$T,Spelerslijst!$Q:$Q=M$29,"")} | T31: {=_xlfn._xlws.FILTER(Spelerslijst!$U:$U,Spelerslijst!$Q:$Q=M$29,"")} | U31: {=_xlfn._xlws.FILTER(Spelerslijst!$S:$S,Spelerslijst!$Q:$Q=M$29,"")} | V31: {=_xlfn._xlws.FILTER(Spelerslijst!$O:$O,Spelerslijst!$Q:$Q=M$29,"")} | X31: {=_xlfn._xlws.FILTER(Spelerslijst!$B:$B,Spelerslijst!$F:$F=X$29,"")} -> Visser, R. (Renske) | Y31: {=_xlfn._xlws.FILTER(Spelerslijst!$I:$I,Spelerslijst!$F:$F=X$29,"")} -> 0 | Z31: {=_xlfn._xlws.FILTER(Spelerslijst!$J:$J,Spelerslijst!$F:$F=X$29,"")} -> 0 | AA31: {=_xlfn._xlws.FILTER(Spelerslijst!$H:$H,Spelerslijst!$F:$F=X$29,"")} -> 0 | AB31: {=_xlfn._xlws.FILTER(Spelerslijst!$D:$D,Spelerslijst!$F:$F=X$29,"")} -> 27.32 | AC31: {=_xlfn._xlws.FILTER(Spelerslijst!$M:$M,Spelerslijst!$Q:$Q=X$29,"")} -> Vlaming, R. (Roy) de | AD31: {=_xlfn._xlws.FILTER(Spelerslijst!$T:$T,Spelerslijst!$Q:$Q=X$29,"")} -> 0 | AE31: {=_xlfn._xlws.FILTER(Spelerslijst!$U:$U,Spelerslijst!$Q:$Q=X$29,"")} -> 0 | AF31: {=_xlfn._xlws.FILTER(Spelerslijst!$S:$S,Spelerslijst!$Q:$Q=X$29,"")} -> 3 | AG31: {=_xlfn._xlws.FILTER(Spelerslijst!$O:$O,Spelerslijst!$Q:$Q=X$29,"")} -> 41.14 | AI31: {=_xlfn._xlws.FILTER(Spelerslijst!$B:$B,Spelerslijst!$F:$F=AI$29,"")} -> Jongh, A. (Anouk) de | AJ31: {=_xlfn._xlws.FILTER(Spelerslijst!$I:$I,Spelerslijst!$F:$F=AI$29,"")} -> 0 | AK31: {=_xlfn._xlws.FILTER(Spelerslijst!$J:$J,Spelerslijst!$F:$F=AI$29,"")} -> 0 | AL31: {=_xlfn._xlws.FILTER(Spelerslijst!$H:$H,Spelerslijst!$F:$F=AI$29,"")} -> 4 | AM31: {=_xlfn._xlws.FILTER(Spelerslijst!$D:$D,Spelerslijst!$F:$F=AI$29,"")} -> 20.33 | AN31: {=_xlfn._xlws.FILTER(Spelerslijst!$M:$M,Spelerslijst!$Q:$Q=AI$29,"")} -> Baars, L.A. (Luuk) | AO31: {=_xlfn._xlws.FILTER(Spelerslijst!$T:$T,Spelerslijst!$Q:$Q=AI$29,"")} -> 0 | AP31: {=_xlfn._xlws.FILTER(Spelerslijst!$U:$U,Spelerslijst!$Q:$Q=AI$29,"")} -> 0 | AQ31: {=_xlfn._xlws.FILTER(Spelerslijst!$S:$S,Spelerslijst!$Q:$Q=AI$29,"")} -> 4 | AR31: {=_xlfn._xlws.FILTER(Spelerslijst!$O:$O,Spelerslijst!$Q:$Q=AI$29,"")} -> 24.9 | AT31: {=_xlfn._xlws.FILTER(Spelerslijst!$B:$B,Spelerslijst!$F:$F=AT$29,"")} -> Valk, M.E. (Marlies) | AU31: {=_xlfn._xlws.FILTER(Spelerslijst!$I:$I,Spelerslijst!$F:$F=AT$29,"")} -> 0 | AV31: {=_xlfn._xlws.FILTER(Spelerslijst!$J:$J,Spelerslijst!$F:$F=AT$29,"")} -> 0 | AW31: {=_xlfn._xlws.FILTER(Spelerslijst!$H:$H,Spelerslijst!$F:$F=AT$29,"")} -> 5 | AX31: {=_xlfn._xlws.FILTER(Spelerslijst!$D:$D,Spelerslijst!$F:$F=AT$29,"")} -> 22.78 | AY31: {=_xlfn._xlws.FILTER(Spelerslijst!$M:$M,Spelerslijst!$Q:$Q=AT$29,"")} -> Schindler, M. (Mark) | AZ31: {=_xlfn._xlws.FILTER(Spelerslijst!$T:$T,Spelerslijst!$Q:$Q=AT$29,"")} -> 0 | BA31: {=_xlfn._xlws.FILTER(Spelerslijst!$U:$U,Spelerslijst!$Q:$Q=AT$29,"")} -> 0 | BB31: {=_xlfn._xlws.FILTER(Spelerslijst!$S:$S,Spelerslijst!$Q:$Q=AT$29,"")} -> 5 | BC31: {=_xlfn._xlws.FILTER(Spelerslijst!$O:$O,Spelerslijst!$Q:$Q=AT$29,"")} -> 26.59 | BE31: {=_xlfn._xlws.FILTER(Spelerslijst!$B:$B,Spelerslijst!$F:$F=BE$29,"")} -> Bozuwa, J. (Julia) | BF31: {=_xlfn._xlws.FILTER(Spelerslijst!$I:$I,Spelerslijst!$F:$F=BE$29,"")} -> 0 | BG31: {=_xlfn._xlws.FILTER(Spelerslijst!$J:$J,Spelerslijst!$F:$F=BE$29,"")} -> 0 | BH31: {=_xlfn._xlws.FILTER(Spelerslijst!$H:$H,Spelerslijst!$F:$F=BE$29,"")} -> A3 | BI31: {=_xlfn._xlws.FILTER(Spelerslijst!$D:$D,Spelerslijst!$F:$F=BE$29,"")} -> 18.47 | BJ31: {=_xlfn._xlws.FILTER(Spelerslijst!$M:$M,Spelerslijst!$Q:$Q=BE$29,"")} -> Dubbeld, R. (Ruben) | BK31: {=_xlfn._xlws.FILTER(Spelerslijst!$T:$T,Spelerslijst!$Q:$Q=BE$29,"")} -> 0 | BL31: {=_xlfn._xlws.FILTER(Spelerslijst!$U:$U,Spelerslijst!$Q:$Q=BE$29,"")} -> 0 | BM31: {=_xlfn._xlws.FILTER(Spelerslijst!$S:$S,Spelerslijst!$Q:$Q=BE$29,"")} -> 6 | BN31: {=_xlfn._xlws.FILTER(Spelerslijst!$O:$O,Spelerslijst!$Q:$Q=BE$29,"")} -> 25.07 | BP31: {=_xlfn._xlws.FILTER(Spelerslijst!$B:$B,Spelerslijst!$F:$F=BP$29,"")} | BQ31: {=_xlfn._xlws.FILTER(Spelerslijst!$I:$I,Spelerslijst!$F:$F=BP$29,"")} | BR31: {=_xlfn._xlws.FILTER(Spelerslijst!$J:$J,Spelerslijst!$F:$F=BP$29,"")} | BS31: {=_xlfn._xlws.FILTER(Spelerslijst!$H:$H,Spelerslijst!$F:$F=BP$29,"")} | BT31: {=_xlfn._xlws.FILTER(Spelerslijst!$D:$D,Spelerslijst!$F:$F=BP$29,"")} | BU31: {=_xlfn._xlws.FILTER(Spelerslijst!$M:$M,Spelerslijst!$Q:$Q=BP$29,"")} | BV31: {=_xlfn._xlws.FILTER(Spelerslijst!$T:$T,Spelerslijst!$Q:$Q=BP$29,"")} | BW31: {=_xlfn._xlws.FILTER(Spelerslijst!$U:$U,Spelerslijst!$Q:$Q=BP$29,"")} | BX31: {=_xlfn._xlws.FILTER(Spelerslijst!$S:$S,Spelerslijst!$Q:$Q=BP$29,"")} | BY31: {=_xlfn._xlws.FILTER(Spelerslijst!$O:$O,Spelerslijst!$Q:$Q=BP$29,"")} | CA31: {=_xlfn._xlws.FILTER(Spelerslijst!$B:$B,Spelerslijst!$F:$F=CA$29,"")} -> Brand, L (Liesbeth) | CB31: {=_xlfn._xlws.FILTER(Spelerslijst!$I:$I,Spelerslijst!$F:$F=CA$29,"")} -> 0 | CC31: {=_xlfn._xlws.FILTER(Spelerslijst!$J:$J,Spelerslijst!$F:$F=CA$29,"")} -> 0 | CD31: {=_xlfn._xlws.FILTER(Spelerslijst!$H:$H,Spelerslijst!$F:$F=CA$29,"")} -> MW1 | CE31: {=_xlfn._xlws.FILTER(Spelerslijst!$D:$D,Spelerslijst!$F:$F=CA$29,"")} -> 35.42 | CF31: {=_xlfn._xlws.FILTER(Spelerslijst!$M:$M,Spelerslijst!$Q:$Q=CA$29,"")} -> Kooij, C.W. (Wilco) | CG31: {=_xlfn._xlws.FILTER(Spelerslijst!$T:$T,Spelerslijst!$Q:$Q=CA$29,"")} -> 0 | CH31: {=_xlfn._xlws.FILTER(Spelerslijst!$U:$U,Spelerslijst!$Q:$Q=CA$29,"")} -> 0 | CI31: {=_xlfn._xlws.FILTER(Spelerslijst!$S:$S,Spelerslijst!$Q:$Q=CA$29,"")} -> MW1 | CJ31: {=_xlfn._xlws.FILTER(Spelerslijst!$O:$O,Spelerslijst!$Q:$Q=CA$29,"")} -> 50.32
X32: Leijdsman, R. (Robin) | Y32: 0 | Z32: 0 | AA32: 3 | AB32: 29.64 | AC32: Isarin, T P (Thomas) | AD32: 0 | AE32: 0 | AF32: 3 | AG32: 37.41 | AI32: Quarré, E.A. (Elena) | AJ32: 0 | AK32: 0 | AL32: 4 | AM32: 20.57 | AN32: Fasbender, T. (Tijmen) | AO32: 0 | AP32: 0 | AQ32: 4 | AR32: 22.48 | AT32: Pierse, A.W. (Anniek) | AU32: 0 | AV32: 0 | AW32: 5 | AX32: 23.81 | AY32: Flach, J.H. (Joram) | AZ32: 0 | BA32: 0 | BB32: 5 | BC32: 26.16 | BE32: Versnel, V. (Vivienne) | BF32: 0 | BG32: 0 | BH32: A3 | BI32: 20.46 | BJ32: Kooper, C. (Ché) | BK32: 0 | BL32: 0 | BM32: 6 | BN32: 23.15 | CA32: Starre-Scheurwater, K. (Kim) van der | CB32: 0 | CC32: 0 | CD32: MW1 | CE32: 36.08 | CF32: Jong, M. (Michiel) 't | CG32: 0 | CH32: 0 | CI32: MW1 | CJ32: 44.64
X33: Kalkeren-Verweij, M. (Mirthe) van | Y33: 0 | Z33: 0 | AA33: 3 | AB33: 31.13 | AC33: Houwerzijl, E. (Emiel) | AD33: 0 | AE33: 0 | AF33: 3 | AG33: 31.64 | AI33: Wensen, M. (Maud) | AJ33: 0 | AK33: 0 | AL33: 0 | AM33: 20.73 | AN33: Wietses, J. (Joël) | AO33: 0 | AP33: 0 | AQ33: 4 | AR33: 20.59 | AT33: Koote, L.D. (Laura) | AU33: 0 | AV33: 0 | AW33: 5 | AX33: 23.96 | AY33: Driel, Q. (Quinten) van | AZ33: 0 | BA33: 0 | BB33: 5 | BC33: 25.61 | BE33: Witman, K. (Kimberley) | BF33: 0 | BG33: 0 | BH33: 6 | BI33: 21.52 | BJ33: Boon, T. (Thijs) | BK33: 0 | BL33: 0 | BM33: 6 | BN33: 22.07 | CA33: Opstal-Haksteen, T.K. (Tamara) van | CB33: 0 | CC33: 0 | CD33: MW1 | CE33: 37.85 | CF33: Ploeg, H (Hans) | CG33: 0 | CH33: 0 | CI33: MW1 | CJ33: 37.92
X34: Gurp, M (Merel) van | Y34: 0 | Z34: 0 | AA34: 3 | AB34: 33.38 | AC34: Gent, L (Lex) van | AD34: 0 | AE34: 0 | AF34: 3 | AG34: 30.97 | AI34: Lievaart, C.A. (Carlijn) | AJ34: 0 | AK34: 0 | AL34: 4 | AM34: 21.23 | AN34: Lohuis, J.A. (Jens) | AO34: 0 | AP34: 0 | AQ34: 4 | AR34: 20.38 | AT34: Wit, N.M.T. (Nadia) de | AU34: 0 | AV34: 0 | AW34: 5 | AX34: 24.42 | AY34: Wijgaart, R.L.H. (Rick) van de | AZ34: 0 | BA34: 0 | BB34: 5 | BC34: 22.21 | BE34: Friebel, A. (Angela) | BF34: 0 | BG34: 0 | BH34: 6 | BI34: 23.22 | BJ34: Kuijper, D.V. (David) | BK34: 0 | BL34: 0 | BM34: 6 | BN34: 22.04 | CA34: Heesterbeek, K. (Kim) | CB34: 0 | CC34: 0 | CD34: MW1 | CE34: 38.96
X35: Ardon, L (Linda) | Y35: 0 | Z35: 0 | AA35: 3 | AB35: 33.75 | AC35: Brugge, B.R. (Bart) van der | AD35: 0 | AE35: 0 | AF35: 0 | AG35: 30.45 | AI35: Mol, L.N.A. (Laura) | AJ35: 0 | AK35: 0 | AL35: 4 | AM35: 21.75 | AN35: - Heer S1/S2 | AO35: 0 | AP35: 0 | AQ35: 0 | AR35: 6 | AT35: Wit, S.E.E. (Syrah) de | AU35: 0 | AV35: 0 | AW35: 5 | AX35: 24.42 | BE35: Dubbeld, S. (Sanne) | BF35: 0 | BG35: 0 | BH35: 6 | BI35: 23.89 | BJ35: Vlaming, J.C. (Jens) de | BK35: 0 | BL35: 0 | BM35: 6 | BN35: 22.03 | CA35: Veld, D. (Dorien) in 't | CB35: 0 | CC35: 0 | CD35: MW1 | CE35: 40.89
X36: Batenburg, H. (Hanneke) | Y36: 0 | Z36: 0 | AA36: 0 | AB36: 38.25 | AC36: Peuter, F. (Freek) | AD36: 0 | AE36: 0 | AF36: 0 | AG36: 29.69 | AI36: Dommisse, K. (Kim) | AJ36: 0 | AK36: 0 | AL36: 4 | AM36: 24.72 | AT36: Schram, L.J. (Lara) | AU36: 0 | AV36: 0 | AW36: 5 | AX36: 25.01 | BE36: Dubbeld, T. (Tessa) | BF36: 0 | BG36: 0 | BH36: 6 | BI36: 25.07 | BJ36: Koornneef, W.J. (Wouter) | BK36: 0 | BL36: 0 | BM36: 6 | BN36: 20.55
X37: Ploeg, L (Lieke) | Y37: 0 | Z37: 0 | AA37: 3 | AB37: 39.12 | AI37: - Dame S1/S2 | AJ37: 0 | AK37: 0 | AL37: 0 | AM37: 26 | BE37: Hulsker, N.M. (Nina) | BF37: 0 | BG37: 0 | BH37: S4 | BI37: 26.38 | BJ37: Koornneef, T.J. (Tommie) | BK37: 0 | BL37: 0 | BM37: A3 | BN37: 18.89
AI38: Knippenberg, R. (Rachel) | AJ38: 0 | AK38: 0 | AL38: 0 | AM38: 26.87 | BJ38: Pille, M.A. (Menno) | BK38: 0 | BL38: 0 | BM38: A3 | BN38: 18.71
AI39: Hoffman, M. (Merel) | AJ39: 0 | AK39: 0 | AL39: 0 | AM39: 126
B41: {=_xlfn._xlws.FILTER(Staf!$C:$C,Staf!$B:$B=Teamsamenstelling!B29,"")} | E41: {=_xlfn._xlws.FILTER(Staf!$A:$A,Staf!$B:$B=Teamsamenstelling!B29,"")} | M41: {=_xlfn._xlws.FILTER(Staf!$C:$C,Staf!$B:$B=Teamsamenstelling!M29,"")} | P41: {=_xlfn._xlws.FILTER(Staf!$A:$A,Staf!$B:$B=Teamsamenstelling!M29,"")} | X41: {=_xlfn._xlws.FILTER(Staf!$C:$C,Staf!$B:$B=Teamsamenstelling!X29,"")} -> Begeleider | AC41: {=_xlfn._xlws.FILTER(Staf!$A:$A,Staf!$B:$B=Teamsamenstelling!X29,"")} -> Kim Ardon | AI41: {=_xlfn._xlws.FILTER(Staf!$C:$C,Staf!$B:$B=Teamsamenstelling!AI29,"")} -> Trainer/Coach | AN41: {=_xlfn._xlws.FILTER(Staf!$A:$A,Staf!$B:$B=Teamsamenstelling!AI29,"")} -> Dio Naaktgeboren | AT41: {=_xlfn._xlws.FILTER(Staf!$C:$C,Staf!$B:$B=Teamsamenstelling!AT29,"")} | AY41: {=_xlfn._xlws.FILTER(Staf!$A:$A,Staf!$B:$B=Teamsamenstelling!AT29,"")} | BE41: {=_xlfn._xlws.FILTER(Staf!$C:$C,Staf!$B:$B=Teamsamenstelling!BE29,"")} | BJ41: {=_xlfn._xlws.FILTER(Staf!$A:$A,Staf!$B:$B=Teamsamenstelling!BE29,"")} | BP41: {=_xlfn._xlws.FILTER(Staf!$C:$C,Staf!$B:$B=Teamsamenstelling!BP29,"")} | BS41: {=_xlfn._xlws.FILTER(Staf!$A:$A,Staf!$B:$B=Teamsamenstelling!BP29,"")} | CA41: {=_xlfn._xlws.FILTER(Staf!$C:$C,Staf!$B:$B=Teamsamenstelling!CA29,"")} | CD41: {=_xlfn._xlws.FILTER(Staf!$A:$A,Staf!$B:$B=Teamsamenstelling!CA29,"")}
A45: Rood | B45: U17-1 | K45: =AVERAGE(F47:F57,K47:K57) -> #DIV/0! | M45: U17-2 | V45: =AVERAGE(Q47:Q57,V47:V57) -> #DIV/0! | X45: OW J1 | AG45: =AVERAGE(AB47:AB57,AG47:AG57) -> 16.41 | AI45: OW J2 | AR45: =AVERAGE(AM47:AM57,AR47:AR57) -> 15.423636 | AT45: -- | BC45: =AVERAGE(AX47:AX57,BC47:BC57) -> #DIV/0!
B46: =CONCATENATE("Dames (",COUNTA(E47:E55),")") -> Dames (1) | G46: =CONCATENATE("Heren (",COUNTA(J47:J55),")") -> Heren (1) | M46: =CONCATENATE("Dames (",COUNTA(P47:P55),")") -> Dames (1) | R46: =CONCATENATE("Heren (",COUNTA(U47:U55),")") -> Heren (1) | X46: =CONCATENATE("Dames (",COUNTA(AA47:AA55),")") -> Dames (6) | AC46: =CONCATENATE("Heren (",COUNTA(AF47:AF55),")") -> Heren (4) | AI46: =CONCATENATE("Dames (",COUNTA(AL47:AL55),")") -> Dames (8) | AN46: =CONCATENATE("Heren (",COUNTA(AQ47:AQ55),")") -> Heren (3) | AT46: =CONCATENATE("Dames (",COUNTA(AW47:AW55),")") -> Dames (1) | AY46: =CONCATENATE("Heren (",COUNTA(BB47:BB55),")") -> Heren (1)
B47: {=_xlfn._xlws.FILTER(Spelerslijst!$B:$B,Spelerslijst!$F:$F=B$45,"")} | C47: {=_xlfn._xlws.FILTER(Spelerslijst!$I:$I,Spelerslijst!$F:$F=B$45,"")} | D47: {=_xlfn._xlws.FILTER(Spelerslijst!$J:$J,Spelerslijst!$F:$F=B$45,"")} | E47: {=_xlfn._xlws.FILTER(Spelerslijst!$H:$H,Spelerslijst!$F:$F=B$45,"")} | F47: {=_xlfn._xlws.FILTER(Spelerslijst!$D:$D,Spelerslijst!$F:$F=B$45,"")} | G47: {=_xlfn._xlws.FILTER(Spelerslijst!$M:$M,Spelerslijst!$Q:$Q=B$45,"")} | H47: {=_xlfn._xlws.FILTER(Spelerslijst!$T:$T,Spelerslijst!$Q:$Q=B$45,"")} | I47: {=_xlfn._xlws.FILTER(Spelerslijst!$U:$U,Spelerslijst!$Q:$Q=B$45,"")} | J47: {=_xlfn._xlws.FILTER(Spelerslijst!$S:$S,Spelerslijst!$Q:$Q=B$45,"")} | K47: {=_xlfn._xlws.FILTER(Spelerslijst!$O:$O,Spelerslijst!$Q:$Q=B$45,"")} | M47: {=_xlfn._xlws.FILTER(Spelerslijst!$B:$B,Spelerslijst!$F:$F=M$45,"")} | N47: {=_xlfn._xlws.FILTER(Spelerslijst!$I:$I,Spelerslijst!$F:$F=M$45,"")} | O47: {=_xlfn._xlws.FILTER(Spelerslijst!$J:$J,Spelerslijst!$F:$F=M$45,"")} | P47: {=_xlfn._xlws.FILTER(Spelerslijst!$H:$H,Spelerslijst!$F:$F=M$45,"")} | Q47: {=_xlfn._xlws.FILTER(Spelerslijst!$D:$D,Spelerslijst!$F:$F=M$45,"")} | R47: {=_xlfn._xlws.FILTER(Spelerslijst!$M:$M,Spelerslijst!$Q:$Q=M$45,"")} | S47: {=_xlfn._xlws.FILTER(Spelerslijst!$T:$T,Spelerslijst!$Q:$Q=M$45,"")} | T47: {=_xlfn._xlws.FILTER(Spelerslijst!$U:$U,Spelerslijst!$Q:$Q=M$45,"")} | U47: {=_xlfn._xlws.FILTER(Spelerslijst!$S:$S,Spelerslijst!$Q:$Q=M$45,"")} | V47: {=_xlfn._xlws.FILTER(Spelerslijst!$O:$O,Spelerslijst!$Q:$Q=M$45,"")} | X47: {=_xlfn._xlws.FILTER(Spelerslijst!$B:$B,Spelerslijst!$F:$F=X$45,"")} -> Dekker, J. (Jordan) | Y47: {=_xlfn._xlws.FILTER(Spelerslijst!$I:$I,Spelerslijst!$F:$F=X$45,"")} -> 0 | Z47: {=_xlfn._xlws.FILTER(Spelerslijst!$J:$J,Spelerslijst!$F:$F=X$45,"")} -> 0 | AA47: {=_xlfn._xlws.FILTER(Spelerslijst!$H:$H,Spelerslijst!$F:$F=X$45,"")} -> - | AB47: {=_xlfn._xlws.FILTER(Spelerslijst!$D:$D,Spelerslijst!$F:$F=X$45,"")} -> 15.56 | AC47: {=_xlfn._xlws.FILTER(Spelerslijst!$M:$M,Spelerslijst!$Q:$Q=X$45,"")} -> Jongh, M. (Matthijs) de | AD47: {=_xlfn._xlws.FILTER(Spelerslijst!$T:$T,Spelerslijst!$Q:$Q=X$45,"")} -> 0 | AE47: {=_xlfn._xlws.FILTER(Spelerslijst!$U:$U,Spelerslijst!$Q:$Q=X$45,"")} -> 0 | AF47: {=_xlfn._xlws.FILTER(Spelerslijst!$S:$S,Spelerslijst!$Q:$Q=X$45,"")} -> A3 | AG47: {=_xlfn._xlws.FILTER(Spelerslijst!$O:$O,Spelerslijst!$Q:$Q=X$45,"")} -> 18.23 | AI47: {=_xlfn._xlws.FILTER(Spelerslijst!$B:$B,Spelerslijst!$F:$F=AI$45,"")} -> Jongkind, P. (Pippa) | AJ47: {=_xlfn._xlws.FILTER(Spelerslijst!$I:$I,Spelerslijst!$F:$F=AI$45,"")} -> 0 | AK47: {=_xlfn._xlws.FILTER(Spelerslijst!$J:$J,Spelerslijst!$F:$F=AI$45,"")} -> 0 | AL47: {=_xlfn._xlws.FILTER(Spelerslijst!$H:$H,Spelerslijst!$F:$F=AI$45,"")} -> B4 | AM47: {=_xlfn._xlws.FILTER(Spelerslijst!$D:$D,Spelerslijst!$F:$F=AI$45,"")} -> 14.31 | AN47: {=_xlfn._xlws.FILTER(Spelerslijst!$M:$M,Spelerslijst!$Q:$Q=AI$45,"")} -> Quarre, S.M. (Stephan) | AO47: {=_xlfn._xlws.FILTER(Spelerslijst!$T:$T,Spelerslijst!$Q:$Q=AI$45,"")} -> 0 | AP47: {=_xlfn._xlws.FILTER(Spelerslijst!$U:$U,Spelerslijst!$Q:$Q=AI$45,"")} -> 0 | AQ47: {=_xlfn._xlws.FILTER(Spelerslijst!$S:$S,Spelerslijst!$Q:$Q=AI$45,"")} -> B3 | AR47: {=_xlfn._xlws.FILTER(Spelerslijst!$O:$O,Spelerslijst!$Q:$Q=AI$45,"")} -> 16.82 | AT47: {=_xlfn._xlws.FILTER(Spelerslijst!$B:$B,Spelerslijst!$F:$F=AT45,"")} | AU47: {=_xlfn._xlws.FILTER(Spelerslijst!$I:$I,Spelerslijst!$F:$F=AT$45,"")} | AV47: {=_xlfn._xlws.FILTER(Spelerslijst!$J:$J,Spelerslijst!$F:$F=AT$45,"")} | AW47: {=_xlfn._xlws.FILTER(Spelerslijst!$H:$H,Spelerslijst!$F:$F=AT45,"")} | AX47: {=_xlfn._xlws.FILTER(Spelerslijst!$D:$D,Spelerslijst!$F:$F=AT45,"")} | AY47: {=_xlfn._xlws.FILTER(Spelerslijst!$M:$M,Spelerslijst!$Q:$Q=AT45,"")} | AZ47: {=_xlfn._xlws.FILTER(Spelerslijst!$T:$T,Spelerslijst!$Q:$Q=AT$45,"")} | BA47: {=_xlfn._xlws.FILTER(Spelerslijst!$U:$U,Spelerslijst!$Q:$Q=AT$45,"")} | BB47: {=_xlfn._xlws.FILTER(Spelerslijst!$S:$S,Spelerslijst!$Q:$Q=AT45,"")} | BC47: {=_xlfn._xlws.FILTER(Spelerslijst!$O:$O,Spelerslijst!$Q:$Q=AT45,"")}
X48: Peters, S.N. (Sanne) | Y48: 0 | Z48: 0 | AA48: B4 | AB48: 15.74 | AC48: Kuijper, R.A. (Raoul) | AD48: 0 | AE48: 0 | AF48: A3 | AG48: 17.5 | AI48: Bergh, M.J. (Marit) van den | AJ48: 0 | AK48: 0 | AL48: B3 | AM48: 15.01 | AN48: Linden, J.W.P. (Jurre) van der | AO48: 0 | AP48: 0 | AQ48: B4 | AR48: 15.65
X49: Dongen, M.J. (Madelief) van | Y49: 0 | Z49: 0 | AA49: B3 | AB49: 16.1 | AC49: Afsharbegloe, P. (Parham) | AD49: 0 | AE49: 0 | AF49: B4 | AG49: 16.23 | AI49: Wiel, D.N. (Danique) van der | AJ49: 0 | AK49: 0 | AL49: B3 | AM49: 15.01 | AN49: Post, J.M. (Joaz) | AO49: 0 | AP49: 0 | AQ49: B3 | AR49: 15.64
X50: Zwanenburg, R.J. (Robin) | Y50: 0 | Z50: 0 | AA50: A3 | AB50: 16.22 | AC50: Heeren, D. (Djess) van | AD50: 0 | AE50: 0 | AF50: B4 | AG50: 15.79 | AI50: Bouwknegt, E.L. (Enora) | AJ50: 0 | AK50: 0 | AL50: B3 | AM50: 15.09
X51: Veenendaal, E. (Eline) | Y51: 0 | Z51: 0 | AA51: B4 | AB51: 16.28 | AI51: Baas, N.J. (Nikki) | AJ51: 0 | AK51: 0 | AL51: B3 | AM51: 15.12
X52: Kamerman, Z. (Zoë) | Y52: 0 | Z52: 0 | AA52: A3 | AB52: 16.45 | AI52: Bakker, F. (Femke) | AJ52: 0 | AK52: 0 | AL52: B3 | AM52: 15.55
...

Sheet Spelerslijst
A1: Rel.nr | B1: Naam & Initialen) | C1: Roepnaam | D1: Leeftijd Peildatum | E1: Geb datum | F1: Team 25-26 | G1: Team 25-26 ALT | H1: Team 24-25 | I1: Notitie | J1: AR | L1: Rel.nr | M1: Naam & Initialen | N1: Roepnaam | O1: Leeftijd Peildatum | P1: Geb datum | Q1: Team 25-26 | R1: Team 25-26 ALT | S1: Team 24-252 | T1: Notitie | U1: AR
A2: NND41B5 | B2: Groot, S. (Senna) de | C2: Senna | D2: =ROUND( YEARFRAC( Tabel1[[#This Row],[Geb datum]], DATE(2025,12,31), 1 ), 2 ) -> 5.89 | E2: 43872 | F2: K | H2: - | L2: NKH71P1 | M2: Kooij, C.W. (Wilco) | N2: Wilco | O2: =ROUND( YEARFRAC( Tabel3[[#This Row],[Geb datum]], DATE(2025,12,31), 1 ), 2 ) -> 50.32 | P2: 27643 | Q2: MW1 | S2: MW1
A3: NMZ15W4 | B3: Merwe, F. (Floor) van de | C3: Floor | D3: =ROUND( YEARFRAC( Tabel1[[#This Row],[Geb datum]], DATE(2025,12,31), 1 ), 2 ) -> 6.28 | E3: 43728 | F3: OW J17 | H3: - | L3: NFW42X5 | M3: Jong, M. (Michiel) 't | N3: Michiel | O3: =ROUND( YEARFRAC( Tabel3[[#This Row],[Geb datum]], DATE(2025,12,31), 1 ), 2 ) -> 44.64 | P3: 29718 | Q3: MW1 | S3: MW1
A4: NND9850 | B4: Burgt, L. (Leah) van de | C4: Leah | D4: =ROUND( YEARFRAC( Tabel1[[#This Row],[Geb datum]], DATE(2025,12,31), 1 ), 2 ) -> 6.44 | E4: 43669 | F4: OW J17 | H4: - | L4: NKQ40P2 | M4: Vlaming, R. (Roy) de | N4: Roy | O4: =ROUND( YEARFRAC( Tabel3[[#This Row],[Geb datum]], DATE(2025,12,31), 1 ), 2 ) -> 41.14 | P4: 30994 | Q4: S3 | S4: 3
A5: NMZ53P9 | B5: Haren, C.M. (Cato) van | C5: Cato | D5: =ROUND( YEARFRAC( Tabel1[[#This Row],[Geb datum]], DATE(2025,12,31), 1 ), 2 ) -> 6.5 | E5: 43646 | F5: OW J16 | H5: F4 | L5: NGG54S2 | M5: Ploeg, H (Hans) | N5: Hans | O5: =ROUND( YEARFRAC( Tabel3[[#This Row],[Geb datum]], DATE(2025,12,31), 1 ), 2 ) -> 37.92 | P5: 32170 | Q5: MW1 | S5: MW1
A6: NNF08Z6 | B6: Struijk, F. (Fay) | C6: Fay | D6: =ROUND( YEARFRAC( Tabel1[[#This Row],[Geb datum]], DATE(2025,12,31), 1 ), 2 ) -> 6.67 | E6: 43586 | F6: OW J16 | L6: NGD51N5 | M6: Isarin, T P (Thomas) | N6: Thomas | O6: =ROUND( YEARFRAC( Tabel3[[#This Row],[Geb datum]], DATE(2025,12,31), 1 ), 2 ) -> 37.41 | P6: 32357 | Q6: S3 | S6: 3
A7: NND37V8 | B7: Nienes, N. (Nova) van | C7: Nova | D7: =ROUND( YEARFRAC( Tabel1[[#This Row],[Geb datum]], DATE(2025,12,31), 1 ), 2 ) -> 7.12 | E7: 43420 | F7: OW J16 | H7: F4 | L7: NGW00S1 | M7: Booy, J (Jan) | N7: Jan | O7: =ROUND( YEARFRAC( Tabel3[[#This Row],[Geb datum]], DATE(2025,12,31), 1 ), 2 ) -> 35.38 | P7: 33100 | Q7: Stopt | S7: 3
A8: NND11G5 | B8: Schaardenburg, L. (Luna) van | C8: Luna | D8: =ROUND( YEARFRAC( Tabel1[[#This Row],[Geb datum]], DATE(2025,12,31), 1 ), 2 ) -> 7.23 | E8: 43383 | F8: OW J15 | L8: NJF53H2 | M8: Strijen, L.A. van (Lars) | N8: Lars | O8: =ROUND( YEARFRAC( Tabel3[[#This Row],[Geb datum]], DATE(2025,12,31), 1 ), 2 ) -> 35 | P8: 33238 | Q8: S1S2 | S8: 3
A9: NND27N7 | B9: Tol, K. (Karlijn) van | C9: Karlijn | D9: =ROUND( YEARFRAC( Tabel1[[#This Row],[Geb datum]], DATE(2025,12,31), 1 ), 2 ) -> 7.28 | E9: 43363 | F9: OW J17 | H9: F4 | L9: NGT16K5 | M9: Naaktgeboren, S. (Stefan) | N9: Stefan | O9: =ROUND( YEARFRAC( Tabel3[[#This Row],[Geb datum]], DATE(2025,12,31), 1 ), 2 ) -> 34.99 | P9: 33241 | Q9: Stopt | S9: 4
B10: Ariadne | C10: Ariadne | D10: =ROUND( YEARFRAC( Tabel1[[#This Row],[Geb datum]], DATE(2025,12,31), 1 ), 2 ) -> 7.59 | E10: 43249 | F10: OW J15 | L10: NJC26C8 | M10: Houwerzijl, E. (Emiel) | N10: Emiel | O10: =ROUND( YEARFRAC( Tabel3[[#This Row],[Geb datum]], DATE(2025,12,31), 1 ), 2 ) -> 31.64 | P10: 34464 | Q10: S3 | S10: 3
A11: NMV77N3 | B11: Mans, L. (Lara) | C11: Lara | D11: =ROUND( YEARFRAC( Tabel1[[#This Row],[Geb datum]], DATE(2025,12,31), 1 ), 2 ) -> 7.69 | E11: 43215 | F11: OW J14 | H11: F1 | L11: NJC17J6 | M11: Gent, L (Lex) van | N11: Lex | O11: =ROUND( YEARFRAC( Tabel3[[#This Row],[Geb datum]], DATE(2025,12,31), 1 ), 2 ) -> 30.97 | P11: 34711 | Q11: S3 | S11: 3
A12: NMX49N6 | B12: Nawar, M. (Mayvin) | C12: Mayvin | D12: =ROUND( YEARFRAC( Tabel1[[#This Row],[Geb datum]], DATE(2025,12,31), 1 ), 2 ) -> 8.19 | E12: 43032 | F12: OW J15 | H12: F3 | L12: NJH39X4 | M12: Brugge, B.R. (Bart) van der | N12: Bart | O12: =ROUND( YEARFRAC( Tabel3[[#This Row],[Geb datum]], DATE(2025,12,31), 1 ), 2 ) -> 30.45 | P12: 34900 | Q12: S3
A13: NNB62G1 | B13: Jong, L.T.M. (Louisa) de | C13: Louisa | D13: =ROUND( YEARFRAC( Tabel1[[#This Row],[Geb datum]], DATE(2025,12,31), 1 ), 2 ) -> 8.24 | E13: 43014 | F13: OW J13 | H13: F2 | L13: NJG52P6 | M13: Peuter, F. (Freek) | N13: Freek | O13: =ROUND( YEARFRAC( Tabel3[[#This Row],[Geb datum]], DATE(2025,12,31), 1 ), 2 ) -> 29.69 | P13: 35179 | Q13: S3
A14: NMQ42K7 | B14: Lange, S. (Sanna) de | C14: Sanna | D14: =ROUND( YEARFRAC( Tabel1[[#This Row],[Geb datum]], DATE(2025,12,31), 1 ), 2 ) -> 8.26 | E14: 43006 | F14: OW J13 | H14: F2 | L14: NJF24X2 | M14: Kalkeren, R. (Robin) van | N14: Robin | O14: =ROUND( YEARFRAC( Tabel3[[#This Row],[Geb datum]], DATE(2025,12,31), 1 ), 2 ) -> 29.5 | P14: 35246 | Q14: Stopt | S14: 2
A15: NMZ21H2 | B15: Rombouts, T. (Tess) | C15: Tess | D15: =ROUND( YEARFRAC( Tabel1[[#This Row],[Geb datum]], DATE(2025,12,31), 1 ), 2 ) -> 8.31 | E15: 42987 | F15: OW J13 | H15: F2 | L15: NJF95S5 | M15: Mans, B. (Bob) | N15: Bob | O15: =ROUND( YEARFRAC( Tabel3[[#This Row],[Geb datum]], DATE(2025,12,31), 1 ), 2 ) -> 29.16 | P15: 35372 | Q15: Stopt | S15: 2
A16: NMV90Z6 | B16: Burgt, L. (Livia) van de | C16: Livia | D16: =ROUND( YEARFRAC( Tabel1[[#This Row],[Geb datum]], DATE(2025,12,31), 1 ), 2 ) -> 8.33 | E16: 42979 | F16: OW J14 | H16: F2 | L16: NJF77Y3 | M16: Klink, M (Marijn) | N16: Marijn | O16: =ROUND( YEARFRAC( Tabel3[[#This Row],[Geb datum]], DATE(2025,12,31), 1 ), 2 ) -> 28.67 | P16: 35550 | Q16: S1S2 | S16: 1
A17: NMV61M3 | B17: Stomp, A. (Alisa) | C17: Alisa | D17: =ROUND( YEARFRAC( Tabel1[[#This Row],[Geb datum]], DATE(2025,12,31), 1 ), 2 ) -> 8.5 | E17: 42919 | F17: OW J14 | H17: F1 | L17: NJD65S8 | M17: Dijk, J. (Joeri) van | N17: Joeri | O17: =ROUND( YEARFRAC( Tabel3[[#This Row],[Geb datum]], DATE(2025,12,31), 1 ), 2 ) -> 27.79 | P17: 35873 | Q17: Stopt | S17: 1
A18: NMM42W7 | B18: Jacobs, V. (Vive) | C18: Vive | D18: =ROUND( YEARFRAC( Tabel1[[#This Row],[Geb datum]], DATE(2025,12,31), 1 ), 2 ) -> 8.85 | E18: 42788 | F18: OW J12 | H18: E4 | L18: NKD19Y4 | M18: Driesprong, B. (Bart) | N18: Bart | O18: =ROUND( YEARFRAC( Tabel3[[#This Row],[Geb datum]], DATE(2025,12,31), 1 ), 2 ) -> 27.23 | P18: 36077 | Q18: S1S2 | S18: 1
A19: NMV75Z1 | B19: Berg, W. (Wies) van den | C19: Wies | D19: =ROUND( YEARFRAC( Tabel1[[#This Row],[Geb datum]], DATE(2025,12,31), 1 ), 2 ) -> 9.06 | E19: 42713 | F19: OW J12 | H19: E4 | L19: NJH76N5 | M19: Klink, O.C. (Olivier) | N19: Olivier | O19: =ROUND( YEARFRAC( Tabel3[[#This Row],[Geb datum]], DATE(2025,12,31), 1 ), 2 ) -> 27.05 | P19: 36143 | Q19: S1S2 | S19: 2
A20: NMX55K8 | B20: Baas, J. (Julia) | C20: Julia | D20: =ROUND( YEARFRAC( Tabel1[[#This Row],[Geb datum]], DATE(2025,12,31), 1 ), 2 ) -> 9.1 | E20: 42696 | F20: Stopt | H20: E4 | L20: NKD39Q8 | M20: Schindler, M. (Mark) | N20: Mark | O20: =ROUND( YEARFRAC( Tabel3[[#This Row],[Geb datum]], DATE(2025,12,31), 1 ), 2 ) -> 26.59 | P20: 36308 | Q20: S5 | S20: 5
A21: NND85L7 | B21: Gemert, F. (Fien) van | C21: Fien | D21: =ROUND( YEARFRAC( Tabel1[[#This Row],[Geb datum]], DATE(2025,12,31), 1 ), 2 ) -> 9.26 | E21: 42641 | F21: OW J11 | H21: - | L21: NKX56P2 | M21: Flach, J.H. (Joram) | N21: Joram | O21: =ROUND( YEARFRAC( Tabel3[[#This Row],[Geb datum]], DATE(2025,12,31), 1 ), 2 ) -> 26.16 | P21: 36465 | Q21: S5 | S21: 5
A22: NMQ48V2 | B22: Bakker, K. (Karlijn) | C22: Karlijn | D22: =ROUND( YEARFRAC( Tabel1[[#This Row],[Geb datum]], DATE(2025,12,31), 1 ), 2 ) -> 9.51 | E22: 42549 | F22: OW J11 | H22: E3 | L22: NJZ00W3 | M22: Gent, T. (Tim) van | N22: Tim | O22: =ROUND( YEARFRAC( Tabel3[[#This Row],[Geb datum]], DATE(2025,12,31), 1 ), 2 ) -> 25.89 | P22: 36567 | Q22: S1S2 | S22: 1
A23: NMS67Y2 | B23: Bouman, I. (Imme) | C23: Imme | D23: =ROUND( YEARFRAC( Tabel1[[#This Row],[Geb datum]], DATE(2025,12,31), 1 ), 2 ) -> 9.69 | E23: 42481 | F23: OW J11 | H23: E3 | L23: NKT73W8 | M23: Driel, Q. (Quinten) van | N23: Quinten | O23: =ROUND( YEARFRAC( Tabel3[[#This Row],[Geb datum]], DATE(2025,12,31), 1 ), 2 ) -> 25.61 | P23: 36666 | Q23: S5 | S23: 5
A24: NNB63S8 | B24: Boog, S.L. (Suze) | C24: Suze | D24: =ROUND( YEARFRAC( Tabel1[[#This Row],[Geb datum]], DATE(2025,12,31), 1 ), 2 ) -> 9.89 | E24: 42409 | F24: OW J11 | H24: E3 | L24: NJY83B4 | M24: Dubbeld, R. (Ruben) | N24: Ruben | O24: =ROUND( YEARFRAC( Tabel3[[#This Row],[Geb datum]], DATE(2025,12,31), 1 ), 2 ) -> 25.07 | P24: 36865 | Q24: S6 | S24: 6
A25: NND99W1 | B25: Gerritsen, J. (Jaylinn) | C25: Jaylinn | D25: =ROUND( YEARFRAC( Tabel1[[#This Row],[Geb datum]], DATE(2025,12,31), 1 ), 2 ) -> 9.91 | E25: 42401 | F25: OW J12 | H25: - | L25: NKN65B6 | M25: Baars, L.A. (Luuk) | N25: Luuk | O25: =ROUND( YEARFRAC( Tabel3[[#This Row],[Geb datum]], DATE(2025,12,31), 1 ), 2 ) -> 24.9 | P25: 36929 | Q25: S4 | S25: 4
B26: Kampman, J. (Jalou) | C26: Jalou | D26: =ROUND( YEARFRAC( Tabel1[[#This Row],[Geb datum]], DATE(2025,12,31), 1 ), 2 ) -> 9.96 | E26: 42384 | F26: OW J11 | L26: NKG59J2 | M26: Groeneweg, T. (Tim) | N26: Tim | O26: =ROUND( YEARFRAC( Tabel3[[#This Row],[Geb datum]], DATE(2025,12,31), 1 ), 2 ) -> 24.03 | P26: 37246 | Q26: S1S2 | S26: -
A27: NNC48S4 | B27: Haseth, L. (Lieve) de | C27: Lieve | D27: =ROUND( YEARFRAC( Tabel1[[#This Row],[Geb datum]], DATE(2025,12,31), 1 ), 2 ) -> 10.04 | E27: 42353 | F27: OW J12 | H27: E4 | L27: NJZ26Z2 | M27: Kooper, C. (Ché) | N27: Ché | O27: =ROUND( YEARFRAC( Tabel3[[#This Row],[Geb datum]], DATE(2025,12,31), 1 ), 2 ) -> 23.15 | P27: 37566 | Q27: S6 | S27: 6
A28: NMS40B0 | B28: Bergh, A.J. (Aniek) van den | C28: Aniek | D28: =ROUND( YEARFRAC( Tabel1[[#This Row],[Geb datum]], DATE(2025,12,31), 1 ), 2 ) -> 10.17 | E28: 42308 | F28: OW J10 | H28: E2 | L28: NKV95Q4 | M28: Fasbender, T. (Tijmen) | N28: Tijmen | O28: =ROUND( YEARFRAC( Tabel3[[#This Row],[Geb datum]], DATE(2025,12,31), 1 ), 2 ) -> 22.48 | P28: 37810 | Q28: S4 | S28: 4
A29: NMW98N7 | B29: Torbali, N. (Nehir) | C29: Nehir | D29: =ROUND( YEARFRAC( Tabel1[[#This Row],[Geb datum]], DATE(2025,12,31), 1 ), 2 ) -> 10.3 | E29: 42259 | F29: OW J10 | H29: E2 | L29: NKY88T2 | M29: Uijl, D. (Daniel) den | N29: Daniel | O29: =ROUND( YEARFRAC( Tabel3[[#This Row],[Geb datum]], DATE(2025,12,31), 1 ), 2 ) -> 22.42 | P29: 37832 | Q29: S1S2 | S29: 2
A30: NMK64V4 | B30: Mans, R. (Robin) | C30: Robin | D30: =ROUND( YEARFRAC( Tabel1[[#This Row],[Geb datum]], DATE(2025,12,31), 1 ), 2 ) -> 10.33 | E30: 42249 | F30: OW J9 | H30: E1 | L30: NLR23F9 | M30: Wijgaart, R.L.H. (Rick) van de | N30: Rick | O30: =ROUND( YEARFRAC( Tabel3[[#This Row],[Geb datum]], DATE(2025,12,31), 1 ), 2 ) -> 22.21 | P30: 37909 | Q30: S5 | S30: 5
A31: NMS09V7 | B31: Twist, J.J. (Julia) van | C31: Julia | D31: =ROUND( YEARFRAC( Tabel1[[#This Row],[Geb datum]], DATE(2025,12,31), 1 ), 2 ) -> 10.37 | E31: 42234 | F31: OW J10 | H31: E2 | L31: NKR20M2 | M31: Seevinck, T. (Tim) | N31: Tim | O31: =ROUND( YEARFRAC( Tabel3[[#This Row],[Geb datum]], DATE(2025,12,31), 1 ), 2 ) -> 22.15 | P31: 37932 | Q31: Stopt | S31: 4
A32: NNB02Y7 | B32: Naeije, E.A. (Eloise) | C32: Eloise | D32: =ROUND( YEARFRAC( Tabel1[[#This Row],[Geb datum]], DATE(2025,12,31), 1 ), 2 ) -> 10.46 | E32: 42203 | F32: OW J11 | H32: E3 | L32: NKW50C2 | M32: Boon, T. (Thijs) | N32: Thijs | O32: =ROUND( YEARFRAC( Tabel3[[#This Row],[Geb datum]], DATE(2025,12,31), 1 ), 2 ) -> 22.07 | P32: 37960 | Q32: S6 | S32: 6
A33: NMW80G9 | B33: Kombe, S.N. (Nesrin) | C33: Nesrin | D33: =ROUND( YEARFRAC( Tabel1[[#This Row],[Geb datum]], DATE(2025,12,31), 1 ), 2 ) -> 10.48 | E33: 42194 | F33: OW J10 | H33: E4 | L33: NKW21H5 | M33: Kuijper, D.V. (David) | N33: David | O33: =ROUND( YEARFRAC( Tabel3[[#This Row],[Geb datum]], DATE(2025,12,31), 1 ), 2 ) -> 22.04 | P33: 37971 | Q33: S6 | S33: 6
A34: NMS99T8 | B34: Rebollo, T. (Tess) | C34: Tess | D34: =ROUND( YEARFRAC( Tabel1[[#This Row],[Geb datum]], DATE(2025,12,31), 1 ), 2 ) -> 10.71 | E34: 42111 | F34: OW J9 | H34: E1 | L34: NKW30G0 | M34: Vlaming, J.C. (Jens) de | N34: Jens | O34: =ROUND( YEARFRAC( Tabel3[[#This Row],[Geb datum]], DATE(2025,12,31), 1 ), 2 ) -> 22.03 | P34: 37974 | Q34: S6 | S34: 6
A35: NML53R9 | B35: Kleingeld, S. (Sofie) | C35: Sofie | D35: =ROUND( YEARFRAC( Tabel1[[#This Row],[Geb datum]], DATE(2025,12,31), 1 ), 2 ) -> 10.75 | E35: 42096 | F35: OW J9 | H35: E1 | L35: NLL37Q7 | M35: Timmer, J. (Jordan) | N35: Jordan | O35: =ROUND( YEARFRAC( Tabel3[[#This Row],[Geb datum]], DATE(2025,12,31), 1 ), 2 ) -> 21.93 | P35: 38010 | Q35: S1S2 | S35: 2
A36: NMM97Y1 | B36: Laban, M. (Maartje) | C36: Maartje | D36: =ROUND( YEARFRAC( Tabel1[[#This Row],[Geb datum]], DATE(2025,12,31), 1 ), 2 ) -> 10.85 | E36: 42058 | F36: OW J9 | H36: E1 | L36: NKX56T0 | M36: Verhagen, L.A.J. (Laurens) | N36: Laurens | O36: =ROUND( YEARFRAC( Tabel3[[#This Row],[Geb datum]], DATE(2025,12,31), 1 ), 2 ) -> 21.72 | P36: 38090 | Q36: Stopt | S36: 5
A37: NMW34Q6 | B37: Arbiati, S. (Sanae) el | C37: Sanae | D37: =ROUND( YEARFRAC( Tabel1[[#This Row],[Geb datum]], DATE(2025,12,31), 1 ), 2 ) -> 11.13 | E37: 41958 | F37: OW J9 | H37: D3 | L37: NKX66T5 | M37: Wietses, J. (Joël) | N37: Joël | O37: =ROUND( YEARFRAC( Tabel3[[#This Row],[Geb datum]], DATE(2025,12,31), 1 ), 2 ) -> 20.59 | P37: 38502 | Q37: S4 | S37: 4
A38: NMJ35H3 | B38: Dongen, P. (Pien) van | C38: Pien | D38: =ROUND( YEARFRAC( Tabel1[[#This Row],[Geb datum]], DATE(2025,12,31), 1 ), 2 ) -> 11.28 | E38: 41901 | F38: OW J8 | H38: D3 | L38: NLB71F2 | M38: Koornneef, W.J. (Wouter) | N38: Wouter | O38: =ROUND( YEARFRAC( Tabel3[[#This Row],[Geb datum]], DATE(2025,12,31), 1 ), 2 ) -> 20.55 | P38: 38517 | Q38: S6 | S38: 6
... A47: NMM21T3 | B47: Boogaart, L. (Lenthe) van den | C47: Lenthe | D47: =ROUND( YEARFRAC( Tabel1[[#This Row],[Geb datum]], DATE(2025,12,31), 1 ), 2 ) -> 12.23 | E47: 41557 | F47: Stopt | H47: D2 | L47: NLM05B2 | M47: Vliet, T. (Tycho) | N47: Tycho | O47: =ROUND( YEARFRAC( Tabel3[[#This Row],[Geb datum]], DATE(2025,12,31), 1 ), 2 ) -> 18.28 | P47: 39346 | Q47: U19 | S47: -
A48: NND10C4 | B48: Rooij, N. (Nora) van | C48: Nora | D48: =ROUND( YEARFRAC( Tabel1[[#This Row],[Geb datum]], DATE(2025,12,31), 1 ), 2 ) -> 12.23 | E48: 41554 | F48: OW J5 | L48: NLL19V8 | M48: Zwanenburg, J. (Jack) | N48: Jack | O48: =ROUND( YEARFRAC( Tabel3[[#This Row],[Geb datum]], DATE(2025,12,31), 1 ), 2 ) -> 18.25 | P48: 39356 | Q48: U19 | S48: A1
...

Sheet Teams
K1: Maandag | AI1: Dinsdag | BG1: Woensdag | CE1: Donderdag
K2: 0.70833333 | L2: - | M2: - | N2: - | O2: 0.75 | P2: - | Q2: - | R2: - | S2: 0.79166667 | T2: - | U2: - | V2: - | W2: 0.83333333 | X2: - | Y2: - | Z2: - | AA2: 0.875 | AB2: - | AC2: - | AD2: - | AE2: 0.91666667 | AF2: - | AG2: - | AH2: - | AI2: 0.70833333 | AJ2: - | AK2: - | AL2: - | AM2: 0.75 | AN2: - | AO2: - | AP2: - | AQ2: 0.79166667 | AR2: - | AS2: - | AT2: - | AU2: 0.83333333 | AV2: - | AW2: - | AX2: - | AY2: 0.875 | AZ2: - | BA2: - | BB2: - | BC2: 0.91666667 | BD2: - | BE2: - | BF2: - | BG2: 0.70833333 | BH2: - | BI2: - | BJ2: - | BK2: 0.75 | BL2: - | BM2: - | BN2: - | BO2: 0.79166667 | BP2: - | BQ2: - | BR2: - | BS2: 0.83333333 | BT2: - | BU2: - | BV2: - | BW2: 0.875 | BX2: - | BY2: - | BZ2: - | CA2: 0.91666667 | CB2: - | CC2: - | CD2: - | CE2: 0.70833333 | CF2: - | CG2: - | CH2: - | CI2: 0.75 | CJ2: - | CK2: - | CL2: - | CM2: 0.79166667 | CN2: - | CO2: - | CP2: - | CQ2: 0.83333333 | CR2: - | CS2: - | CT2: - | CU2: 0.875 | CV2: - | CW2: - | CX2: - | CY2: 0.91666667 | CZ2: - | DA2: - | DB2: -
A3: 2025-2026 | B3: Selectie/Team | C3: Team | D3: Naam | E3: A/B | F3: Kleur | G3: 8 of 4-korfbal | H3: Gem. Leeftijd | I3: (Samenstelling 24-25)
A4: Ja | B4: Selectie | C4: S1S2 | D4: 1e selectie senioren
A5: Ja | B5: Team | C5: S1 | D5: Senioren 1 | E5: A | G5: 8 | I5: 1
A6: Ja | B6: Team | C6: S2 | D6: Senioren 2 | E6: A | G6: 8 | I6: 2
A7: Ja | B7: Team | C7: S3 | D7: Senioren 3 | E7: A | G7: 8 | I7: 3
A8: Ja | B8: Team | C8: S4 | D8: Senioren 4 | E8: A | G8: 8 | I8: 4
A9: Ja | B9: Team | C9: S5 | D9: Senioren 5 | E9: B | G9: 8 | I9: 5
A10: Ja | B10: Team | C10: S6 | D10: Senioren 6 | E10: B | G10: 8 | I10: 6
A11: ? | B11: Team | C11: S7 | D11: Senioren 7 | E11: B | G11: 8 | H11: 18 | I11: A3
A12: Ja | B12: Selectie | C12: U19 | D12: U19 Selectie
A13: Ja | B13: Team | C13: U19-1 | D13: U19-1 | E13: A | G13: 8 | I13: A1
A14: Ja | B14: Team | C14: U19-2 | D14: U19-2 | E14: A | G14: 8 | I14: A2
A15: Ja | B15: Selectie | C15: U17 | D15: U17 selectie
A16: Ja | B16: Team | C16: U17-1 | D16: U17-1 | E16: A | G16: 8 | I16: B1
A17: Ja | B17: Team | C17: U17-2 | D17: U17-2 | E17: A | G17: 8 | I17: B2/C1
A18: Nee | B18: Selectie | C18: U15 | D18: U15 | I18: C1/C2
A19: Ja | B19: Team | C19: U15-1 | D19: U15-1 | E19: A | G19: 8 | I19: C1/C2
A20: Nee | B20: Team | C20: U15-2 | D20: U15-2 | E20: A | G20: 8
A21: Ja | B21: Team | C21: OW J01 | D21: OW Jeugd 01 | E21: B | F21: Rood | G21: 8 | H21: 15.5 | I21: B3
A22: Ja | B22: Team | C22: OW J02 | D22: OW Jeugd 02 | E22: B | F22: Rood | G22: 8 | H22: 15.5 | I22: B4
A23: Ja | B23: Team | C23: OW J03 | D23: OW Jeugd 03 | E23: B | F23: Oranje | G23: 8 | H23: 14 | I23: C2
A24: Ja | B24: Team | C24: OW J04 | D24: OW Jeugd 04 | E24: B | F24: Oranje | G24: 8 | H24: 14 | I24: C3
A25: Ja | B25: Team | C25: OW J05 | D25: OW Jeugd 05 | E25: B | F25: Oranje | G25: 8 | H25: 12.5 | I25: D1
A26: Ja | B26: Team | C26: OW J06 | D26: OW Jeugd 06 | E26: B | F26: Oranje | G26: 8 | H26: 12.5 | I26: D2
A27: Ja | B27: Team | C27: OW J07 | D27: OW Jeugd 07 | E27: B | F27: Geel | G27: 8 | H27: 12 | I27: D3
A28: Ja | B28: Team | C28: OW J08 | D28: OW Jeugd 08 | E28: B | F28: Geel | G28: 8 | H28: 12 | I28: D4
A29: Ja | B29: Team | C29: OW J09 | D29: OW Jeugd 09 | E29: B | F29: Geel | G29: 8 | H29: 11 | I29: E1
A30: Ja | B30: Team | C30: OW J10 | D30: OW Jeugd 10 | E30: B | F30: Geel | G30: 8 | H30: 10.5 | I30: E2
A31: Ja | B31: Team | C31: OW J11 | D31: OW Jeugd 11 | E31: B | F31: Groen | G31: 4 | H31: 10 | I31: E3
A32: Ja | B32: Team | C32: OW J12 | D32: OW Jeugd 12 | E32: B | F32: Groen | G32: 4 | H32: 9.5 | I32: E4
... A38: Ja | B38: Team | C38: OW J18 | D38: OW Jeugd 18 | E38: B | F38: Blauw | G38: 4 | H38: 6.5 | I38: Nieuwe F
A39: Nee | B39: Team | C39: OW J19
A40: Nee | B40: Team | C40: OW J20
C41: OW K | D41: Kangoeroes | E41: B | F41: -
L42: Veld 1
L43: Veld 2
L44: Veld 3

Sheet Staf
A1: Naam | B1: Team | C1: Functie | D1: eigen team | E1: team vorig jaar | F1: Niveau | G1: Column1 | H1: Column2
A2: Menno Kop | B2: S1S2 | C2: Trainer/Coach S1
A3: Niels Mastijn | B3: S1S2 | C3: Trainer/Coach S1
A4: Rene te Witt | B4: S1S2 | C4: Trainer/Coach S2 | D4: S1S2 | E4: S1S2 | F4: Senior - KT3
A5: Fred Lichteveld | B5: S1S2 | C5: Teammanager S2 | D5: X | E5: A1A2
A6: Ruben Kamerbeek | B6: S1S2 | C6: Fysio | D6: S1S2 | E6: S1S2 | F6: nvt
A7: Anouk de Jongh | B7: S1S2 | C7: Verzorger | D7: A3 | E7: D3 | F7: Medior
A8: Joris van den Neucker | B8: S1S2 | C8: Analist S1 | D8: S1S2 | E8: S1S2 | F8: nvt
A9: Kim Ardon | B9: S3 | C9: Begeleider | D9: X | E9: S3
A10: Dio Naaktgeboren | B10: S4 | C10: Trainer/Coach | D10: X | E10: S4
A11: Arthyn Muller | B11: U19 | C11: Trainer/Coach U19-1 | E11: S1S2 | F11: Senior
A12: Lianne Stomp - vd Burgt | B12: U19 | C12: Trainer/Coach U19-1 | D12: - | E12: F1 | F12: Senior
A13: Jens Lohuis | B13: U19 | C13: Trainer/Coach U19-2 | D13: A1/A2 | E13: - | F13: Medior
A14: Joël Wietses | B14: U19 | C14: Trainer/Coach U19-2 | D14: A1/A2 | E14: - | F14: Medior
A15: Jasper Kleingeld | B15: U17 | C15: Trainer/Coach U17-1 | D15: X | E15: B1B2 | F15: Senior
A16: Mees Oppe | B16: U17 | C16: Trainer/Coach U17-1 | D16: DeetosSnel 1 | E16: B1B2 | F16: Junior - KT2
A17: Alex de Boer | B17: U17 | C17: Trainer/Coach U17-2 | D17: X | E17: D1 | F17: Senior
A18: Tom van de Ven | B18: U17 | C18: Trainer/Coach U17-2 | D18: X | E18: D1 | F18: Medior
A19: Alex van de Klooster | B19: U17 | C19: Teammanager U17 | E19: U17
A20: Bas de Jong | B20: U17 | C20: Ondersteuning U17
A21: Milou Oppe | B21: U15-1 | C21: Trainer/Coach | D21: S1/S2 | E21: C1 | F21: Junior - KT2
A22: Rob van Dongen | B22: U15-1 | C22: Trainer/Coach | E22: A1A2
A23: Luuk Baars | B23: OW J1 | C23: Trainer/Coach | E23: B4
A24: Maud van Wensen | B24: OW J1 | C24: Trainer/Coach | D24: A1/A2 | E24: B4 | F24: Junior - KT2
A25: Martijn van der Wiel | B25: OW J2 | C25: Trainer/Coach | D25: X | E25: B3 | F25: Medior
A26: Chris Gerritsen | B26: OW J3 | C26: Trainer/Coach
A27: Fieneke Lotgerink | B27: OW J3 | C27: Trainer/Coach
A28: Niek Driesprong | B28: OW J4 | C28: Trainer/Coach | D28: DeetosSnel U19 | F28: Medior
A29: Seth vd Burgt | B29: OW J4 | C29: Trainer/Coach | E29: F1 | F29: Startend - KT2
A30: Sophie Kilsdonk | B30: OW J4 | C30: Trainer/Coach | E30: F1 | F30: Startend - KT2
A31: Justin Vos | B31: OW J5 | C31: Trainer/Coach
A32: Sara Boshoven | B32: OW J5 | C32: Trainer/Coach | E32: D2 | H32: gaat door
A33: Kimberley Witman | B33: OW J6 | C33: Trainer/Coach | E33: C2
A34: Robert Koster | B34: OW J6 | C34: Trainer/Coach | D34: X | E34: C2 | F34: Senior
A35: Senne Koster | B35: OW J6 | C35: Trainer/Coach | E35: C2 | F35: Junior
A36: Nadia de Wit | B36: OW J7 | C36: Trainer/Coach | D36: S7 | E36: C3 | F36: Junior
A37: Syrah de Wit | B37: OW J7 | C37: Trainer/Coach | D37: S7 | E37: C3 | F37: Junior
A38: Marcel St. Nicolaas | B38: OW J8 | C38: Trainer/Coach | D38: X | E38: D1 | F38: Medior
A39: Sjoerd van Ameijden | B39: OW J8 | C39: Trainer/Coach | D39: X | E39: D3 | F39: Medior
A40: Liesbeth Wibbens | B40: OW J9 | C40: Trainer/Coach | D40: X | E40: E1 | F40: Medior
...

Sheet Aandachtpunten
A1: Categorie | B1: Aandachtspunten | C1: Onderwerp | D1: Antwoord | E1: Actiehouder | F1: Wanneer | G1: Status
B61: Scenario 1. - nu
B62: Scenario 2 - Evie Groen door en Pippa naar D4
B63: Scenario 3 - Manon, Noortje en Evie naar C4 -met 17 kids + wedstrijdlid

Sheet Teams-deelversie
A2: Selecties | B2: S1S2 | E2: U19 | H2: U17 | K2: U15
B3: Dames | C3: Heren | E3: Dames | F3: Heren | H3: Dames | I3: Heren | K3: Dames | L3: Heren
B4: {=_xlfn._xlws.FILTER(Spelerslijst!$B:$B,Spelerslijst!$F:$F=B$2,"")} -> Klooster, C. (Carmen) van der | C4: {=_xlfn._xlws.FILTER(Spelerslijst!$M:$M,Spelerslijst!$Q:$Q=B$2,"")} -> Strijen, L.A. van (Lars) | E4: {=_xlfn._xlws.FILTER(Spelerslijst!$B:$B,Spelerslijst!$F:$F=E$2,"")} -> Klooster, D. (Danique) van der | F4: {=_xlfn._xlws.FILTER(Spelerslijst!$M:$M,Spelerslijst!$Q:$Q=E$2,"")} -> Dongen, F.P.B. (Freek) van | H4: {=_xlfn._xlws.FILTER(Spelerslijst!$B:$B,Spelerslijst!$F:$F=H$2,"")} -> Kleingeld, J.N. (Julia) | I4: {=_xlfn._xlws.FILTER(Spelerslijst!$M:$M,Spelerslijst!$Q:$Q=H$2,"")} -> Pichel, T. (Timo) | K4: {=_xlfn._xlws.FILTER(Spelerslijst!$B:$B,Spelerslijst!$F:$F=K$2,"")} | L4: {=_xlfn._xlws.FILTER(Spelerslijst!$M:$M,Spelerslijst!$Q:$Q=K$2,"")}
B5: Fasbender, L. (Lindi) | C5: Klink, M (Marijn) | E5: Reuvers, L. (Lisa) | F5: Bäcker, C.J. (Tijn) | H5: Stomp, N. (Noa) | I5: Vliet, K.M. (Kian)
B6: Boshoven, S.A.E. (Sara) | C6: Driesprong, B. (Bart) | E6: Burgt, E. (Elize) van de | F6: Vliet, T. (Tycho) | H6: Burgt, F. (Feline) van de | I6: Sempel, J.D. (Jasper)
B7: Groeneweg, R.K. (Roos) | C7: Klink, O.C. (Olivier) | E7: Voorbij, D.M. (Doeska) | F7: Zwanenburg, J. (Jack) | H7: Boer, E.M. (Esmée) de | I7: Hovestadt, D. (Diederik)
B8: Driesprong, M. (Meike) | C8: Gent, T. (Tim) van | E8: Linden, B.S. (Benthe) van der | F8: Valk, J.B. (Jarno) | H8: Engelfriet, D. (Demi) | I8: Bemer, J.L.E. (Jarno)
B9: Fernhout, L. (Loïs) | C9: Groeneweg, T. (Tim) | E9: Verboom, S. (Stella) | F9: Dekker, O.C. (Onno) den | H9: Jongkind, F.W.J. (Floortje) | I9: Sas, N. (Niek)
B10: Teerds, E.L. (Eva) | C10: Uijl, D. (Daniel) den | E10: Kilsdonk, S.A (Sophie) | F10: Sas, M. (Maarten) | H10: Volker, T.N. (Tess) | I10: Ven, J. (Jonas) van de
B11: Oppe, M. (Milou) | C11: Timmer, J. (Jordan) | E11: Manduapessy, M. (Merel) | F11: Camphens, T. (Tijn) | H11: Lindhout, D. (Demi) | I11: Vos, T. (Thomas)
B12: Dijk, D. (Demi) van | C12: Koster, S. (Senne) | E12: Haas, A. (Amber) de | F12: Heersping, D.B.A.C. (Dani) | H12: Bemer, G.M.E. (Githa)
B13: Dommisse, R. (Robin) | C13: Burgt, S. (Seth) van de | H13: Lohuis, F.A.C. (Floor)
B14: Klink, X (Xanne) | C14: Vaartmans, J.A. (Jordi)
B16: {=_xlfn._xlws.FILTER(Staf!$C:$C,Staf!$B:$B=Teamsamenstelling!B2,"")} -> Trainer/Coach S1 | C16: {=_xlfn._xlws.FILTER(Staf!$A:$A,Staf!$B:$B=Teamsamenstelling!B2,"")} -> Menno Kop | E16: {=_xlfn._xlws.FILTER(Staf!$C:$C,Staf!$B:$B=Teamsamenstelling!M2,"")} -> Trainer/Coach U19-1 | F16: {=_xlfn._xlws.FILTER(Staf!$A:$A,Staf!$B:$B=Teamsamenstelling!M2,"")} -> Arthyn Muller | H16: {=_xlfn._xlws.FILTER(Staf!$C:$C,Staf!$B:$B=Teamsamenstelling!X2,"")} -> Trainer/Coach U17-1 | I16: {=_xlfn._xlws.FILTER(Staf!$A:$A,Staf!$B:$B=Teamsamenstelling!X2,"")} -> Jasper Kleingeld | K16: {=_xlfn._xlws.FILTER(Staf!$C:$C,Staf!$B:$B=#REF!,"")} -> #REF!
B17: Trainer/Coach S1 | C17: Niels Mastijn | E17: Trainer/Coach U19-1 | F17: Lianne Stomp - vd Burgt | H17: Trainer/Coach U17-1 | I17: Mees Oppe
B18: Trainer/Coach S2 | C18: Rene te Witt | E18: Trainer/Coach U19-2 | F18: Jens Lohuis | H18: Trainer/Coach U17-2 | I18: Alex de Boer
B19: Teammanager S2 | C19: Fred Lichteveld | E19: Trainer/Coach U19-2 | F19: Joël Wietses | H19: Trainer/Coach U17-2 | I19: Tom van de Ven
B20: Fysio | C20: Ruben Kamerbeek | H20: Teammanager U17 | I20: Alex van de Klooster
B21: Verzorger | C21: Anouk de Jongh | H21: Ondersteuning U17 | I21: Bas de Jong
B22: Analist S1 | C22: Joris van den Neucker
A25: Senioren | B25: S1 | E25: S2 | H25: S3 | K25: S4 | N25: S5 | Q25: S6 | T25: S7 | W25: MW1
B26: Dames | C26: Heren | E26: Dames | F26: Heren | H26: Dames | I26: Heren | K26: Dames | L26: Heren | N26: Dames | O26: Heren | Q26: Dames | R26: Heren | T26: Dames | U26: Heren | W26: Dames | X26: Heren
B27: {=_xlfn._xlws.FILTER(Spelerslijst!$B:$B,Spelerslijst!$F:$F=B$25,"")} | C27: {=_xlfn._xlws.FILTER(Spelerslijst!$M:$M,Spelerslijst!$Q:$Q=B$25,"")} | E27: {=_xlfn._xlws.FILTER(Spelerslijst!$B:$B,Spelerslijst!$F:$F=E$25,"")} | F27: {=_xlfn._xlws.FILTER(Spelerslijst!$M:$M,Spelerslijst!$Q:$Q=E$25,"")} | H27: {=_xlfn._xlws.FILTER(Spelerslijst!$B:$B,Spelerslijst!$F:$F=H$25,"")} -> Visser, R. (Renske) | I27: {=_xlfn._xlws.FILTER(Spelerslijst!$M:$M,Spelerslijst!$Q:$Q=H$25,"")} -> Vlaming, R. (Roy) de | K27: {=_xlfn._xlws.FILTER(Spelerslijst!$B:$B,Spelerslijst!$F:$F=K$25,"")} -> Jongh, A. (Anouk) de | L27: {=_xlfn._xlws.FILTER(Spelerslijst!$M:$M,Spelerslijst!$Q:$Q=K$25,"")} -> Baars, L.A. (Luuk) | N27: {=_xlfn._xlws.FILTER(Spelerslijst!$B:$B,Spelerslijst!$F:$F=N$25,"")} -> Valk, M.E. (Marlies) | O27: {=_xlfn._xlws.FILTER(Spelerslijst!$M:$M,Spelerslijst!$Q:$Q=N$25,"")} -> Schindler, M. (Mark) | Q27: {=_xlfn._xlws.FILTER(Spelerslijst!$B:$B,Spelerslijst!$F:$F=Q$25,"")} -> Bozuwa, J. (Julia) | R27: {=_xlfn._xlws.FILTER(Spelerslijst!$M:$M,Spelerslijst!$Q:$Q=Q$25,"")} -> Dubbeld, R. (Ruben) | T27: {=_xlfn._xlws.FILTER(Spelerslijst!$B:$B,Spelerslijst!$F:$F=T$25,"")} | U27: {=_xlfn._xlws.FILTER(Spelerslijst!$M:$M,Spelerslijst!$Q:$Q=T$25,"")} | W27: {=_xlfn._xlws.FILTER(Spelerslijst!$B:$B,Spelerslijst!$F:$F=W$25,"")} -> Brand, L (Liesbeth) | X27: {=_xlfn._xlws.FILTER(Spelerslijst!$M:$M,Spelerslijst!$Q:$Q=W$25,"")} -> Kooij, C.W. (Wilco)
H28: Leijdsman, R. (Robin) | I28: Isarin, T P (Thomas) | K28: Quarré, E.A. (Elena) | L28: Fasbender, T. (Tijmen) | N28: Pierse, A.W. (Anniek) | O28: Flach, J.H. (Joram) | Q28: Versnel, V. (Vivienne) | R28: Kooper, C. (Ché) | W28: Starre-Scheurwater, K. (Kim) van der | X28: Jong, M. (Michiel) 't
H29: Kalkeren-Verweij, M. (Mirthe) van | I29: Houwerzijl, E. (Emiel) | K29: Wensen, M. (Maud) | L29: Wietses, J. (Joël) | N29: Koote, L.D. (Laura) | O29: Driel, Q. (Quinten) van | Q29: Witman, K. (Kimberley) | R29: Boon, T. (Thijs) | W29: Opstal-Haksteen, T.K. (Tamara) van | X29: Ploeg, H (Hans)
H30: Gurp, M (Merel) van | I30: Gent, L (Lex) van | K30: Lievaart, C.A. (Carlijn) | L30: Lohuis, J.A. (Jens) | N30: Wit, N.M.T. (Nadia) de | O30: Wijgaart, R.L.H. (Rick) van de | Q30: Friebel, A. (Angela) | R30: Kuijper, D.V. (David) | W30: Heesterbeek, K. (Kim)
H31: Ardon, L (Linda) | I31: Brugge, B.R. (Bart) van der | K31: Mol, L.N.A. (Laura) | L31: - Heer S1/S2 | N31: Wit, S.E.E. (Syrah) de | Q31: Dubbeld, S. (Sanne) | R31: Vlaming, J.C. (Jens) de | W31: Veld, D. (Dorien) in 't
H32: Batenburg, H. (Hanneke) | I32: Peuter, F. (Freek) | K32: Dommisse, K. (Kim) | N32: Schram, L.J. (Lara) | Q32: Dubbeld, T. (Tessa) | R32: Koornneef, W.J. (Wouter)
H33: Ploeg, L (Lieke) | K33: - Dame S1/S2 | Q33: Hulsker, N.M. (Nina) | R33: Koornneef, T.J. (Tommie)
K34: Knippenberg, R. (Rachel) | R34: Pille, M.A. (Menno)
K35: Hoffman, M. (Merel)
B36: {=_xlfn._xlws.FILTER(Staf!$C:$C,Staf!$B:$B=Teamsamenstelling!B29,"")} | E36: {=_xlfn._xlws.FILTER(Staf!$C:$C,Staf!$B:$B=Teamsamenstelling!M29,"")} | H36: {=_xlfn._xlws.FILTER(Staf!$C:$C,Staf!$B:$B=Teamsamenstelling!X29,"")} -> Begeleider | I36: {=_xlfn._xlws.FILTER(Staf!$A:$A,Staf!$B:$B=Teamsamenstelling!X29,"")} -> Kim Ardon | K36: {=_xlfn._xlws.FILTER(Staf!$C:$C,Staf!$B:$B=Teamsamenstelling!AI29,"")} -> Trainer/Coach | L36: {=_xlfn._xlws.FILTER(Staf!$A:$A,Staf!$B:$B=Teamsamenstelling!AI29,"")} -> Dio Naaktgeboren | N36: {=_xlfn._xlws.FILTER(Staf!$C:$C,Staf!$B:$B=Teamsamenstelling!AT29,"")} | O36: {=_xlfn._xlws.FILTER(Staf!$A:$A,Staf!$B:$B=Teamsamenstelling!AT29,"")} | Q36: {=_xlfn._xlws.FILTER(Staf!$C:$C,Staf!$B:$B=Teamsamenstelling!BE29,"")} | R36: {=_xlfn._xlws.FILTER(Staf!$A:$A,Staf!$B:$B=Teamsamenstelling!BE29,"")} | T36: {=_xlfn._xlws.FILTER(Staf!$C:$C,Staf!$B:$B=Teamsamenstelling!BP29,"")} | W36: {=_xlfn._xlws.FILTER(Staf!$C:$C,Staf!$B:$B=Teamsamenstelling!CA29,"")}
A40: Rood | B40: U17-1 | E40: U17-2 | H40: OW J01 | K40: OW J02 | N40: --
B41: Dames | C41: Heren | E41: Dames | F41: Heren | H41: Dames | I41: Heren | K41: Dames | L41: Heren | N41: Dames | O41: Heren
B42: {=_xlfn._xlws.FILTER(Spelerslijst!$B:$B,Spelerslijst!$F:$F=B$40,"")} | C42: {=_xlfn._xlws.FILTER(Spelerslijst!$M:$M,Spelerslijst!$Q:$Q=B$40,"")} | E42: {=_xlfn._xlws.FILTER(Spelerslijst!$B:$B,Spelerslijst!$F:$F=E$40,"")} | F42: {=_xlfn._xlws.FILTER(Spelerslijst!$M:$M,Spelerslijst!$Q:$Q=E$40,"")} | H42: {=_xlfn._xlws.FILTER(Spelerslijst!$B:$B,Spelerslijst!$F:$F=H$40,"")} | I42: {=_xlfn._xlws.FILTER(Spelerslijst!$M:$M,Spelerslijst!$Q:$Q=H$40,"")} | K42: {=_xlfn._xlws.FILTER(Spelerslijst!$B:$B,Spelerslijst!$F:$F=K$40,"")} | L42: {=_xlfn._xlws.FILTER(Spelerslijst!$M:$M,Spelerslijst!$Q:$Q=K$40,"")} | N42: {=_xlfn._xlws.FILTER(Spelerslijst!$B:$B,Spelerslijst!$F:$F=N40,"")} | O42: {=_xlfn._xlws.FILTER(Spelerslijst!$M:$M,Spelerslijst!$Q:$Q=N40,"")}
B51: {=_xlfn._xlws.FILTER(Staf!$C:$C,Staf!$B:$B=Teamsamenstelling!B45,"")} | C51: {=_xlfn._xlws.FILTER(Staf!$A:$A,Staf!$B:$B=Teamsamenstelling!B45,"")} | E51: {=_xlfn._xlws.FILTER(Staf!$C:$C,Staf!$B:$B=Teamsamenstelling!M45,"")} | F51: {=_xlfn._xlws.FILTER(Staf!$A:$A,Staf!$B:$B=Teamsamenstelling!M45,"")} | H51: {=_xlfn._xlws.FILTER(Staf!$C:$C,Staf!$B:$B=Teamsamenstelling!X45,"")} -> Trainer/Coach | I51: {=_xlfn._xlws.FILTER(Staf!$A:$A,Staf!$B:$B=Teamsamenstelling!X45,"")} -> Luuk Baars | K51: {=_xlfn._xlws.FILTER(Staf!$C:$C,Staf!$B:$B=Teamsamenstelling!AI45,"")} -> Trainer/Coach | L51: {=_xlfn._xlws.FILTER(Staf!$A:$A,Staf!$B:$B=Teamsamenstelling!AI45,"")} -> Martijn van der Wiel | N51: {=_xlfn._xlws.FILTER(Staf!$C:$C,Staf!$B:$B=Teamsamenstelling!AT45,"")} | O51: {=_xlfn._xlws.FILTER(Staf!$A:$A,Staf!$B:$B=Teamsamenstelling!AT45,"")}
H52: Trainer/Coach | I52: Maud van Wensen
A55: Oranje | B55: U15-1 | E55: OW J03 | H55: OW J04 | K55: OW J05 | N55: OW J06
B56: Dames | C56: Heren | E56: Dames | F56: Heren | H56: Dames | I56: Heren | K56: Dames | L56: Heren | N56: Dames | O56: Heren
