Workbook

Sheet Teams
A2: Selecties | B2: S1S2 | G2: =AVERAGE(D4:D21,G4:G21) -> 23.681818 | I2: S5S6 | N2: =AVERAGE(K4:K21,N4:N21) -> 21.117647 | P2: A1A2 | U2: =AVERAGE(R4:R21,U4:U21) -> #DIV/0! | W2: B1B2 | AB2: =AVERAGE(Y4:Y21,AB4:AB21) -> #DIV/0!
B3: =CONCATENATE("Dames (",COUNTA(C4:C16),")") -> Dames (11) | E3: =CONCATENATE("Heren (",COUNTA(F4:F16),")") -> Heren (11) | I3: =CONCATENATE("Dames (",COUNTA(J4:J16),")") -> Dames (8) | L3: =CONCATENATE("Heren (",COUNTA(M4:M16),")") -> Heren (9) | P3: =CONCATENATE("Dames (",COUNTA(Q4:Q16),")") -> Dames (1) | S3: =CONCATENATE("Heren (",COUNTA(T4:T16),")") -> Heren (1) | W3: =CONCATENATE("Dames (",COUNTA(X4:X16),")") -> Dames (1) | Z3: =CONCATENATE("Heren (",COUNTA(AA4:AA16),")") -> Heren (1)
B4: {=_xlfn._xlws.FILTER(Spelerslijst!$B:$B,Spelerslijst!$G:$G=B$2,"")} -> Bridget ter Horst | C4: {=_xlfn._xlws.FILTER(Spelerslijst!$H:$H,Spelerslijst!$G:$G=B$2,"")} -> S5 | D4: {=_xlfn._xlws.FILTER(Spelerslijst!$D:$D,Spelerslijst!$G:$G=B$2,"")} -> 20 | E4: {=_xlfn._xlws.FILTER(Spelerslijst!$L:$L,Spelerslijst!$Q:$Q=B$2,"")} -> Bart Driesprong | F4: {=_xlfn._xlws.FILTER(Spelerslijst!$R:$R,Spelerslijst!$Q:$Q=B$2,"")} -> S1 | G4: {=_xlfn._xlws.FILTER(Spelerslijst!$N:$N,Spelerslijst!$Q:$Q=B$2,"")} -> 25 | I4: {=_xlfn._xlws.FILTER(Spelerslijst!$B:$B,Spelerslijst!$G:$G=I$2,"")} -> Angela Friebel | J4: {=_xlfn._xlws.FILTER(Spelerslijst!$H:$H,Spelerslijst!$G:$G=I$2,"")} -> S6 | K4: {=_xlfn._xlws.FILTER(Spelerslijst!$D:$D,Spelerslijst!$G:$G=I$2,"")} -> 21 | L4: {=_xlfn._xlws.FILTER(Spelerslijst!$L:$L,Spelerslijst!$Q:$Q=I$2,"")} -> Cas Tieleman | M4: {=_xlfn._xlws.FILTER(Spelerslijst!$R:$R,Spelerslijst!$Q:$Q=I$2,"")} -> S6 | N4: {=_xlfn._xlws.FILTER(Spelerslijst!$N:$N,Spelerslijst!$Q:$Q=I$2,"")} -> 19 | P4: {=_xlfn._xlws.FILTER(Spelerslijst!$B:$B,Spelerslijst!$G:$G=P$2,"")} | Q4: {=_xlfn._xlws.FILTER(Spelerslijst!$H:$H,Spelerslijst!$G:$G=P$2,"")} | R4: {=_xlfn._xlws.FILTER(Spelerslijst!$D:$D,Spelerslijst!$G:$G=P$2,"")} | S4: {=_xlfn._xlws.FILTER(Spelerslijst!$L:$L,Spelerslijst!$Q:$Q=P$2,"")} | T4: {=_xlfn._xlws.FILTER(Spelerslijst!$R:$R,Spelerslijst!$Q:$Q=P$2,"")} | U4: {=_xlfn._xlws.FILTER(Spelerslijst!$N:$N,Spelerslijst!$Q:$Q=P$2,"")} | W4: {=_xlfn._xlws.FILTER(Spelerslijst!$B:$B,Spelerslijst!$G:$G=W$2,"")} | X4: {=_xlfn._xlws.FILTER(Spelerslijst!$H:$H,Spelerslijst!$G:$G=W$2,"")} | Y4: {=_xlfn._xlws.FILTER(Spelerslijst!$D:$D,Spelerslijst!$G:$G=W$2,"")} | Z4: {=_xlfn._xlws.FILTER(Spelerslijst!$L:$L,Spelerslijst!$Q:$Q=W$2,"")} | AA4: {=_xlfn._xlws.FILTER(Spelerslijst!$R:$R,Spelerslijst!$Q:$Q=W$2,"")} | AB4: {=_xlfn._xlws.FILTER(Spelerslijst!$N:$N,Spelerslijst!$Q:$Q=W$2,"")}
B5: Demi van Dijk | C5: S2 | D5: 22 | E5: Bob Mans | F5: S2 | G5: 27 | I5: Carlijn Lievaart | J5: A2 | K5: 19 | L5: Ché Kooper | M5: S7 | N5: 21
B6: Djuna Seevinck | C6: S1 | D6: 22 | E6: Daniel den Uijl | F6: S5 | G6: 20 | I6: Jany Lacroes | J6: S5 | K6: 25 | L6: David Kuijper | M6: S6 | N6: 20
B7: Eva Teerds | C7: S2 | D7: 21 | E7: Jaimy van Arkel | F7: * | G7: 23 | I7: Jennifer Herremans | J7: S6 | K7: 20 | L7: Jens de Vlaming | M7: S6 | N7: 20
B8: Kim Dommisse | C8: S5 | D8: 22 | E8: Joeri van Dijk | F8: S2 | G8: 25 | I8: Kimberley Witman | J8: S6 | K8: 19 | L8: Luuk Baars | M8: S5 | N8: 22
B9: Loïs Fernhout | C9: S5 | D9: 20 | E9: Jordan Timmer | F9: A1 | G9: 19 | I9: Lara Schram | J9: S5 | K9: 23 | L9: Quinten van Driel | M9: S5 | N9: 23
B10: Milou Oppe | C10: S2 | D10: 21 | E10: Marijn Klink | F10: S1 | G10: 26 | I10: Sanne Dubbeld | J10: S6 | K10: 21 | L10: Ruben Dubbeld | M10: S6 | N10: 23
B11: Renske Visser | C11: S2 | D11: 25 | E11: Olivier Klink | F11: AR | G11: 25 | I11: Tessa Dubbeld | J11: S6 | K11: 23 | L11: Thijs Boon | M11: S6 | N11: 20
B12: Robin Dommisse | C12: S2 | D12: 25 | E12: Robin van Kalkeren | F12: S1 | G12: 27 | L12: Tijmen Fasbender | M12: S5 | N12: 20
B13: Vera Klootwijk | C13: * | D13: 23 | E13: Stefan Naaktgeboren | F13: S2 | G13: 32
B14: Xanne Klink | C14: S1 | D14: 28 | E14: Tim van Gent | F14: S2 | G14: 23
B17: {=_xlfn._xlws.FILTER(Staf!$C:$C,Staf!$B:$B=Teams!B2,"")} -> Analist S1 | C17: {=_xlfn._xlws.FILTER(Staf!$A:$A,Staf!$B:$B=Teams!B2,"")} -> Joris van den Neucker | I17: {=_xlfn._xlws.FILTER(Staf!$C:$C,Staf!$B:$B=Teams!I2,"")} -> Trainer/Coach S5 | J17: {=_xlfn._xlws.FILTER(Staf!$A:$A,Staf!$B:$B=Teams!I2,"")} -> Robin Dommisse | P17: {=_xlfn._xlws.FILTER(Staf!$C:$C,Staf!$B:$B=Teams!P2,"")} -> Trainer/Coach A1 | Q17: {=_xlfn._xlws.FILTER(Staf!$A:$A,Staf!$B:$B=Teams!P2,"")} -> Rob van Dongen | W17: {=_xlfn._xlws.FILTER(Staf!$C:$C,Staf!$B:$B=Teams!W2,"")} | X17: {=_xlfn._xlws.FILTER(Staf!$A:$A,Staf!$B:$B=Teams!W2,"")}
B18: Teambegeleider S1 | C18: Dionne Broere
B19: Teambegeleider S2 | C19: Sandra Kerklaan
B20: Fysio | C20: Ruben Kamerbeek
B21: Verzorger | C21: Theo Anrochte
B22: Coach S2 | C22: Arthyn Muller
B23: Coach S2 | C23: Jeroen de Kruif
B24: Coach S1 | C24: Bo van Hoof
A26: Senioren | B26: S1 | G26: =AVERAGE(D28:D37,G28:G37) -> #DIV/0! | I26: S2 | N26: =AVERAGE(K28:K37,N28:N37) -> #DIV/0! | P26: S3 | U26: =AVERAGE(R28:R37,U28:U37) -> 31.5 | W26: S4 | AB26: =AVERAGE(Y28:Y37,AB28:AB37) -> 38.6 | AD26: S5 | AI26: =AVERAGE(AF28:AF37,AI28:AI37) -> #DIV/0! | AK26: S6 | AP26: =AVERAGE(AM28:AM37,AP28:AP37) -> #DIV/0! | AR26: S7 | AW26: =AVERAGE(AT28:AT37,AW28:AW37) -> 21.75 | AY26: MW1 | BD26: =AVERAGE(BA28:BA37,BD28:BD37) -> 39
B27: =CONCATENATE("Dames (",COUNTA(C28:C35),")") -> Dames (1) | E27: =CONCATENATE("Heren (",COUNTA(F28:F35),")") -> Heren (1) | I27: =CONCATENATE("Dames (",COUNTA(J28:J35),")") -> Dames (1) | L27: =CONCATENATE("Heren (",COUNTA(M28:M35),")") -> Heren (1) | P27: =CONCATENATE("Dames (",COUNTA(Q28:Q35),")") -> Dames (7) | S27: =CONCATENATE("Heren (",COUNTA(T28:T35),")") -> Heren (5) | W27: =CONCATENATE("Dames (",COUNTA(X28:X35),")") -> Dames (5) | Z27: =CONCATENATE("Heren (",COUNTA(AA28:AA35),")") -> Heren (5) | AD27: =CONCATENATE("Dames (",COUNTA(AE28:AE35),")") -> Dames (1) | AG27: =CONCATENATE("Heren (",COUNTA(AH28:AH35),")") -> Heren (1) | AK27: =CONCATENATE("Dames (",COUNTA(AL28:AL35),")") -> Dames (1) | AN27: =CONCATENATE("Heren (",COUNTA(AO28:AO35),")") -> Heren (1) | AR27: =CONCATENATE("Dames (",COUNTA(AS28:AS35),")") -> Dames (5) | AU27: =CONCATENATE("Heren (",COUNTA(AV28:AV35),")") -> Heren (3) | AY27: =CONCATENATE("Dames (",COUNTA(AZ28:AZ35),")") -> Dames (7) | BB27: =CONCATENATE("Heren (",COUNTA(BC28:BC35),")") -> Heren (6)
B28: {=_xlfn._xlws.FILTER(Spelerslijst!$B:$B,Spelerslijst!$G:$G=B$26,"")} | C28: {=_xlfn._xlws.FILTER(Spelerslijst!$H:$H,Spelerslijst!$G:$G=B$26,"")} | D28: {=_xlfn._xlws.FILTER(Spelerslijst!$D:$D,Spelerslijst!$G:$G=B$26,"")} | E28: {=_xlfn._xlws.FILTER(Spelerslijst!$L:$L,Spelerslijst!$Q:$Q=B$26,"")} | F28: {=_xlfn._xlws.FILTER(Spelerslijst!$R:$R,Spelerslijst!$Q:$Q=B$26,"")} | G28: {=_xlfn._xlws.FILTER(Spelerslijst!$N:$N,Spelerslijst!$Q:$Q=B$26,"")} | I28: {=_xlfn._xlws.FILTER(Spelerslijst!$B:$B,Spelerslijst!$G:$G=I$26,"")} | J28: {=_xlfn._xlws.FILTER(Spelerslijst!$H:$H,Spelerslijst!$G:$G=I$26,"")} | K28: {=_xlfn._xlws.FILTER(Spelerslijst!$D:$D,Spelerslijst!$G:$G=I$26,"")} | L28: {=_xlfn._xlws.FILTER(Spelerslijst!$L:$L,Spelerslijst!$Q:$Q=I$26,"")} | M28: {=_xlfn._xlws.FILTER(Spelerslijst!$R:$R,Spelerslijst!$Q:$Q=I$26,"")} | N28: {=_xlfn._xlws.FILTER(Spelerslijst!$N:$N,Spelerslijst!$Q:$Q=I$26,"")} | P28: {=_xlfn._xlws.FILTER(Spelerslijst!$B:$B,Spelerslijst!$G:$G=P$26,"")} -> Esther Ardon | Q28: {=_xlfn._xlws.FILTER(Spelerslijst!$H:$H,Spelerslijst!$G:$G=P$26,"")} -> S3 | R28: {=_xlfn._xlws.FILTER(Spelerslijst!$D:$D,Spelerslijst!$G:$G=P$26,"")} -> 27 | S28: {=_xlfn._xlws.FILTER(Spelerslijst!$L:$L,Spelerslijst!$Q:$Q=P$26,"")} -> Emiel Houwerzijl | T28: {=_xlfn._xlws.FILTER(Spelerslijst!$R:$R,Spelerslijst!$Q:$Q=P$26,"")} -> S3 | U28: {=_xlfn._xlws.FILTER(Spelerslijst!$N:$N,Spelerslijst!$Q:$Q=P$26,"")} -> 29 | W28: {=_xlfn._xlws.FILTER(Spelerslijst!$B:$B,Spelerslijst!$G:$G=W$26,"")} -> Barbara Camphens-Moerman | X28: {=_xlfn._xlws.FILTER(Spelerslijst!$H:$H,Spelerslijst!$G:$G=W$26,"")} -> MW1 | Y28: {=_xlfn._xlws.FILTER(Spelerslijst!$D:$D,Spelerslijst!$G:$G=W$26,"")} -> 42 | Z28: {=_xlfn._xlws.FILTER(Spelerslijst!$L:$L,Spelerslijst!$Q:$Q=W$26,"")} -> Antjan Laban | AA28: {=_xlfn._xlws.FILTER(Spelerslijst!$R:$R,Spelerslijst!$Q:$Q=W$26,"")} -> S4 | AB28: {=_xlfn._xlws.FILTER(Spelerslijst!$N:$N,Spelerslijst!$Q:$Q=W$26,"")} -> 43 | AD28: {=_xlfn._xlws.FILTER(Spelerslijst!$B:$B,Spelerslijst!$G:$G=AD$26,"")} | AE28: {=_xlfn._xlws.FILTER(Spelerslijst!$H:$H,Spelerslijst!$G:$G=AD$26,"")} | AF28: {=_xlfn._xlws.FILTER(Spelerslijst!$D:$D,Spelerslijst!$G:$G=AD$26,"")} | AG28: {=_xlfn._xlws.FILTER(Spelerslijst!$L:$L,Spelerslijst!$Q:$Q=AD$26,"")} | AH28: {=_xlfn._xlws.FILTER(Spelerslijst!$R:$R,Spelerslijst!$Q:$Q=AD$26,"")} | AI28: {=_xlfn._xlws.FILTER(Spelerslijst!$N:$N,Spelerslijst!$Q:$Q=AD$26,"")} | AK28: {=_xlfn._xlws.FILTER(Spelerslijst!$B:$B,Spelerslijst!$G:$G=AK$26,"")} | AL28: {=_xlfn._xlws.FILTER(Spelerslijst!$H:$H,Spelerslijst!$G:$G=AK$26,"")} | AM28: {=_xlfn._xlws.FILTER(Spelerslijst!$D:$D,Spelerslijst!$G:$G=AK$26,"")} | AN28: {=_xlfn._xlws.FILTER(Spelerslijst!$L:$L,Spelerslijst!$Q:$Q=AK$26,"")} | AO28: {=_xlfn._xlws.FILTER(Spelerslijst!$R:$R,Spelerslijst!$Q:$Q=AK$26,"")} | AP28: {=_xlfn._xlws.FILTER(Spelerslijst!$N:$N,Spelerslijst!$Q:$Q=AK$26,"")} | AR28: {=_xlfn._xlws.FILTER(Spelerslijst!$B:$B,Spelerslijst!$G:$G=AR$26,"")} -> Anniek Pierse | AS28: {=_xlfn._xlws.FILTER(Spelerslijst!$H:$H,Spelerslijst!$G:$G=AR$26,"")} -> S7 | AT28: {=_xlfn._xlws.FILTER(Spelerslijst!$D:$D,Spelerslijst!$G:$G=AR$26,"")} -> 21 | AU28: {=_xlfn._xlws.FILTER(Spelerslijst!$L:$L,Spelerslijst!$Q:$Q=AR$26,"")} -> Joram Flach | AV28: {=_xlfn._xlws.FILTER(Spelerslijst!$R:$R,Spelerslijst!$Q:$Q=AR$26,"")} -> S7 | AW28: {=_xlfn._xlws.FILTER(Spelerslijst!$N:$N,Spelerslijst!$Q:$Q=AR$26,"")} -> 24 | AY28: {=_xlfn._xlws.FILTER(Spelerslijst!$B:$B,Spelerslijst!$G:$G=AY$26,"")} -> Dorien in 't Veld | AZ28: {=_xlfn._xlws.FILTER(Spelerslijst!$H:$H,Spelerslijst!$G:$G=AY$26,"")} -> MW1 | BA28: {=_xlfn._xlws.FILTER(Spelerslijst!$D:$D,Spelerslijst!$G:$G=AY$26,"")} -> 38 | BB28: {=_xlfn._xlws.FILTER(Spelerslijst!$L:$L,Spelerslijst!$Q:$Q=AY$26,"")} -> Hans Ploeg | BC28: {=_xlfn._xlws.FILTER(Spelerslijst!$R:$R,Spelerslijst!$Q:$Q=AY$26,"")} -> * | BD28: {=_xlfn._xlws.FILTER(Spelerslijst!$N:$N,Spelerslijst!$Q:$Q=AY$26,"")} -> 38
P29: Hanneke Batenburg | Q29: S3 | R29: 36 | S29: Jan Booy | T29: S3 | U29: 33 | W29: Diana Visser-Michelsen | X29: S4 | Y29: 31 | Z29: Arjan Noels | AA29: S4 | AB29: 43 | AR29: Laura Koote | AS29: S7 | AT29: 21 | AU29: Mark Schindler | AV29: S7 | AW29: 24 | AY29: Kim Heesterbeek | AZ29: * | BA29: 36 | BB29: Michiel 't Jong | BC29: MW1 | BD29: 42
P30: Linda Ardon | Q30: S3 | R30: 31 | S30: Lex van Gent | T30: S1 | U30: 28 | W30: Esther Wibbens | X30: S4 | Y30: 31 | Z30: Bart de Wit | AA30: S4 | AB30: 44 | AR30: Marlies Valk | AS30: S7 | AT30: 20 | AU30: Rick van de Wijgaart | AV30: S7 | AW30: 20 | AY30: Kim Scheurwater | AZ30: * | BA30: 35 | BB30: Peter Batenburg | BC30: * | BD30: 41
P31: Merel van Gurp | Q31: S3 | R31: 31 | S31: Roy de Vlaming | T31: S3 | U31: 39 | W31: Lieke Ploeg | X31: S4 | Y31: 37 | Z31: Bas de Jong | AA31: S4 | AB31: 33 | AR31: Nadia de Wit | AS31: S7 | AT31: 22 | AY31: Liesbeth Brand | AZ31: * | BA31: 33 | BB31: Ronald Riet | BC31: MW1 | BD31: 40
P32: Nada Hussein | Q32: S3 | R32: 33 | S32: Thomas Isarin | T32: S3 | U32: 35 | W32: Petra Verheijde | X32: S4 | Y32: 49 | Z32: Steven Kuperus | AA32: S4 | AB32: 33 | AR32: Syrah de Wit | AS32: S7 | AT32: 22 | AY32: Mirjam de Wit | AZ32: MW1 | BA32: 43 | BB32: Sebastiaan Belder | BC32: * | BD32: 43
P33: Robin Leijdsman | Q33: S3 | R33: 27 | AY33: Sanne van Andel | AZ33: * | BA33: 35 | BB33: Wilco Kooij | BC33: MW1 | BD33: 48
P34: Simone van Zwoll | Q34: S3 | R34: 29 | AY34: Tamara van Opstal-Haksteen | AZ34: MW1 | BA34: 35
B36: {=_xlfn._xlws.FILTER(Staf!$C:$C,Staf!$B:$B=Teams!B26,"")} | C36: {=_xlfn._xlws.FILTER(Staf!$A:$A,Staf!$B:$B=Teams!B26,"")} | I36: {=_xlfn._xlws.FILTER(Staf!$C:$C,Staf!$B:$B=Teams!I26,"")} | J36: {=_xlfn._xlws.FILTER(Staf!$A:$A,Staf!$B:$B=Teams!I26,"")} | P36: {=_xlfn._xlws.FILTER(Staf!$C:$C,Staf!$B:$B=Teams!P26,"")} -> Begeleider | Q36: {=_xlfn._xlws.FILTER(Staf!$A:$A,Staf!$B:$B=Teams!P26,"")} -> Kim Ardon | W36: {=_xlfn._xlws.FILTER(Staf!$C:$C,Staf!$B:$B=Teams!W26,"")} -> Thuiscoach | X36: {=_xlfn._xlws.FILTER(Staf!$A:$A,Staf!$B:$B=Teams!W26,"")} -> Marco van Kalkeren | AD36: {=_xlfn._xlws.FILTER(Staf!$C:$C,Staf!$B:$B=Teams!AD26,"")} | AE36: {=_xlfn._xlws.FILTER(Staf!$A:$A,Staf!$B:$B=Teams!AD26,"")} | AK36: {=_xlfn._xlws.FILTER(Staf!$C:$C,Staf!$B:$B=Teams!AK26,"")} | AL36: {=_xlfn._xlws.FILTER(Staf!$A:$A,Staf!$B:$B=Teams!AK26,"")} | AR36: {=_xlfn._xlws.FILTER(Staf!$C:$C,Staf!$B:$B=Teams!AR26,"")} | AS36: {=_xlfn._xlws.FILTER(Staf!$A:$A,Staf!$B:$B=Teams!AR26,"")} | AY36: {=_xlfn._xlws.FILTER(Staf!$C:$C,Staf!$B:$B=Teams!AY26,"")} | AZ36: {=_xlfn._xlws.FILTER(Staf!$A:$A,Staf!$B:$B=Teams!AY26,"")}
A40: A-Junioren | B40: A1 | G40: =AVERAGE(D42:D52,G42:G52) -> 16.9 | I40: A2 | N40: =AVERAGE(K42:K52,N42:N52) -> 17.3 | P40: A3 | U40: =AVERAGE(R42:R52,U42:U52) -> 15.454545 | W40: A4 | AB40: =AVERAGE(Y42:Y52,AB42:AB52) -> #DIV/0! | AD40: A5 | AI40: =AVERAGE(AF42:AF52,AI42:AI52) -> #DIV/0!
B41: =CONCATENATE("Dames (",COUNTA(C42:C50),")") -> Dames (5) | E41: =CONCATENATE("Heren (",COUNTA(F42:F50),")") -> Heren (5) | I41: =CONCATENATE("Dames (",COUNTA(J42:J50),")") -> Dames (5) | L41: =CONCATENATE("Heren (",COUNTA(M42:M50),")") -> Heren (5) | P41: =CONCATENATE("Dames (",COUNTA(Q42:Q50),")") -> Dames (7) | S41: =CONCATENATE("Heren (",COUNTA(T42:T50),")") -> Heren (4) | W41: =CONCATENATE("Dames (",COUNTA(X42:X50),")") -> Dames (1) | Z41: =CONCATENATE("Heren (",COUNTA(AA42:AA50),")") -> Heren (1) | AD41: =CONCATENATE("Dames (",COUNTA(AE42:AE50),")") -> Dames (1) | AG41: =CONCATENATE("Heren (",COUNTA(AH42:AH50),")") -> Heren (1)
B42: {=_xlfn._xlws.FILTER(Spelerslijst!$B:$B,Spelerslijst!$G:$G=B$40,"")} -> Amber de Haas | C42: {=_xlfn._xlws.FILTER(Spelerslijst!$H:$H,Spelerslijst!$G:$G=B$40,"")} -> B1 | D42: {=_xlfn._xlws.FILTER(Spelerslijst!$D:$D,Spelerslijst!$G:$G=B$40,"")} -> 16 | E42: {=_xlfn._xlws.FILTER(Spelerslijst!$L:$L,Spelerslijst!$Q:$Q=B$40,"")} -> Jack Zwanenburg | F42: {=_xlfn._xlws.FILTER(Spelerslijst!$R:$R,Spelerslijst!$Q:$Q=B$40,"")} -> B1 | G42: {=_xlfn._xlws.FILTER(Spelerslijst!$N:$N,Spelerslijst!$Q:$Q=B$40,"")} -> 16 | I42: {=_xlfn._xlws.FILTER(Spelerslijst!$B:$B,Spelerslijst!$G:$G=I$40,"")} -> Anouk de Jongh | J42: {=_xlfn._xlws.FILTER(Spelerslijst!$H:$H,Spelerslijst!$G:$G=I$40,"")} -> A2 | K42: {=_xlfn._xlws.FILTER(Spelerslijst!$D:$D,Spelerslijst!$G:$G=I$40,"")} -> 18 | L42: {=_xlfn._xlws.FILTER(Spelerslijst!$L:$L,Spelerslijst!$Q:$Q=I$40,"")} -> Freek van Dongen | M42: {=_xlfn._xlws.FILTER(Spelerslijst!$R:$R,Spelerslijst!$Q:$Q=I$40,"")} -> B2 | N42: {=_xlfn._xlws.FILTER(Spelerslijst!$N:$N,Spelerslijst!$Q:$Q=I$40,"")} -> 16 | P42: {=_xlfn._xlws.FILTER(Spelerslijst!$B:$B,Spelerslijst!$G:$G=P$40,"")} -> Amber Boeije | Q42: {=_xlfn._xlws.FILTER(Spelerslijst!$H:$H,Spelerslijst!$G:$G=P$40,"")} -> A3 | R42: {=_xlfn._xlws.FILTER(Spelerslijst!$D:$D,Spelerslijst!$G:$G=P$40,"")} -> 18 | S42: {=_xlfn._xlws.FILTER(Spelerslijst!$L:$L,Spelerslijst!$Q:$Q=P$40,"")} -> Laurens Verhagen | T42: {=_xlfn._xlws.FILTER(Spelerslijst!$R:$R,Spelerslijst!$Q:$Q=P$40,"")} -> A3 | U42: {=_xlfn._xlws.FILTER(Spelerslijst!$N:$N,Spelerslijst!$Q:$Q=P$40,"")} -> 19 | W42: {=_xlfn._xlws.FILTER(Spelerslijst!$B:$B,Spelerslijst!$G:$G=W$40,"")} | X42: {=_xlfn._xlws.FILTER(Spelerslijst!$H:$H,Spelerslijst!$G:$G=W$40,"")} | Y42: {=_xlfn._xlws.FILTER(Spelerslijst!$D:$D,Spelerslijst!$G:$G=W$40,"")} | Z42: {=_xlfn._xlws.FILTER(Spelerslijst!$L:$L,Spelerslijst!$Q:$Q=W$40,"")} | AA42: {=_xlfn._xlws.FILTER(Spelerslijst!$R:$R,Spelerslijst!$Q:$Q=W$40,"")} | AB42: {=_xlfn._xlws.FILTER(Spelerslijst!$N:$N,Spelerslijst!$Q:$Q=W$40,"")} | AD42: {=_xlfn._xlws.FILTER(Spelerslijst!$B:$B,Spelerslijst!$G:$G=AD$40,"")} | AE42: {=_xlfn._xlws.FILTER(Spelerslijst!$H:$H,Spelerslijst!$G:$G=AD$40,"")} | AF42: {=_xlfn._xlws.FILTER(Spelerslijst!$D:$D,Spelerslijst!$G:$G=AD$40,"")} | AG42: {=_xlfn._xlws.FILTER(Spelerslijst!$L:$L,Spelerslijst!$Q:$Q=AD$40,"")} | AH42: {=_xlfn._xlws.FILTER(Spelerslijst!$R:$R,Spelerslijst!$Q:$Q=AD$40,"")} | AI42: {=_xlfn._xlws.FILTER(Spelerslijst!$N:$N,Spelerslijst!$Q:$Q=AD$40,"")}
B43: Iza Wolleswinkel | C43: B1 | D43: 16 | E43: Jarno Valk | F43: B1 | G43: 16 | I43: Elena Quarré | J43: A2 | K43: 18 | L43: Joël Wietses | M43: A2 | N43: 18 | P43: Bente van Wijngaarden | Q43: A3 | R43: 17 | S43: Matthijs de Jongh | T43: B4 | U43: 16
B44: Merel Manduapessy | C44: B1 | D44: 16 | E44: Jens Lohuis | F44: A1 | G44: 18 | I44: Lindi Fasbender | J44: A2 | K44: 18 | L44: Seth van de Burgt | M44: B2 | N44: 17 | P44: Flore Steenks | Q44: A3 | R44: 19 | S44: Menno Pille | T44: B4 | U44: 16
B45: Roos Groeneweg | C45: A1 | D45: 18 | E45: Jordi Vaartmans | F45: B1 | G45: 17 | I45: Maud van Wensen | J45: A1 | K45: 18 | L45: Tijn Bäcker | M45: B1 | N45: 16 | P45: Julia Bozuwa | Q45: A3 | R45: 16 | S45: Tommie Koornneef | T45: B4 | U45: 16
B46: Sara Boshoven | C46: A1 | D46: 18 | E46: Senne Koster | F46: A1 | G46: 18 | I46: Mila de Wit | J46: B2 | K46: 16 | L46: Wouter Koornneef | M46: A2 | N46: 18 | P46: Lianne Bouwknegt | Q46: A3 | R46: 16
P47: Tessa van Everdingen | Q47: A3 | R47: 17
P48: Vivienne Versnel | Q48: * | R48: 0
...

Sheet Spelerslijst
A1: Rel.nr | B1: Naam & Initialen) | C1: Roepnaam | D1: Leeftijd Peildatum | E1: Geb datum | F1: Team op Peildatum | G1: Team 23-24 | H1: Team 22-23 | I1: AR | K1: Rel.nr | L1: Naam & Initialen | M1: Roepnaam | N1: Leeftijd Peildatum | O1: Geb datum | P1: Team op Peildatum | Q1: Team 23-24 | R1: Team 22-232 | S1: AR
A2: NLH27P1 | B2: Amber de Haas | C2: Amber | D2: =VLOOKUP(YEAR(Tabel1[[#This Row],[Geb datum]]),Tabel8[#All],2,FALSE) -> 16 | E2: 39114 | F2: =VLOOKUP(YEAR(Tabel1[[#This Row],[Geb datum]]),Tabel8[#All],3,FALSE) -> A | G2: A1 | H2: B1 | K2: NLG58X4 | L2: Freek van Dongen | M2: Freek | N2: =VLOOKUP(YEAR(Tabel3[[#This Row],[Geb datum]]),Tabel8[#All],2,FALSE) -> 16 | O2: 39196 | P2: =VLOOKUP(YEAR(Tabel3[[#This Row],[Geb datum]]),Tabel8[#All],3,FALSE) -> A | Q2: A2 | R2: B2
A3: NKT92K1 | B3: Anouk de Jongh | C3: Anouk | D3: =VLOOKUP(YEAR(Tabel1[[#This Row],[Geb datum]]),Tabel8[#All],2,FALSE) -> 18 | E3: 38597 | F3: =VLOOKUP(YEAR(Tabel1[[#This Row],[Geb datum]]),Tabel8[#All],3,FALSE) -> A | G3: A2 | H3: A2 | K3: NLL19V8 | L3: Jack Zwanenburg | M3: Jack | N3: =VLOOKUP(YEAR(Tabel3[[#This Row],[Geb datum]]),Tabel8[#All],2,FALSE) -> 16 | O3: 39356 | P3: =VLOOKUP(YEAR(Tabel3[[#This Row],[Geb datum]]),Tabel8[#All],3,FALSE) -> A | Q3: A1 | R3: B1
A4: NLB70S0 | B4: Elena Quarré | C4: Elena | D4: =VLOOKUP(YEAR(Tabel1[[#This Row],[Geb datum]]),Tabel8[#All],2,FALSE) -> 18 | E4: 38509 | F4: =VLOOKUP(YEAR(Tabel1[[#This Row],[Geb datum]]),Tabel8[#All],3,FALSE) -> A | G4: A2 | H4: A2 | K4: NLG57L7 | L4: Jarno Valk | M4: Jarno | N4: =VLOOKUP(YEAR(Tabel3[[#This Row],[Geb datum]]),Tabel8[#All],2,FALSE) -> 16 | O4: 39367 | P4: =VLOOKUP(YEAR(Tabel3[[#This Row],[Geb datum]]),Tabel8[#All],3,FALSE) -> A | Q4: A1 | R4: B1
A5: NLP78N3 | B5: Iza Wolleswinkel | C5: Iza | D5: =VLOOKUP(YEAR(Tabel1[[#This Row],[Geb datum]]),Tabel8[#All],2,FALSE) -> 16 | E5: 39328 | F5: =VLOOKUP(YEAR(Tabel1[[#This Row],[Geb datum]]),Tabel8[#All],3,FALSE) -> A | G5: A1 | H5: B1 | K5: NLG59F1 | L5: Jens Lohuis | M5: Jens | N5: =VLOOKUP(YEAR(Tabel3[[#This Row],[Geb datum]]),Tabel8[#All],2,FALSE) -> 18 | O5: 38578 | P5: =VLOOKUP(YEAR(Tabel3[[#This Row],[Geb datum]]),Tabel8[#All],3,FALSE) -> A | Q5: A1 | R5: A1
A6: NLF50K8 | B6: Lindi Fasbender | C6: Lindi | D6: =VLOOKUP(YEAR(Tabel1[[#This Row],[Geb datum]]),Tabel8[#All],2,FALSE) -> 18 | E6: 38656 | F6: =VLOOKUP(YEAR(Tabel1[[#This Row],[Geb datum]]),Tabel8[#All],3,FALSE) -> A | G6: A2 | H6: A2 | K6: NLB70Y2 | L6: Joeke Meijer | M6: Joeke | N6: =VLOOKUP(YEAR(Tabel3[[#This Row],[Geb datum]]),Tabel8[#All],2,FALSE) -> 18 | O6: 38617 | P6: =VLOOKUP(YEAR(Tabel3[[#This Row],[Geb datum]]),Tabel8[#All],3,FALSE) -> A | Q6: Stopt | R6: A2
A7: NLL20B6 | B7: Maud van Wensen | C7: Maud | D7: =VLOOKUP(YEAR(Tabel1[[#This Row],[Geb datum]]),Tabel8[#All],2,FALSE) -> 18 | E7: 38451 | F7: =VLOOKUP(YEAR(Tabel1[[#This Row],[Geb datum]]),Tabel8[#All],3,FALSE) -> A | G7: A2 | H7: A1 | K7: NKX66T5 | L7: Joël Wietses | M7: Joël | N7: =VLOOKUP(YEAR(Tabel3[[#This Row],[Geb datum]]),Tabel8[#All],2,FALSE) -> 18 | O7: 38502 | P7: =VLOOKUP(YEAR(Tabel3[[#This Row],[Geb datum]]),Tabel8[#All],3,FALSE) -> A | Q7: A2 | R7: A2
A8: NLL81G4 | B8: Merel Manduapessy | C8: Merel | D8: =VLOOKUP(YEAR(Tabel1[[#This Row],[Geb datum]]),Tabel8[#All],2,FALSE) -> 16 | E8: 39324 | F8: =VLOOKUP(YEAR(Tabel1[[#This Row],[Geb datum]]),Tabel8[#All],3,FALSE) -> A | G8: A1 | H8: B1 | K8: NLG58W7 | L8: Jordi Vaartmans | M8: Jordi | N8: =VLOOKUP(YEAR(Tabel3[[#This Row],[Geb datum]]),Tabel8[#All],2,FALSE) -> 17 | O8: 39069 | P8: =VLOOKUP(YEAR(Tabel3[[#This Row],[Geb datum]]),Tabel8[#All],3,FALSE) -> A | Q8: A1 | R8: B1
A9: NLL19T4 | B9: Mila de Wit | C9: Mila | D9: =VLOOKUP(YEAR(Tabel1[[#This Row],[Geb datum]]),Tabel8[#All],2,FALSE) -> 16 | E9: 39433 | F9: =VLOOKUP(YEAR(Tabel1[[#This Row],[Geb datum]]),Tabel8[#All],3,FALSE) -> A | G9: A2 | H9: B2 | K9: NLG59G8 | L9: Senne Koster | M9: Senne | N9: =VLOOKUP(YEAR(Tabel3[[#This Row],[Geb datum]]),Tabel8[#All],2,FALSE) -> 18 | O9: 38657 | P9: =VLOOKUP(YEAR(Tabel3[[#This Row],[Geb datum]]),Tabel8[#All],3,FALSE) -> A | Q9: A1 | R9: A1
A10: NKY17P6 | B10: Roos Groeneweg | C10: Roos | D10: =VLOOKUP(YEAR(Tabel1[[#This Row],[Geb datum]]),Tabel8[#All],2,FALSE) -> 18 | E10: 38432 | F10: =VLOOKUP(YEAR(Tabel1[[#This Row],[Geb datum]]),Tabel8[#All],3,FALSE) -> A | G10: A1 | H10: A1 | K10: NLL20F4 | L10: Seth van de Burgt | M10: Seth | N10: =VLOOKUP(YEAR(Tabel3[[#This Row],[Geb datum]]),Tabel8[#All],2,FALSE) -> 17 | O10: 39018 | P10: =VLOOKUP(YEAR(Tabel3[[#This Row],[Geb datum]]),Tabel8[#All],3,FALSE) -> A | Q10: A2 | R10: B2
A11: NLB71D8 | B11: Sara Boshoven | C11: Sara | D11: =VLOOKUP(YEAR(Tabel1[[#This Row],[Geb datum]]),Tabel8[#All],2,FALSE) -> 18 | E11: 38635 | F11: =VLOOKUP(YEAR(Tabel1[[#This Row],[Geb datum]]),Tabel8[#All],3,FALSE) -> A | G11: A1 | H11: A1 | K11: NLG57P5 | L11: Tijn Bäcker | M11: Tijn | N11: =VLOOKUP(YEAR(Tabel3[[#This Row],[Geb datum]]),Tabel8[#All],2,FALSE) -> 16 | O11: 39239 | P11: =VLOOKUP(YEAR(Tabel3[[#This Row],[Geb datum]]),Tabel8[#All],3,FALSE) -> A | Q11: A2 | R11: B1
A12: NLB70T7 | B12: Amber Boeije | C12: Amber | D12: =VLOOKUP(YEAR(Tabel1[[#This Row],[Geb datum]]),Tabel8[#All],2,FALSE) -> 18 | E12: 38480 | F12: =VLOOKUP(YEAR(Tabel1[[#This Row],[Geb datum]]),Tabel8[#All],3,FALSE) -> A | G12: A3 | H12: A3 | K12: NLM05B2 | L12: Tycho Vliet | M12: Tycho | N12: =VLOOKUP(YEAR(Tabel3[[#This Row],[Geb datum]]),Tabel8[#All],2,FALSE) -> 16 | O12: 39346 | P12: =VLOOKUP(YEAR(Tabel3[[#This Row],[Geb datum]]),Tabel8[#All],3,FALSE) -> A | Q12: B2 | R12: B2
A13: NKS24S7 | B13: Bente van Wijngaarden | C13: Bente | D13: =VLOOKUP(YEAR(Tabel1[[#This Row],[Geb datum]]),Tabel8[#All],2,FALSE) -> 17 | E13: 38928 | F13: =VLOOKUP(YEAR(Tabel1[[#This Row],[Geb datum]]),Tabel8[#All],3,FALSE) -> A | G13: A3 | H13: A3 | K13: NLB71F2 | L13: Wouter Koornneef | M13: Wouter | N13: =VLOOKUP(YEAR(Tabel3[[#This Row],[Geb datum]]),Tabel8[#All],2,FALSE) -> 18 | O13: 38517 | P13: =VLOOKUP(YEAR(Tabel3[[#This Row],[Geb datum]]),Tabel8[#All],3,FALSE) -> A | Q13: A2 | R13: A2
... A17: NLJ47P3 | B17: Tessa van Everdingen | C17: Tessa | D17: =VLOOKUP(YEAR(Tabel1[[#This Row],[Geb datum]]),Tabel8[#All],2,FALSE) -> 17 | E17: 38900 | F17: =VLOOKUP(YEAR(Tabel1[[#This Row],[Geb datum]]),Tabel8[#All],3,FALSE) -> A | G17: A3 | H17: A3 | K17: NLB71B4 | L17: Tommie Koornneef | M17: Tommie | N17: =VLOOKUP(YEAR(Tabel3[[#This Row],[Geb datum]]),Tabel8[#All],2,FALSE) -> 16 | O17: 39123 | P17: =VLOOKUP(YEAR(Tabel3[[#This Row],[Geb datum]]),Tabel8[#All],3,FALSE) -> A | Q17: A3 | R17: B4
B18: Vivienne Versnel | C18: Vivienne | G18: A3 | H18: * | K18: NJH39X4 | L18: Bart van der Brugge | M18: Bart | N18: =VLOOKUP(YEAR(Tabel3[[#This Row],[Geb datum]]),Tabel8[#All],2,FALSE) -> 28 | O18: 34900 | P18: =VLOOKUP(YEAR(Tabel3[[#This Row],[Geb datum]]),Tabel8[#All],3,FALSE) -> S | Q18: AR | R18: AR
A19: NKD19X7 | B19: Anne Driesprong | C19: Anne | D19: =VLOOKUP(YEAR(Tabel1[[#This Row],[Geb datum]]),Tabel8[#All],2,FALSE) -> 23 | E19: 36727 | F19: =VLOOKUP(YEAR(Tabel1[[#This Row],[Geb datum]]),Tabel8[#All],3,FALSE) -> S | G19: AR | H19: AR | K19: NKX66V9 | L19: Bert Seevinck | M19: Bert | N19: =VLOOKUP(YEAR(Tabel3[[#This Row],[Geb datum]]),Tabel8[#All],2,FALSE) -> 62 | O19: 22358 | P19: =VLOOKUP(YEAR(Tabel3[[#This Row],[Geb datum]]),Tabel8[#All],3,FALSE) -> S | Q19: AR | R19: AR
A20: NKX56Q9 | B20: Damaris Everaarts | C20: Damaris | D20: =VLOOKUP(YEAR(Tabel1[[#This Row],[Geb datum]]),Tabel8[#All],2,FALSE) -> 44 | E20: 28948 | F20: =VLOOKUP(YEAR(Tabel1[[#This Row],[Geb datum]]),Tabel8[#All],3,FALSE) -> S | G20: AR | H20: AR | K20: NJG52P6 | L20: Freek de Peuter | M20: Freek | N20: =VLOOKUP(YEAR(Tabel3[[#This Row],[Geb datum]]),Tabel8[#All],2,FALSE) -> 27 | O20: 35270 | P20: =VLOOKUP(YEAR(Tabel3[[#This Row],[Geb datum]]),Tabel8[#All],3,FALSE) -> S | Q20: AR | R20: S2
A21: NGT43N2 | B21: Hilde Visser | C21: Hilde | D21: =VLOOKUP(YEAR(Tabel1[[#This Row],[Geb datum]]),Tabel8[#All],2,FALSE) -> 33 | E21: 33146 | F21: =VLOOKUP(YEAR(Tabel1[[#This Row],[Geb datum]]),Tabel8[#All],3,FALSE) -> S | G21: AR | H21: S4 | K21: NFW28T5 | L21: Jasper Kleingeld | M21: Jasper | N21: =VLOOKUP(YEAR(Tabel3[[#This Row],[Geb datum]]),Tabel8[#All],2,FALSE) -> 38 | O21: 31083 | P21: =VLOOKUP(YEAR(Tabel3[[#This Row],[Geb datum]]),Tabel8[#All],3,FALSE) -> S | Q21: AR | R21: AR
A22: NJW77M6 | B22: Merel Schram | C22: Merel | D22: =VLOOKUP(YEAR(Tabel1[[#This Row],[Geb datum]]),Tabel8[#All],2,FALSE) -> 24 | E22: 36432 | F22: =VLOOKUP(YEAR(Tabel1[[#This Row],[Geb datum]]),Tabel8[#All],3,FALSE) -> S | G22: AR | H22: S2 | K22: NJH51J2 | L22: Jeroen Huijgen | M22: Jeroen | N22: =VLOOKUP(YEAR(Tabel3[[#This Row],[Geb datum]]),Tabel8[#All],2,FALSE) -> 27 | O22: 35145 | P22: =VLOOKUP(YEAR(Tabel3[[#This Row],[Geb datum]]),Tabel8[#All],3,FALSE) -> S | Q22: AR | R22: AR
A23: NGT43H0 | B23: Mirjam Noordam | C23: Mirjam | D23: =VLOOKUP(YEAR(Tabel1[[#This Row],[Geb datum]]),Tabel8[#All],2,FALSE) -> 36 | E23: 32119 | F23: =VLOOKUP(YEAR(Tabel1[[#This Row],[Geb datum]]),Tabel8[#All],3,FALSE) -> S | G23: AR | H23: S4 | K23: NFW15F3 | L23: Johan van der Wall | M23: Johan | N23: =VLOOKUP(YEAR(Tabel3[[#This Row],[Geb datum]]),Tabel8[#All],2,FALSE) -> 58 | O23: 24003 | P23: =VLOOKUP(YEAR(Tabel3[[#This Row],[Geb datum]]),Tabel8[#All],3,FALSE) -> S | Q23: AR | R23: AR
A24: NKF94H2 | B24: Tirsa Fernhout | C24: Tirsa | D24: =VLOOKUP(YEAR(Tabel1[[#This Row],[Geb datum]]),Tabel8[#All],2,FALSE) -> 25 | E24: 35817 | F24: =VLOOKUP(YEAR(Tabel1[[#This Row],[Geb datum]]),Tabel8[#All],3,FALSE) -> S | G24: AR | H24: AR | K24: NJF53H2 | L24: Lars van Strijen | M24: Lars | N24: =VLOOKUP(YEAR(Tabel3[[#This Row],[Geb datum]]),Tabel8[#All],2,FALSE) -> 27 | O24: 35330 | P24: =VLOOKUP(YEAR(Tabel3[[#This Row],[Geb datum]]),Tabel8[#All],3,FALSE) -> S | Q24: AR | R24: AR
A25: NLY40X3 | B25: Anjanette Matena | C25: Anjanette | D25: =VLOOKUP(YEAR(Tabel1[[#This Row],[Geb datum]]),Tabel8[#All],2,FALSE) -> 14 | E25: 39961 | F25: =VLOOKUP(YEAR(Tabel1[[#This Row],[Geb datum]]),Tabel8[#All],3,FALSE) -> B | G25: Stopt | H25: C1 | K25: NFX11D8 | L25: Lex van Dalen | M25: Lex | N25: =VLOOKUP(YEAR(Tabel3[[#This Row],[Geb datum]]),Tabel8[#All],2,FALSE) -> 56 | O25: 24583 | P25: =VLOOKUP(YEAR(Tabel3[[#This Row],[Geb datum]]),Tabel8[#All],3,FALSE) -> S | Q25: AR | R25: AR
A26: NLP78D3 | B26: Benthe van der Linden | C26: Benthe | D26: =VLOOKUP(YEAR(Tabel1[[#This Row],[Geb datum]]),Tabel8[#All],2,FALSE) -> 15 | E26: 39629 | F26: =VLOOKUP(YEAR(Tabel1[[#This Row],[Geb datum]]),Tabel8[#All],3,FALSE) -> B | G26: B2 | H26: B2 | K26: NJH51W3 | L26: Peter Berendsen | M26: Peter | N26: =VLOOKUP(YEAR(Tabel3[[#This Row],[Geb datum]]),Tabel8[#All],2,FALSE) -> 26 | O26: 35488 | P26: =VLOOKUP(YEAR(Tabel3[[#This Row],[Geb datum]]),Tabel8[#All],3,FALSE) -> S | Q26: AR | R26: AR
A27: NLN05N7 | B27: Carmen van der Klooster | C27: Carmen | D27: =VLOOKUP(YEAR(Tabel1[[#This Row],[Geb datum]]),Tabel8[#All],2,FALSE) -> 15 | E27: 39760 | F27: =VLOOKUP(YEAR(Tabel1[[#This Row],[Geb datum]]),Tabel8[#All],3,FALSE) -> B | G27: B1 | H27: B1 | K27: NGT42V5 | L27: Rens Draaijer | M27: Rens | N27: =VLOOKUP(YEAR(Tabel3[[#This Row],[Geb datum]]),Tabel8[#All],2,FALSE) -> 33 | O27: 33211 | P27: =VLOOKUP(YEAR(Tabel3[[#This Row],[Geb datum]]),Tabel8[#All],3,FALSE) -> S | Q27: AR | R27: AR
A28: NLT96R9 | B28: Doeska Voorbij | C28: Doeska | D28: =VLOOKUP(YEAR(Tabel1[[#This Row],[Geb datum]]),Tabel8[#All],2,FALSE) -> 15 | E28: 39751 | F28: =VLOOKUP(YEAR(Tabel1[[#This Row],[Geb datum]]),Tabel8[#All],3,FALSE) -> B | G28: B1 | H28: B2 | K28: NGP49B2 | L28: Robbert van Ameijden | M28: Robbert | N28: =VLOOKUP(YEAR(Tabel3[[#This Row],[Geb datum]]),Tabel8[#All],2,FALSE) -> 33 | O28: 32911 | P28: =VLOOKUP(YEAR(Tabel3[[#This Row],[Geb datum]]),Tabel8[#All],3,FALSE) -> S | Q28: AR | R28: AR
A29: NLL20G1 | B29: Elize van de Burgt | C29: Elize | D29: =VLOOKUP(YEAR(Tabel1[[#This Row],[Geb datum]]),Tabel8[#All],2,FALSE) -> 15 | E29: 39804 | F29: =VLOOKUP(YEAR(Tabel1[[#This Row],[Geb datum]]),Tabel8[#All],3,FALSE) -> B | G29: B2 | H29: B2 | K29: NKG59J2 | L29: Tim Groeneweg | M29: Tim | N29: =VLOOKUP(YEAR(Tabel3[[#This Row],[Geb datum]]),Tabel8[#All],2,FALSE) -> 22 | O29: 37246 | P29: =VLOOKUP(YEAR(Tabel3[[#This Row],[Geb datum]]),Tabel8[#All],3,FALSE) -> S | Q29: AR | R29: S2
A30: NLJ04Z4 | B30: Floor Lohuis | C30: Floor | D30: =VLOOKUP(YEAR(Tabel1[[#This Row],[Geb datum]]),Tabel8[#All],2,FALSE) -> 14 | E30: 39878 | F30: =VLOOKUP(YEAR(Tabel1[[#This Row],[Geb datum]]),Tabel8[#All],3,FALSE) -> B | G30: B2 | H30: C2 | K30: NJF34K6 | L30: Tom Hendriks | M30: Tom | N30: =VLOOKUP(YEAR(Tabel3[[#This Row],[Geb datum]]),Tabel8[#All],2,FALSE) -> 27 | O30: 35092 | P30: =VLOOKUP(YEAR(Tabel3[[#This Row],[Geb datum]]),Tabel8[#All],3,FALSE) -> S | Q30: AR | R30: AR
... A85: NMD34T8 | B85: Lisa Exalto | C85: Lisa | D85: =VLOOKUP(YEAR(Tabel1[[#This Row],[Geb datum]]),Tabel8[#All],2,FALSE) -> 9 | E85: 41807 | F85: =VLOOKUP(YEAR(Tabel1[[#This Row],[Geb datum]]),Tabel8[#All],3,FALSE) -> E | G85: E2 | H85: E5 | K85: NMV01T2 | L85: Rens Boekee | M85: Rens | N85: =VLOOKUP(YEAR(Tabel3[[#This Row],[Geb datum]]),Tabel8[#All],2,FALSE) -> 8 | O85: 42156 | P85: =VLOOKUP(YEAR(Tabel3[[#This Row],[Geb datum]]),Tabel8[#All],3,FALSE) -> E | Q85: E4 | R85: F1
A86: NMQ40P6 | B86: Emma Schot | C86: Emma | D86: =VLOOKUP(YEAR(Tabel1[[#This Row],[Geb datum]]),Tabel8[#All],2,FALSE) -> 10 | E86: 41586 | F86: =VLOOKUP(YEAR(Tabel1[[#This Row],[Geb datum]]),Tabel8[#All],3,FALSE) -> D | G86: E3 | H86: E7 | L86: Gideon Verberkt | M86: Gideon | N86: =VLOOKUP(YEAR(Tabel3[[#This Row],[Geb datum]]),Tabel8[#All],2,FALSE) -> 9 | O86: 41640 | P86: =VLOOKUP(YEAR(Tabel3[[#This Row],[Geb datum]]),Tabel8[#All],3,FALSE) -> E | Q86: E5 | R86: *
A87: NML14J6 | B87: Suze Maaskant | C87: Suze | D87: =VLOOKUP(YEAR(Tabel1[[#This Row],[Geb datum]]),Tabel8[#All],2,FALSE) -> 8 | E87: 42188 | F87: =VLOOKUP(YEAR(Tabel1[[#This Row],[Geb datum]]),Tabel8[#All],3,FALSE) -> E | G87: E3 | H87: F2 | K87: NMV70H0 | L87: Timo van der Sijde | M87: Timo | N87: =VLOOKUP(YEAR(Tabel3[[#This Row],[Geb datum]]),Tabel8[#All],2,FALSE) -> 8 | O87: 42324 | P87: =VLOOKUP(YEAR(Tabel3[[#This Row],[Geb datum]]),Tabel8[#All],3,FALSE) -> E | Q87: E5 | R87: *
A88: NMS99T8 | B88: Tess Rebollo | C88: Tess | D88: =VLOOKUP(YEAR(Tabel1[[#This Row],[Geb datum]]),Tabel8[#All],2,FALSE) -> 8 | E88: 42111 | F88: =VLOOKUP(YEAR(Tabel1[[#This Row],[Geb datum]]),Tabel8[#All],3,FALSE) -> E | G88: E3 | H88: F2 | K88: NMV71X5 | L88: Amos Alberts | M88: Amos | N88: =VLOOKUP(YEAR(Tabel3[[#This Row],[Geb datum]]),Tabel8[#All],2,FALSE) -> 6 | O88: 42901 | P88: =VLOOKUP(YEAR(Tabel3[[#This Row],[Geb datum]]),Tabel8[#All],3,FALSE) -> F | Q88: F1 | R88: *
A89: NMM97Y1 | B89: Maartje Laban | C89: Maartje | D89: =VLOOKUP(YEAR(Tabel1[[#This Row],[Geb datum]]),Tabel8[#All],2,FALSE) -> 8 | E89: 42058 | F89: =VLOOKUP(YEAR(Tabel1[[#This Row],[Geb datum]]),Tabel8[#All],3,FALSE) -> E | G89: E4 | H89: F1 | K89: NMV76G1 | L89: Art Malschaert | M89: Art | N89: =VLOOKUP(YEAR(Tabel3[[#This Row],[Geb datum]]),Tabel8[#All],2,FALSE) -> 6 | O89: 42955 | P89: =VLOOKUP(YEAR(Tabel3[[#This Row],[Geb datum]]),Tabel8[#All],3,FALSE) -> F | Q89: F2 | R89: *
A90: NMK64V4 | B90: Robin Mans | C90: Robin | D90: =VLOOKUP(YEAR(Tabel1[[#This Row],[Geb datum]]),Tabel8[#All],2,FALSE) -> 8 | E90: 42249 | F90: =VLOOKUP(YEAR(Tabel1[[#This Row],[Geb datum]]),Tabel8[#All],3,FALSE) -> E | G90: E4 | H90: F1 | L90: Sem van de Wiel | M90: Sem | N90: =VLOOKUP(YEAR(Tabel3[[#This Row],[Geb datum]]),Tabel8[#All],2,FALSE) -> 6 | O90: 42736 | P90: =VLOOKUP(YEAR(Tabel3[[#This Row],[Geb datum]]),Tabel8[#All],3,FALSE) -> F | Q90: F2 | R90: *
A91: NML53R9 | B91: Sofie Kleingeld | C91: Sofie | D91: =VLOOKUP(YEAR(Tabel1[[#This Row],[Geb datum]]),Tabel8[#All],2,FALSE) -> 8 | E91: 42096 | F91: =VLOOKUP(YEAR(Tabel1[[#This Row],[Geb datum]]),Tabel8[#All],3,FALSE) -> E | G91: E4 | H91: F1 | L91: Hans Ploeg | M91: Hans | N91: =VLOOKUP(YEAR(Tabel3[[#This Row],[Geb datum]]),Tabel8[#All],2,FALSE) -> 38 | O91: 31048 | P91: =VLOOKUP(YEAR(Tabel3[[#This Row],[Geb datum]]),Tabel8[#All],3,FALSE) -> S | Q91: MW1 | R91: *
A92: NMS40B0 | B92: Aniek van den Bergh | C92: Aniek | D92: =VLOOKUP(YEAR(Tabel1[[#This Row],[Geb datum]]),Tabel8[#All],2,FALSE) -> 8 | E92: 42308 | F92: =VLOOKUP(YEAR(Tabel1[[#This Row],[Geb datum]]),Tabel8[#All],3,FALSE) -> E | G92: E5 | H92: F2 | K92: NFW42X5 | L92: Michiel 't Jong | M92: Michiel | N92: =VLOOKUP(YEAR(Tabel3[[#This Row],[Geb datum]]),Tabel8[#All],2,FALSE) -> 42 | O92: 29718 | P92: =VLOOKUP(YEAR(Tabel3[[#This Row],[Geb datum]]),Tabel8[#All],3,FALSE) -> S | Q92: MW1 | R92: MW1
A93: NMQ57Y5 | B93: Feliz Lanser | C93: Feliz | D93: =VLOOKUP(YEAR(Tabel1[[#This Row],[Geb datum]]),Tabel8[#All],2,FALSE) -> 8 | E93: 42333 | F93: =VLOOKUP(YEAR(Tabel1[[#This Row],[Geb datum]]),Tabel8[#All],3,FALSE) -> E | G93: E5 | H93: F2 | K93: NFZ85W0 | L93: Peter Batenburg | M93: Peter | N93: =VLOOKUP(YEAR(Tabel3[[#This Row],[Geb datum]]),Tabel8[#All],2,FALSE) -> 41 | O93: 30083 | P93: =VLOOKUP(YEAR(Tabel3[[#This Row],[Geb datum]]),Tabel8[#All],3,FALSE) -> S | Q93: MW1 | R93: *
A94: NMS09V7 | B94: Julia van Twist | C94: Julia | D94: =VLOOKUP(YEAR(Tabel1[[#This Row],[Geb datum]]),Tabel8[#All],2,FALSE) -> 8 | E94: 42234 | F94: =VLOOKUP(YEAR(Tabel1[[#This Row],[Geb datum]]),Tabel8[#All],3,FALSE) -> E | G94: E5 | H94: F2 | K94: NFV13V8 | L94: Ronald Riet | M94: Ronald | N94: =VLOOKUP(YEAR(Tabel3[[#This Row],[Geb datum]]),Tabel8[#All],2,FALSE) -> 40 | O94: 30397 | P94: =VLOOKUP(YEAR(Tabel3[[#This Row],[Geb datum]]),Tabel8[#All],3,FALSE) -> S | Q94: MW1 | R94: MW1
B95: Sanae | C95: Sanae | E95: 42005 | F95: =VLOOKUP(YEAR(Tabel1[[#This Row],[Geb datum]]),Tabel8[#All],3,FALSE) -> E | G95: E5 | H95: * | L95: Sebastiaan Belder | M95: Sebastiaan | N95: =VLOOKUP(YEAR(Tabel3[[#This Row],[Geb datum]]),Tabel8[#All],2,FALSE) -> 43 | O95: 29221 | P95: =VLOOKUP(YEAR(Tabel3[[#This Row],[Geb datum]]),Tabel8[#All],3,FALSE) -> S | Q95: MW1 | R95: *
A96: NMV61M3 | B96: Alisa Stomp | C96: Alisa | D96: =VLOOKUP(YEAR(Tabel1[[#This Row],[Geb datum]]),Tabel8[#All],2,FALSE) -> 6 | E96: 42919 | F96: =VLOOKUP(YEAR(Tabel1[[#This Row],[Geb datum]]),Tabel8[#All],3,FALSE) -> F | G96: F1 | H96: * | K96: NKH71P1 | L96: Wilco Kooij | M96: Wilco | N96: =VLOOKUP(YEAR(Tabel3[[#This Row],[Geb datum]]),Tabel8[#All],2,FALSE) -> 48 | O96: 27643 | P96: =VLOOKUP(YEAR(Tabel3[[#This Row],[Geb datum]]),Tabel8[#All],3,FALSE) -> S | Q96: MW1 | R96: MW1
A97: NMS67Y2 | B97: Imme Bouman | C97: Imme | D97: =VLOOKUP(YEAR(Tabel1[[#This Row],[Geb datum]]),Tabel8[#All],2,FALSE) -> 7 | E97: 42481 | F97: =VLOOKUP(YEAR(Tabel1[[#This Row],[Geb datum]]),Tabel8[#All],3,FALSE) -> F | G97: F1 | H97: F2 | K97: NFW40B5 | L97: Erwin Belder | M97: Erwin | N97: =VLOOKUP(YEAR(Tabel3[[#This Row],[Geb datum]]),Tabel8[#All],2,FALSE) -> 46 | O97: 28259 | P97: =VLOOKUP(YEAR(Tabel3[[#This Row],[Geb datum]]),Tabel8[#All],3,FALSE) -> S | Q97: NSL | R97: NSL
...

Sheet Count
B2: Dames | C2: Aantal | E2: Heren | F2: Aantal | H2: Totaal
B3: K | C3: =COUNTIF(Spelerslijst!F:F,Count!B3) -> 2 | E3: K | F3: =COUNTIF(Spelerslijst!P:P,Count!E3) -> 1 | H3: =Tabel7[[#This Row],[Aantal]]+Tabel9[[#This Row],[Aantal]] -> 3
B4: F | C4: =COUNTIF(Spelerslijst!F:F,Count!B4) -> 8 | E4: F | F4: =COUNTIF(Spelerslijst!P:P,Count!E4) -> 4 | H4: =Tabel7[[#This Row],[Aantal]]+Tabel9[[#This Row],[Aantal]] -> 12 | J4: 2
B5: E | C5: =COUNTIF(Spelerslijst!F:F,Count!B5) -> 14 | E5: E | F5: =COUNTIF(Spelerslijst!P:P,Count!E5) -> 16 | H5: =Tabel7[[#This Row],[Aantal]]+Tabel9[[#This Row],[Aantal]] -> 30 | J5: 5
B6: D | C6: =COUNTIF(Spelerslijst!F:F,Count!B6) -> 22 | E6: D | F6: =COUNTIF(Spelerslijst!P:P,Count!E6) -> 12 | H6: =Tabel7[[#This Row],[Aantal]]+Tabel9[[#This Row],[Aantal]] -> 34 | J6: 3
B7: C | C7: =COUNTIF(Spelerslijst!F:F,Count!B7) -> 23 | E7: C | F7: =COUNTIF(Spelerslijst!P:P,Count!E7) -> 15 | H7: =Tabel7[[#This Row],[Aantal]]+Tabel9[[#This Row],[Aantal]] -> 38 | J7: 4
B8: B | C8: =COUNTIF(Spelerslijst!F:F,Count!B8) -> 18 | E8: B | F8: =COUNTIF(Spelerslijst!P:P,Count!E8) -> 16 | H8: =Tabel7[[#This Row],[Aantal]]+Tabel9[[#This Row],[Aantal]] -> 34 | J8: 3
B9: A | C9: =COUNTIF(Spelerslijst!F:F,Count!B9) -> 18 | E9: A | F9: =COUNTIF(Spelerslijst!P:P,Count!E9) -> 20 | H9: =Tabel7[[#This Row],[Aantal]]+Tabel9[[#This Row],[Aantal]] -> 38 | J9: 4
B10: S | C10: =COUNTIF(Spelerslijst!F:F,Count!B10) -> 61 | E10: S | F10: =COUNTIF(Spelerslijst!P:P,Count!E10) -> 63 | H10: =Tabel7[[#This Row],[Aantal]]+Tabel9[[#This Row],[Aantal]] -> 124
H11: =SUM(H3:H10) -> 313
C15: M | D15: J
B16: D | C16: 22 | D16: 11 | E16: 3
B17: E | C17: 13 | D17: 13 | E17: 26

Sheet Staf
A1: Naam | B1: Team | C1: Functie | D1: eigen team | E1: team vorig jaar | F1: Niveau
A2: Tim van Gent | B2: A2 | C2: Trainer/Coach A2 | D2: S1S2 | F2: Junior
A3: Rob van Dongen | B3: A1A2 | C3: Trainer/Coach A1 | D3: X | F3: Medior - KT3
A4: Olivier Klink | B4: A2 | C4: Trainer/Coach A2 | D4: S1S2 | F4: Medior - KT3
A5: Ruben Blokland | B5: A1 | C5: Trainer/Coach A1 | D5: X | F5: Senior
A6: Rob van Dongen | B6: A1 | C6: Trainer/Coach A1 | D6: X
A7: Robbert van Ameijden | B7: Stopt | C7: Trainer/Coach | D7: X
A8: Lex van Dalen | B8: Stopt | C8: Trainer/Coach | D8: X
A9: Team 6 | B9: A3 | C9: Trainer/Coach
A10: o.a. Kimberley Witman & Angela Friebel | B10: A3
A11: o.a. Ruben Dubbeld & David Kuijper | B11: A3
A12: Milou Oppe | B12: B1 | C12: Trainer/Coach | D12: S1/S2 | F12: Junior - KT2
A13: Stephan Ligtmans | B13: B1 | C13: Trainer/Coach | D13: X | F13: Medior - KT3
A14: Michel Sas | B14: B1 | C14: Teambegeleider | D14: X
A15: Daniel den Uijl | B15: B2 | C15: Trainer/Coach
A16: Eva Teerds | B16: B2 | C16: Trainer/Coach
A17: Maud van Wensen | B17: B3 | C17: Trainer/Coach | D17: A1/A2 | F17: Junior - KT2
A18: Laura Mol | B18: B3 | C18: Trainer/Coach
A19: Robert Koster | B19: B3 | C19: Trainer/Coach | D19: X | F19: Senior
A20: Mees Oppe | B20: C1 | C20: Trainer/Coach | D20: DeetosSnel 1 | F20: Junior - KT2
A21: Jasper Kleingeld | B21: C1 | C21: Trainer/Coach | D21: X | F21: Senior
A22: Antjan Laban | B22: C2 | C22: Trainer/Coach | D22: X | F22: Senior
A23: Tessa Dubbeld | B23: C2 | C23: Trainer/Coach | D23: S6
A24: Kimberly Jacobs | B24: C3 | C24: Trainer/Coach | D24: X | F24: Medior
A25: Martijn van der Wiel | B25: C3 | C25: Trainer/Coach | D25: X | F25: Medior
A26: Mark Schindler | B26: D3 | C26: Trainer/Coach | D26: S7 | F26: Junior
A27: Rick van de Wijgaart | B27: D3 | C27: Trainer/Coach | D27: S7 | F27: Startend - KT2
A28: Jarno Valk | B28: D3 | C28: Trainer/Coach | D28: A1/A2 | F28: Startend - KT2
A29: Joram Flach | B29: D1 | C29: Trainer/Coach | D29: S7 | F29: Medior
A30: Marlies Valk | B30: D1 | C30: Trainer/Coach | D30: S7 | F30: Medior
A31: Egbert Vos | B31: D1 | C31: Assistent-trainer | D31: X | F31: Senior
A32: Marcel St. Nicolaas | B32: D2 | C32: Trainer/Coach | D32: X | F32: Medior
A33: Tom van de Ven | B33: D2 | C33: Trainer/Coach | D33: X | F33: Medior
A34: Alex de Boer | B34: D2 | C34: Assistent-trainer | D34: X | F34: Senior
A35: Lieke Ploeg | B35: Stopt | C35: Trainer/Coach | D35: X
A36: Syrah de Wit | B36: C4 | C36: Trainer/Coach | D36: S7 | F36: Junior
A37: Nadia de Wit | B37: C4 | C37: Trainer/Coach | D37: S7 | F37: Junior
A38: Bart de Wit | B38: E1 | C38: Trainer/Coach | D38: S4 | F38: Senior
A39: Anouk de Jongh | B39: E2 | C39: Trainer/Coach | D39: A3 | F39: Medior
A40: Sjoerd van Ameijden | B40: E2 | C40: Trainer/Coach | D40: X | F40: Medior
...

Sheet Teams-deelversie
A2: Selecties | B2: S1S2 | I2: S5S6 | P2: A1A2 | W2: B1B2
B3: Dames | E3: Heren | I3: Dames | L3: Heren | P3: Dames | S3: Heren | W3: Dames | Z3: Heren
B4: {=_xlfn._xlws.FILTER(Spelerslijst!$B:$B,Spelerslijst!$G:$G=B$2,"")} -> Bridget ter Horst | E4: {=_xlfn._xlws.FILTER(Spelerslijst!$L:$L,Spelerslijst!$Q:$Q=B$2,"")} -> Bart Driesprong | I4: {=_xlfn._xlws.FILTER(Spelerslijst!$B:$B,Spelerslijst!$G:$G=I$2,"")} -> Angela Friebel | L4: {=_xlfn._xlws.FILTER(Spelerslijst!$L:$L,Spelerslijst!$Q:$Q=I$2,"")} -> Cas Tieleman | P4: {=_xlfn._xlws.FILTER(Spelerslijst!$B:$B,Spelerslijst!$G:$G=P$2,"")} | S4: {=_xlfn._xlws.FILTER(Spelerslijst!$L:$L,Spelerslijst!$Q:$Q=P$2,"")} | W4: {=_xlfn._xlws.FILTER(Spelerslijst!$B:$B,Spelerslijst!$G:$G=W$2,"")} | Z4: {=_xlfn._xlws.FILTER(Spelerslijst!$L:$L,Spelerslijst!$Q:$Q=W$2,"")}
B5: Demi van Dijk | E5: Bob Mans | I5: Carlijn Lievaart | L5: Ché Kooper
B6: Djuna Seevinck | E6: Daniel den Uijl | I6: Jany Lacroes | L6: David Kuijper
B7: Eva Teerds | E7: Jaimy van Arkel | I7: Jennifer Herremans | L7: Jens de Vlaming
B8: Kim Dommisse | E8: Joeri van Dijk | I8: Kimberley Witman | L8: Luuk Baars
B9: Loïs Fernhout | E9: Jordan Timmer | I9: Lara Schram | L9: Quinten van Driel
B10: Milou Oppe | E10: Marijn Klink | I10: Sanne Dubbeld | L10: Ruben Dubbeld
B11: Renske Visser | E11: Olivier Klink | I11: Tessa Dubbeld | L11: Thijs Boon
B12: Robin Dommisse | E12: Robin van Kalkeren | L12: Tijmen Fasbender
B13: Vera Klootwijk | E13: Stefan Naaktgeboren
B14: Xanne Klink | E14: Tim van Gent
B17: {=_xlfn._xlws.FILTER(Staf!$C:$C,Staf!$B:$B='Teams-deelversie'!B2,"")} -> Analist S1 | C17: {=_xlfn._xlws.FILTER(Staf!$A:$A,Staf!$B:$B='Teams-deelversie'!B2,"")} -> Joris van den Neucker | I17: {=_xlfn._xlws.FILTER(Staf!$C:$C,Staf!$B:$B='Teams-deelversie'!I2,"")} -> Trainer/Coach S5 | J17: {=_xlfn._xlws.FILTER(Staf!$A:$A,Staf!$B:$B='Teams-deelversie'!I2,"")} -> Robin Dommisse | P17: {=_xlfn._xlws.FILTER(Staf!$C:$C,Staf!$B:$B='Teams-deelversie'!P2,"")} -> Trainer/Coach A1 | Q17: {=_xlfn._xlws.FILTER(Staf!$A:$A,Staf!$B:$B='Teams-deelversie'!P2,"")} -> Rob van Dongen | W17: {=_xlfn._xlws.FILTER(Staf!$C:$C,Staf!$B:$B='Teams-deelversie'!W2,"")} | X17: {=_xlfn._xlws.FILTER(Staf!$A:$A,Staf!$B:$B='Teams-deelversie'!W2,"")}
B18: Teambegeleider S1 | C18: Dionne Broere
B19: Teambegeleider S2 | C19: Sandra Kerklaan
B20: Fysio | C20: Ruben Kamerbeek
B21: Verzorger | C21: Theo Anrochte
B22: Coach S2 | C22: Arthyn Muller
B23: Coach S2 | C23: Jeroen de Kruif
B24: Coach S1 | C24: Bo van Hoof
A26: Senioren | B26: S1 | I26: S2 | P26: S3 | W26: S4 | AD26: S5 | AK26: S6 | AR26: S7 | AY26: MW1
B27: Dames | E27: Heren | I27: Dames | L27: Heren | P27: Dames | S27: Heren | W27: Dames | Z27: Heren | AD27: Dames | AG27: Heren | AK27: Dames | AN27: Heren | AR27: Dames | AU27: Heren | AY27: Dames | BB27: Heren
B28: {=_xlfn._xlws.FILTER(Spelerslijst!$B:$B,Spelerslijst!$G:$G=B$26,"")} | C28: {=_xlfn._xlws.FILTER(Spelerslijst!$H:$H,Spelerslijst!$G:$G=B$26,"")} | D28: {=_xlfn._xlws.FILTER(Spelerslijst!$D:$D,Spelerslijst!$G:$G=B$26,"")} | E28: {=_xlfn._xlws.FILTER(Spelerslijst!$L:$L,Spelerslijst!$Q:$Q=B$26,"")} | F28: {=_xlfn._xlws.FILTER(Spelerslijst!$R:$R,Spelerslijst!$Q:$Q=B$26,"")} | G28: {=_xlfn._xlws.FILTER(Spelerslijst!$N:$N,Spelerslijst!$Q:$Q=B$26,"")} | I28: {=_xlfn._xlws.FILTER(Spelerslijst!$B:$B,Spelerslijst!$G:$G=I$26,"")} | J28: {=_xlfn._xlws.FILTER(Spelerslijst!$H:$H,Spelerslijst!$G:$G=I$26,"")} | K28: {=_xlfn._xlws.FILTER(Spelerslijst!$D:$D,Spelerslijst!$G:$G=I$26,"")} | L28: {=_xlfn._xlws.FILTER(Spelerslijst!$L:$L,Spelerslijst!$Q:$Q=I$26,"")} | M28: {=_xlfn._xlws.FILTER(Spelerslijst!$R:$R,Spelerslijst!$Q:$Q=I$26,"")} | N28: {=_xlfn._xlws.FILTER(Spelerslijst!$N:$N,Spelerslijst!$Q:$Q=I$26,"")} | P28: {=_xlfn._xlws.FILTER(Spelerslijst!$B:$B,Spelerslijst!$G:$G=P$26,"")} -> Esther Ardon | S28: {=_xlfn._xlws.FILTER(Spelerslijst!$L:$L,Spelerslijst!$Q:$Q=P$26,"")} -> Emiel Houwerzijl | W28: {=_xlfn._xlws.FILTER(Spelerslijst!$B:$B,Spelerslijst!$G:$G=W$26,"")} -> Barbara Camphens-Moerman | Z28: {=_xlfn._xlws.FILTER(Spelerslijst!$L:$L,Spelerslijst!$Q:$Q=W$26,"")} -> Antjan Laban | AD28: {=_xlfn._xlws.FILTER(Spelerslijst!$B:$B,Spelerslijst!$G:$G=AD$26,"")} | AE28: {=_xlfn._xlws.FILTER(Spelerslijst!$H:$H,Spelerslijst!$G:$G=AD$26,"")} | AF28: {=_xlfn._xlws.FILTER(Spelerslijst!$D:$D,Spelerslijst!$G:$G=AD$26,"")} | AG28: {=_xlfn._xlws.FILTER(Spelerslijst!$L:$L,Spelerslijst!$Q:$Q=AD$26,"")} | AH28: {=_xlfn._xlws.FILTER(Spelerslijst!$R:$R,Spelerslijst!$Q:$Q=AD$26,"")} | AI28: {=_xlfn._xlws.FILTER(Spelerslijst!$N:$N,Spelerslijst!$Q:$Q=AD$26,"")} | AK28: {=_xlfn._xlws.FILTER(Spelerslijst!$B:$B,Spelerslijst!$G:$G=AK$26,"")} | AL28: {=_xlfn._xlws.FILTER(Spelerslijst!$H:$H,Spelerslijst!$G:$G=AK$26,"")} | AM28: {=_xlfn._xlws.FILTER(Spelerslijst!$D:$D,Spelerslijst!$G:$G=AK$26,"")} | AN28: {=_xlfn._xlws.FILTER(Spelerslijst!$L:$L,Spelerslijst!$Q:$Q=AK$26,"")} | AO28: {=_xlfn._xlws.FILTER(Spelerslijst!$R:$R,Spelerslijst!$Q:$Q=AK$26,"")} | AP28: {=_xlfn._xlws.FILTER(Spelerslijst!$N:$N,Spelerslijst!$Q:$Q=AK$26,"")} | AR28: {=_xlfn._xlws.FILTER(Spelerslijst!$B:$B,Spelerslijst!$G:$G=AR$26,"")} -> Anniek Pierse | AU28: {=_xlfn._xlws.FILTER(Spelerslijst!$L:$L,Spelerslijst!$Q:$Q=AR$26,"")} -> Joram Flach | AY28: {=_xlfn._xlws.FILTER(Spelerslijst!$B:$B,Spelerslijst!$G:$G=AY$26,"")} -> Dorien in 't Veld | BB28: {=_xlfn._xlws.FILTER(Spelerslijst!$L:$L,Spelerslijst!$Q:$Q=AY$26,"")} -> Hans Ploeg
P29: Hanneke Batenburg | S29: Jan Booy | W29: Diana Visser-Michelsen | Z29: Arjan Noels | AR29: Laura Koote | AU29: Mark Schindler | AY29: Kim Heesterbeek | BB29: Michiel 't Jong
P30: Linda Ardon | S30: Lex van Gent | W30: Esther Wibbens | Z30: Bart de Wit | AR30: Marlies Valk | AU30: Rick van de Wijgaart | AY30: Kim Scheurwater | BB30: Peter Batenburg
P31: Merel van Gurp | S31: Roy de Vlaming | W31: Lieke Ploeg | Z31: Bas de Jong | AR31: Nadia de Wit | AY31: Liesbeth Brand | BB31: Ronald Riet
P32: Nada Hussein | S32: Thomas Isarin | W32: Petra Verheijde | Z32: Steven Kuperus | AR32: Syrah de Wit | AY32: Mirjam de Wit | BB32: Sebastiaan Belder
P33: Robin Leijdsman | AY33: Sanne van Andel | BB33: Wilco Kooij
P34: Simone van Zwoll | AY34: Tamara van Opstal-Haksteen
B36: {=_xlfn._xlws.FILTER(Staf!$C:$C,Staf!$B:$B='Teams-deelversie'!B26,"")} | C36: {=_xlfn._xlws.FILTER(Staf!$A:$A,Staf!$B:$B='Teams-deelversie'!B26,"")} | I36: {=_xlfn._xlws.FILTER(Staf!$C:$C,Staf!$B:$B='Teams-deelversie'!I26,"")} | J36: {=_xlfn._xlws.FILTER(Staf!$A:$A,Staf!$B:$B='Teams-deelversie'!I26,"")} | P36: {=_xlfn._xlws.FILTER(Staf!$C:$C,Staf!$B:$B='Teams-deelversie'!P26,"")} -> Begeleider | Q36: {=_xlfn._xlws.FILTER(Staf!$A:$A,Staf!$B:$B='Teams-deelversie'!P26,"")} -> Kim Ardon | W36: {=_xlfn._xlws.FILTER(Staf!$C:$C,Staf!$B:$B='Teams-deelversie'!W26,"")} -> Thuiscoach | X36: {=_xlfn._xlws.FILTER(Staf!$A:$A,Staf!$B:$B='Teams-deelversie'!W26,"")} -> Marco van Kalkeren | AD36: {=_xlfn._xlws.FILTER(Staf!$C:$C,Staf!$B:$B='Teams-deelversie'!AD26,"")} | AE36: {=_xlfn._xlws.FILTER(Staf!$A:$A,Staf!$B:$B='Teams-deelversie'!AD26,"")} | AK36: {=_xlfn._xlws.FILTER(Staf!$C:$C,Staf!$B:$B='Teams-deelversie'!AK26,"")} | AL36: {=_xlfn._xlws.FILTER(Staf!$A:$A,Staf!$B:$B='Teams-deelversie'!AK26,"")} | AO36: web | AR36: {=_xlfn._xlws.FILTER(Staf!$C:$C,Staf!$B:$B='Teams-deelversie'!AR26,"")} | AS36: {=_xlfn._xlws.FILTER(Staf!$A:$A,Staf!$B:$B='Teams-deelversie'!AR26,"")} | AY36: {=_xlfn._xlws.FILTER(Staf!$C:$C,Staf!$B:$B='Teams-deelversie'!AY26,"")} | AZ36: {=_xlfn._xlws.FILTER(Staf!$A:$A,Staf!$B:$B='Teams-deelversie'!AY26,"")}
A39: A-Junioren | B39: A1 | I39: A2 | P39: A3 | W39: A4 | AD39: A5
B40: Dames | E40: Heren | I40: Dames | L40: Heren | P40: Dames | S40: Heren | W40: Dames | Z40: Heren | AD40: Dames | AG40: Heren
B41: {=_xlfn._xlws.FILTER(Spelerslijst!$B:$B,Spelerslijst!$G:$G=B$39,"")} -> Amber de Haas | C41: {=_xlfn._xlws.FILTER(Spelerslijst!$H:$H,Spelerslijst!$G:$G=B$39,"")} -> B1 | D41: {=_xlfn._xlws.FILTER(Spelerslijst!$D:$D,Spelerslijst!$G:$G=B$39,"")} -> 16 | E41: {=_xlfn._xlws.FILTER(Spelerslijst!$L:$L,Spelerslijst!$Q:$Q=B$39,"")} -> Jack Zwanenburg | F41: {=_xlfn._xlws.FILTER(Spelerslijst!$R:$R,Spelerslijst!$Q:$Q=B$39,"")} -> B1 | G41: {=_xlfn._xlws.FILTER(Spelerslijst!$N:$N,Spelerslijst!$Q:$Q=B$39,"")} -> 16 | I41: {=_xlfn._xlws.FILTER(Spelerslijst!$B:$B,Spelerslijst!$G:$G=I$39,"")} -> Anouk de Jongh | J41: {=_xlfn._xlws.FILTER(Spelerslijst!$H:$H,Spelerslijst!$G:$G=I$39,"")} -> A2 | K41: {=_xlfn._xlws.FILTER(Spelerslijst!$D:$D,Spelerslijst!$G:$G=I$39,"")} -> 18 | L41: {=_xlfn._xlws.FILTER(Spelerslijst!$L:$L,Spelerslijst!$Q:$Q=I$39,"")} -> Freek van Dongen | M41: {=_xlfn._xlws.FILTER(Spelerslijst!$R:$R,Spelerslijst!$Q:$Q=I$39,"")} -> B2 | N41: {=_xlfn._xlws.FILTER(Spelerslijst!$N:$N,Spelerslijst!$Q:$Q=I$39,"")} -> 16 | P41: {=_xlfn._xlws.FILTER(Spelerslijst!$B:$B,Spelerslijst!$G:$G=P$39,"")} -> Amber Boeije | S41: {=_xlfn._xlws.FILTER(Spelerslijst!$L:$L,Spelerslijst!$Q:$Q=P$39,"")} -> Laurens Verhagen | W41: {=_xlfn._xlws.FILTER(Spelerslijst!$B:$B,Spelerslijst!$G:$G=W$39,"")} | X41: {=_xlfn._xlws.FILTER(Spelerslijst!$H:$H,Spelerslijst!$G:$G=W$39,"")} | Y41: {=_xlfn._xlws.FILTER(Spelerslijst!$D:$D,Spelerslijst!$G:$G=W$39,"")} | Z41: {=_xlfn._xlws.FILTER(Spelerslijst!$L:$L,Spelerslijst!$Q:$Q=W$39,"")} | AA41: {=_xlfn._xlws.FILTER(Spelerslijst!$R:$R,Spelerslijst!$Q:$Q=W$39,"")} | AB41: {=_xlfn._xlws.FILTER(Spelerslijst!$N:$N,Spelerslijst!$Q:$Q=W$39,"")} | AD41: {=_xlfn._xlws.FILTER(Spelerslijst!$B:$B,Spelerslijst!$G:$G=AD$39,"")} | AE41: {=_xlfn._xlws.FILTER(Spelerslijst!$H:$H,Spelerslijst!$G:$G=AD$39,"")} | AF41: {=_xlfn._xlws.FILTER(Spelerslijst!$D:$D,Spelerslijst!$G:$G=AD$39,"")} | AG41: {=_xlfn._xlws.FILTER(Spelerslijst!$L:$L,Spelerslijst!$Q:$Q=AD$39,"")} | AH41: {=_xlfn._xlws.FILTER(Spelerslijst!$R:$R,Spelerslijst!$Q:$Q=AD$39,"")} | AI41: {=_xlfn._xlws.FILTER(Spelerslijst!$N:$N,Spelerslijst!$Q:$Q=AD$39,"")}
B42: Iza Wolleswinkel | C42: B1 | D42: 16 | E42: Jarno Valk | F42: B1 | G42: 16 | I42: Elena Quarré | J42: A2 | K42: 18 | L42: Joël Wietses | M42: A2 | N42: 18 | P42: Bente van Wijngaarden | S42: Matthijs de Jongh
B43: Merel Manduapessy | C43: B1 | D43: 16 | E43: Jens Lohuis | F43: A1 | G43: 18 | I43: Lindi Fasbender | J43: A2 | K43: 18 | L43: Seth van de Burgt | M43: B2 | N43: 17 | P43: Flore Steenks | S43: Menno Pille
B44: Roos Groeneweg | C44: A1 | D44: 18 | E44: Jordi Vaartmans | F44: B1 | G44: 17 | I44: Maud van Wensen | J44: A1 | K44: 18 | L44: Tijn Bäcker | M44: B1 | N44: 16 | P44: Julia Bozuwa | S44: Tommie Koornneef
B45: Sara Boshoven | C45: A1 | D45: 18 | E45: Senne Koster | F45: A1 | G45: 18 | I45: Mila de Wit | J45: B2 | K45: 16 | L45: Wouter Koornneef | M45: A2 | N45: 18 | P45: Lianne Bouwknegt
P46: Tessa van Everdingen
P47: Vivienne Versnel
...

Sheet Stoppers
A1: Rel.nr | B1: Naam & Initialen) | C1: Roepnaam | D1: Leeftijd Peildatum | E1: Geb datum | F1: Team op Peildatum | G1: Team 20-21 | I1: Rel.nr | J1: Naam & Initialen) | K1: Roepnaam | L1: Leeftijd Peildatum | M1: Geb datum | N1: Team op Peildatum | O1: Team 20-21
A2: {=_xlfn._xlws.FILTER(Spelerslijst!A:A,Spelerslijst!$G:$G="Stopt","")} -> NLY40X3 | B2: {=_xlfn._xlws.FILTER(Spelerslijst!B:B,Spelerslijst!$G:$G="Stopt","")} -> Anjanette Matena | C2: {=_xlfn._xlws.FILTER(Spelerslijst!C:C,Spelerslijst!$G:$G="Stopt","")} -> Anjanette | D2: {=_xlfn._xlws.FILTER(Spelerslijst!D:D,Spelerslijst!$G:$G="Stopt","")} -> 14 | E2: {=_xlfn._xlws.FILTER(Spelerslijst!E:E,Spelerslijst!$G:$G="Stopt","")} -> 39961 | F2: {=_xlfn._xlws.FILTER(Spelerslijst!F:F,Spelerslijst!$G:$G="Stopt","")} -> B | G2: {=_xlfn._xlws.FILTER(Spelerslijst!G:G,Spelerslijst!$G:$G="Stopt","")} -> Stopt | I2: {=_xlfn._xlws.FILTER(Spelerslijst!K:K,Spelerslijst!$Q:$Q="Stopt","")} -> NLB70Y2 | J2: {=_xlfn._xlws.FILTER(Spelerslijst!L:L,Spelerslijst!$Q:$Q="Stopt","")} -> Joeke Meijer | K2: {=_xlfn._xlws.FILTER(Spelerslijst!M:M,Spelerslijst!$Q:$Q="Stopt","")} -> Joeke | L2: {=_xlfn._xlws.FILTER(Spelerslijst!N:N,Spelerslijst!$Q:$Q="Stopt","")} -> 18 | M2: {=_xlfn._xlws.FILTER(Spelerslijst!O:O,Spelerslijst!$Q:$Q="Stopt","")} -> 38617 | N2: {=_xlfn._xlws.FILTER(Spelerslijst!P:P,Spelerslijst!$Q:$Q="Stopt","")} -> A | O2: {=_xlfn._xlws.FILTER(Spelerslijst!Q:Q,Spelerslijst!$Q:$Q="Stopt","")} -> Stopt
A3: NLC07S7 | B3: Anna Everaarts | C3: Anna | D3: 15 | E3: 39589 | F3: B | G3: Stopt | I3: NMJ09L8 | J3: Abdi Ibrahim | K3: Abdi | L3: 16 | M3: 39402 | N3: A | O3: Stopt
A4: NMH36F0 | B4: Anouk Vreeling | C4: Anouk | D4: 16 | E4: 39427 | F4: A | G4: Stopt | I4: NKH56N2 | J4: Alexander Wolff | K4: Alexander | L4: 27 | M4: 35231 | N4: S | O4: Stopt
A5: NLM86V5 | B5: Britt Vaartmans | C5: Britt | D5: 12 | E5: 40561 | F5: C | G5: Stopt | I5: NLW47J4 | J5: Ali Hashmei | K5: Ali | L5: 16 | M5: 39402 | N5: A | O5: Stopt
A6: NMN14W9 | B6: Carlijn van den Broek | C6: Carlijn | D6: 15 | E6: 39702 | F6: B | G6: Stopt | I6: NJD52B5 | J6: Bas Willemsteijn | K6: Bas | L6: 29 | M6: 34435 | N6: S | O6: Stopt
A7: NKC46R0 | B7: Dionne Broere | C7: Dionne | D7: 24 | E7: 36460 | F7: S | G7: Stopt | I7: NLJ47N9 | J7: Chris IJben | K7: Chris | L7: 18 | M7: 38519 | N7: A | O7: Stopt
A8: NMM29Q6 | B8: Elin Vogelaar | C8: Elin | D8: 6 | E8: 43083 | F8: F | G8: Stopt | I8: NFW26Q8 | J8: Egbert Vos | K8: Egbert | L8: 42 | M8: 29725 | N8: S | O8: Stopt
A9: NLS08K0 | B9: Hanna Oomens | C9: Hanna | D9: 15 | E9: 39635 | F9: B | G9: Stopt | I9: NLL19X2 | J9: Evan Altena | K9: Evan | L9: 16 | M9: 39100 | N9: A | O9: Stopt
A10: NKB62K8 | B10: Hulsker, N.M. | C10: Nina | D10: 24 | E10: 36385 | F10: S | G10: Stopt | I10: NFW14Y3 | J10: Jan-Peter Verwaal | K10: Jan-Peter | L10: 54 | M10: 25273 | N10: S | O10: Stopt
A11: NKW52X5 | B11: Jana Driesprong | C11: Jana | D11: 16 | E11: 39205 | F11: A | G11: Stopt | I11: NLJ97M7 | J11: Jesper Felix | K11: Jesper | L11: 16 | M11: 39420 | N11: A | O11: Stopt
A12: NKL60P7 | B12: Kim de Reus | C12: Kim | D12: 19 | E12: 38159 | F12: S | G12: Stopt | I12: NLC07T4 | J12: Jesse Everaarts | K12: Jesse | L12: 19 | M12: 38346 | N12: S | O12: Stopt
A13: NKK48D6 | B13: Laura Mol | C13: Laura | D13: 19 | E13: 38079 | F13: S | G13: Stopt | I13: NFW13Y0 | J13: Marco van Kalkeren | K13: Marco | L13: 54 | M13: 25227 | N13: S | O13: Stopt
A14: NLD26P4 | B14: Lisa Taal | C14: Lisa | D14: 20 | E14: 37931 | F14: S | G14: Stopt | I14: NKW50D9 | J14: Mathijs Lange | K14: Mathijs | L14: 19 | M14: 38169 | N14: S | O14: Stopt
... A20: NMM99N0 | B20: Sofie Faber | C20: Sofie | D20: 9 | E20: 41761 | F20: E | G20: Stopt | I20: NKR20M2 | J20: Tim Seevinck | K20: Tim | L20: 20 | M20: 37932 | N20: S | O20: Stopt
A21: NLX08D6 | B21: Sterre Reijerkerk | C21: Sterre | D21: 14 | E21: 39861 | F21: B | G21: Stopt
A22: NKS24M5 | B22: Yente Verbeek | C22: Yente | D22: 19 | E22: 38012 | F22: S | G22: stopt

Sheet vraagtekens
A1: Rel.nr | B1: Naam & Initialen) | C1: Roepnaam | D1: Leeftijd Peildatum | E1: Geb datum | F1: Team op Peildatum | G1: Team 20-21 | I1: Rel.nr | J1: Naam & Initialen) | K1: Roepnaam | L1: Leeftijd Peildatum | M1: Geb datum | N1: Team op Peildatum | O1: Team 20-21
A2: {=_xlfn._xlws.FILTER(Spelerslijst!A:A,Spelerslijst!$G:$G="?","")} | B2: {=_xlfn._xlws.FILTER(Spelerslijst!B:B,Spelerslijst!$G:$G="?","")} | C2: {=_xlfn._xlws.FILTER(Spelerslijst!C:C,Spelerslijst!$G:$G="?","")} | D2: {=_xlfn._xlws.FILTER(Spelerslijst!D:D,Spelerslijst!$G:$G="?","")} | E2: {=_xlfn._xlws.FILTER(Spelerslijst!E:E,Spelerslijst!$G:$G="?","")} | F2: {=_xlfn._xlws.FILTER(Spelerslijst!F:F,Spelerslijst!$G:$G="?","")} | G2: {=_xlfn._xlws.FILTER(Spelerslijst!G:G,Spelerslijst!$G:$G="?","")} | I2: {=_xlfn._xlws.FILTER(Spelerslijst!K:K,Spelerslijst!$Q:$Q="?","")} | J2: {=_xlfn._xlws.FILTER(Spelerslijst!L:L,Spelerslijst!$Q:$Q="?","")} | K2: {=_xlfn._xlws.FILTER(Spelerslijst!M:M,Spelerslijst!$Q:$Q="?","")} | L2: {=_xlfn._xlws.FILTER(Spelerslijst!N:N,Spelerslijst!$Q:$Q="?","")} | M2: {=_xlfn._xlws.FILTER(Spelerslijst!O:O,Spelerslijst!$Q:$Q="?","")} | N2: {=_xlfn._xlws.FILTER(Spelerslijst!P:P,Spelerslijst!$Q:$Q="?","")} | O2: {=_xlfn._xlws.FILTER(Spelerslijst!Q:Q,Spelerslijst!$Q:$Q="?","")}

Sheet streepjes

Sheet check bond 280623
A1: Check V | B1: Check M | C1: Check | D1: Relatiecode | E1: Volledige naam (2) | F1: Roepnaam | G1: Geboortedatum | H1: Geslacht | I1: E-mail | J1: Status | K1: Lidmaatschapcode | L1: Bondssporten | M1: Verenigingssporten | N1: Lid sinds
A2: =_xlfn.IFNA(VLOOKUP(D2,Spelerslijst!A:B,1,FALSE),FALSE) -> FALSE | B2: =_xlfn.IFNA(VLOOKUP(D2,Spelerslijst!K:L,1,FALSE),FALSE) -> NJC26C8 | C2: =IF(AND(A2=FALSE,B2=FALSE),"Onbekend","") | D2: NJC26C8 | E2: Emiel Houwerzijl | F2: Emiel | G2: 34464 | H2: M | I2: emielhouwerzijl@hotmail.com | J2: definitief | K2: 200 | L2: Veld - Week, Zaal - Week | M2: Korfbal - Korfbal - Week | N2: 44746
A3: =_xlfn.IFNA(VLOOKUP(D3,Spelerslijst!A:B,1,FALSE),FALSE) -> FALSE | B3: =_xlfn.IFNA(VLOOKUP(D3,Spelerslijst!K:L,1,FALSE),FALSE) -> NKN65B6 | C3: =IF(AND(A3=FALSE,B3=FALSE),"Onbekend","") | D3: NKN65B6 | E3: Luuk Baars | F3: Luuk | G3: 36929 | H3: M | I3: luukbaars2001@gmail.com | J3: definitief | K3: 200 | L3: Veld - Week, Zaal - Week | M3: Korfbal - Korfbal - Week | N3: 40087
A4: =_xlfn.IFNA(VLOOKUP(D4,Spelerslijst!A:B,1,FALSE),FALSE) -> NMM29Q6 | B4: =_xlfn.IFNA(VLOOKUP(D4,Spelerslijst!K:L,1,FALSE),FALSE) -> FALSE | C4: =IF(AND(A4=FALSE,B4=FALSE),"Onbekend","") | D4: NMM29Q6 | E4: Elin Vogelaar | F4: Elin | G4: 43083 | H4: V | I4: maritteisarin@gmail.com | J4: af te melden | K4: 240 | M4: Korfbal - Korfbal - Week | N4: 44326
A5: =_xlfn.IFNA(VLOOKUP(D5,Spelerslijst!A:B,1,FALSE),FALSE) -> NMS09V7 | B5: =_xlfn.IFNA(VLOOKUP(D5,Spelerslijst!K:L,1,FALSE),FALSE) -> FALSE | C5: =IF(AND(A5=FALSE,B5=FALSE),"Onbekend","") | D5: NMS09V7 | E5: Julia van Twist | F5: Julia | G5: 42234 | H5: V | I5: rmvantwist@hotmail.com | J5: definitief | K5: 230 | L5: Veld - Week, Zaal - Week | M5: Korfbal - Korfbal - Week | N5: 44817
A6: =_xlfn.IFNA(VLOOKUP(D6,Spelerslijst!A:B,1,FALSE),FALSE) -> NLB70X5 | B6: =_xlfn.IFNA(VLOOKUP(D6,Spelerslijst!K:L,1,FALSE),FALSE) -> FALSE | C6: =IF(AND(A6=FALSE,B6=FALSE),"Onbekend","") | D6: NLB70X5 | E6: Angela Friebel | F6: Angela | G6: 37541 | H6: V | I6: angelafriebel02@gmail.com | J6: definitief | K6: 200 | L6: Veld - Week, Zaal - Week | M6: Korfbal - Korfbal - Week | N6: 41153
A7: =_xlfn.IFNA(VLOOKUP(D7,Spelerslijst!A:B,1,FALSE),FALSE) -> NKB62K8 | B7: =_xlfn.IFNA(VLOOKUP(D7,Spelerslijst!K:L,1,FALSE),FALSE) -> FALSE | C7: =IF(AND(A7=FALSE,B7=FALSE),"Onbekend","") | D7: NKB62K8 | E7: Nina Hulsker | F7: Nina | G7: 36385 | H7: V | I7: ninahulsker@hotmail.com | J7: af te melden | K7: 200 | L7: Veld - Week, Zaal - Week | M7: Korfbal - Korfbal - Week | N7: 39296
A8: =_xlfn.IFNA(VLOOKUP(D8,Spelerslijst!A:B,1,FALSE),FALSE) -> NML00R5 | B8: =_xlfn.IFNA(VLOOKUP(D8,Spelerslijst!K:L,1,FALSE),FALSE) -> FALSE | C8: =IF(AND(A8=FALSE,B8=FALSE),"Onbekend","") | D8: NML00R5 | E8: Bryanna Bos | F8: Bryanna | G8: 40373 | H8: V | I8: luthiendenheeten@gmail.com | J8: definitief | K8: 220 | L8: Veld - Week, Zaal - Week | M8: Korfbal - Korfbal - Week | N8: 44099
