Workbook

Sheet Teams
A2: Selecties | B2: S1S2 | G2: =AVERAGE(D4:D24,G4:G24) -> 22.458333 | I2: A1A2 | N2: =AVERAGE(K4:K24,N4:N24) -> 16.47619 | P2: B1B2 | U2: =AVERAGE(R4:R24,U4:U24) -> 14.5 | W2: S5S6 | AB2: =AVERAGE(Y4:Y24,AB4:AB24) -> #DIV/0!
B3: =CONCATENATE("Dames (",COUNTA(C4:C19),")") -> Dames (12) | E3: =CONCATENATE("Heren (",COUNTA(F4:F19),")") -> Heren (12) | I3: =CONCATENATE("Dames (",COUNTA(J4:J19),")") -> Dames (9) | L3: =CONCATENATE("Heren (",COUNTA(M4:M19),")") -> Heren (12) | P3: =CONCATENATE("Dames (",COUNTA(Q4:Q19),")") -> Dames (9) | S3: =CONCATENATE("Heren (",COUNTA(T4:T19),")") -> Heren (9) | W3: =CONCATENATE("Dames (",COUNTA(X4:X19),")") -> Dames (1) | Z3: =CONCATENATE("Heren (",COUNTA(AA4:AA19),")") -> Heren (1)
B4: {=_xlfn._xlws.FILTER(Spelerslijst!$B:$B,Spelerslijst!$G:$G=B$2,"")} -> Demi van Dijk | C4: {=_xlfn._xlws.FILTER(Spelerslijst!$H:$H,Spelerslijst!$G:$G=B$2,"")} -> S2 | D4: {=_xlfn._xlws.FILTER(Spelerslijst!$D:$D,Spelerslijst!$G:$G=B$2,"")} -> 23 | E4: {=_xlfn._xlws.FILTER(Spelerslijst!$L:$L,Spelerslijst!$Q:$Q=B$2,"")} -> Bart Driesprong | F4: {=_xlfn._xlws.FILTER(Spelerslijst!$R:$R,Spelerslijst!$Q:$Q=B$2,"")} -> S1 | G4: {=_xlfn._xlws.FILTER(Spelerslijst!$N:$N,Spelerslijst!$Q:$Q=B$2,"")} -> 26 | I4: {=_xlfn._xlws.FILTER(Spelerslijst!$B:$B,Spelerslijst!$G:$G=I$2,"")} -> Amber de Haas | J4: {=_xlfn._xlws.FILTER(Spelerslijst!$H:$H,Spelerslijst!$G:$G=I$2,"")} -> A1 | K4: {=_xlfn._xlws.FILTER(Spelerslijst!$D:$D,Spelerslijst!$G:$G=I$2,"")} -> 17 | L4: {=_xlfn._xlws.FILTER(Spelerslijst!$L:$L,Spelerslijst!$Q:$Q=I$2,"")} -> Dani Heersping | M4: {=_xlfn._xlws.FILTER(Spelerslijst!$R:$R,Spelerslijst!$Q:$Q=I$2,"")} -> B2 | N4: {=_xlfn._xlws.FILTER(Spelerslijst!$N:$N,Spelerslijst!$Q:$Q=I$2,"")} -> 16 | P4: {=_xlfn._xlws.FILTER(Spelerslijst!$B:$B,Spelerslijst!$G:$G=P$2,"")} -> Danique van der Klooster | Q4: {=_xlfn._xlws.FILTER(Spelerslijst!$H:$H,Spelerslijst!$G:$G=P$2,"")} -> C1 | R4: {=_xlfn._xlws.FILTER(Spelerslijst!$D:$D,Spelerslijst!$G:$G=P$2,"")} -> 14 | S4: {=_xlfn._xlws.FILTER(Spelerslijst!$L:$L,Spelerslijst!$Q:$Q=P$2,"")} -> Diederik Hovestadt | T4: {=_xlfn._xlws.FILTER(Spelerslijst!$R:$R,Spelerslijst!$Q:$Q=P$2,"")} -> C2 | U4: {=_xlfn._xlws.FILTER(Spelerslijst!$N:$N,Spelerslijst!$Q:$Q=P$2,"")} -> 15 | W4: {=_xlfn._xlws.FILTER(Spelerslijst!$B:$B,Spelerslijst!$G:$G=W$2,"")} | X4: {=_xlfn._xlws.FILTER(Spelerslijst!$H:$H,Spelerslijst!$G:$G=W$2,"")} | Y4: {=_xlfn._xlws.FILTER(Spelerslijst!$D:$D,Spelerslijst!$G:$G=W$2,"")} | Z4: {=_xlfn._xlws.FILTER(Spelerslijst!$L:$L,Spelerslijst!$Q:$Q=W$2,"")} | AA4: {=_xlfn._xlws.FILTER(Spelerslijst!$R:$R,Spelerslijst!$Q:$Q=W$2,"")} | AB4: {=_xlfn._xlws.FILTER(Spelerslijst!$N:$N,Spelerslijst!$Q:$Q=W$2,"")}
B5: Eva Teerds | C5: S2 | D5: 22 | E5: Bob Mans | F5: S2 | G5: 28 | I5: Benthe van der Linden | J5: B2 | K5: 16 | L5: Freek van Dongen | M5: A2 | N5: 17 | P5: Demi Engelfriet | Q5: C1 | R5: 14 | S5: Jarno Bemer | T5: B2 | U5: 15
B6: Iza Wolleswinkel | C6: A1 | D6: 17 | E6: Daniel den Uijl | F6: S2 | G6: 21 | I6: Carmen van der Klooster | J6: B1 | K6: 16 | L6: Jack Zwanenburg | M6: A1 | N6: 17 | P6: Demi Lindhout | Q6: C1 | R6: 14 | S6: Jasper Sempel | T6: B2 | U6: 15
B7: Lindi Fasbender | C7: A2 | D7: 19 | E7: Jens Lohuis | F7: A1 | G7: 19 | I7: Doeska Voorbij | J7: B1 | K7: 16 | L7: Jarno Valk | M7: A1 | N7: 17 | P7: Feline van de Burgt | Q7: C2 | R7: 14 | S7: Jonas van de Ven | T7: C2 | U7: 14
B8: Loïs Fernhout | C8: S1 | D8: 21 | E8: Joël Wietses | F8: A2 | G8: 19 | I8: Elize van de Burgt | J8: B2 | K8: 16 | L8: Jordi Vaartmans | M8: A1 | N8: 18 | P8: Floor Lohuis | Q8: B2 | R8: 15 | S8: Kian Vliet | T8: B2 | U8: 15
B9: Maud van Wensen | C9: A2 | D9: 19 | E9: Joeri van Dijk | F9: S1 | G9: 26 | I9: Lisa Reuvers | J9: B1 | K9: 15 | L9: Lars Visser | M9: B1 | N9: 16 | P9: Floortje Jongkind | Q9: B3 | R9: 14 | S9: Niek Sas | T9: C1 | U9: 14
B10: Meike Driesprong | C10: S1 | D10: 20 | E10: Jordan Timmer | F10: S2 | G10: 20 | I10: Merel Manduapessy | J10: A1 | K10: 17 | L10: Maarten Sas | M10: B1 | N10: 16 | P10: Githa Bemer | Q10: B2 | R10: 15 | S10: Onno den Dekker | T10: B1 | U10: 16
B11: Milou Oppe | C11: S1 | D11: 22 | E11: Marijn Klink | F11: S2 | G11: 27 | I11: Sophie Kilsdonk | J11: B1 | K11: 16 | L11: Niek Driesprong | M11: B1 | N11: 16 | P11: Julia Kleingeld | Q11: C1 | R11: 14 | S11: Thomas Vos | T11: C1 | U11: 14
B12: Robin Dommisse | C12: S2 | D12: 26 | E12: Olivier Klink | F12: AR | G12: 26 | I12: Stella Verboom | J12: B2 | K12: 16 | L12: Seth van de Burgt | M12: A2 | N12: 18 | P12: Noa Stomp | Q12: C1 | R12: 14 | S12: Timo Pichel | T12: B3 | U12: 15
B13: Roos Groeneweg | C13: A1 | D13: 19 | E13: Robin van Kalkeren | F13: S1 | G13: 28 | L13: Tijn Bäcker | M13: A2 | N13: 17
B14: Sara Boshoven | C14: A1 | D14: 19 | E14: Senne Koster | F14: A1 | G14: 19 | L14: Tijn Camphens | M14: B2 | N14: 16
B15: Xanne Klink | C15: S1 | D15: 29 | E15: Tim van Gent | F15: S1 | G15: 24 | L15: Tycho Vliet | M15: B2 | N15: 17
B20: {=_xlfn._xlws.FILTER(Staf!$C:$C,Staf!$B:$B=Teams!B2,"")} -> Trainer/Coach S1 | C20: {=_xlfn._xlws.FILTER(Staf!$A:$A,Staf!$B:$B=Teams!B2,"")} -> Bo van Hoof | I20: {=_xlfn._xlws.FILTER(Staf!$C:$C,Staf!$B:$B=Teams!I2,"")} -> Trainer/Coach A1 | J20: {=_xlfn._xlws.FILTER(Staf!$A:$A,Staf!$B:$B=Teams!I2,"")} -> Rob van Dongen | P20: {=_xlfn._xlws.FILTER(Staf!$C:$C,Staf!$B:$B=Teams!P2,"")} -> Trainer/Coach B1 | Q20: {=_xlfn._xlws.FILTER(Staf!$A:$A,Staf!$B:$B=Teams!P2,"")} -> Jasper Kleingeld | W20: {=_xlfn._xlws.FILTER(Staf!$C:$C,Staf!$B:$B=#REF!,"")} -> #REF! | X20: {=_xlfn._xlws.FILTER(Staf!$A:$A,Staf!$B:$B=#REF!,"")} -> #REF!
B21: Trainer/Coach S2 | C21: Arthyn Muller | I21: Trainer/Coach A1 | J21: Ruben Blokland | P21: Trainer/Coach B1 | Q21: Mees Oppe
B22: Teambegeleider S1 | C22: Dionne Broere | I22: Trainer/Coach A2 | J22: Olivier Klink | P22: Trainer/Coach B2 | Q22: Daniël den Uijl
B23: Teambegeleider S2 | C23: Fred Lichteveld | I23: Trainer/Coach A2 | J23: Tim van Gent | P23: Trainer/Coach B2 | Q23: Eva Teerds
B24: Analist S1 | C24: Joris van den Neucker | I24: Teambegeleider | J24: Alex van de Klooster | P24: Trainer/Coach B2 | Q24: Vacature
B25: Fysio | C25: Ruben Kamerbeek | P25: Teambegeleider | Q25: Michel Sas
B26: Verzorger | C26: Theo Anrochte
A29: Senioren | B29: S1 | G29: =AVERAGE(D31:D40,G31:G40) -> #DIV/0! | I29: S2 | N29: =AVERAGE(K31:K40,N31:N40) -> #DIV/0! | P29: S3 | U29: =AVERAGE(R31:R40,U31:U40) -> 32.818182 | W29: S4 | AB29: =AVERAGE(Y31:Y40,AB31:AB40) -> #N/A | AD29: S5 | AI29: =AVERAGE(AF31:AF40,AI31:AI40) -> 23 | AK29: S6 | AP29: =AVERAGE(AM31:AM40,AP31:AP40) -> 21.333333 | AR29: S7 | AW29: =AVERAGE(AT31:AT40,AW31:AW40) -> #DIV/0! | AY29: MW1 | BD29: =AVERAGE(BA31:BA40,BD31:BD40) -> 38.888889
B30: =CONCATENATE("Dames (",COUNTA(C31:C38),")") -> Dames (1) | E30: =CONCATENATE("Heren (",COUNTA(F31:F38),")") -> Heren (1) | I30: =CONCATENATE("Dames (",COUNTA(J31:J38),")") -> Dames (1) | L30: =CONCATENATE("Heren (",COUNTA(M31:M38),")") -> Heren (1) | P30: =CONCATENATE("Dames (",COUNTA(Q31:Q38),")") -> Dames (6) | S30: =CONCATENATE("Heren (",COUNTA(T31:T38),")") -> Heren (5) | W30: =CONCATENATE("Dames (",COUNTA(X31:X38),")") -> Dames (7) | Z30: =CONCATENATE("Heren (",COUNTA(AA31:AA38),")") -> Heren (5) | AD30: =CONCATENATE("Dames (",COUNTA(AE31:AE38),")") -> Dames (7) | AG30: =CONCATENATE("Heren (",COUNTA(AH31:AH38),")") -> Heren (5) | AK30: =CONCATENATE("Dames (",COUNTA(AL31:AL38),")") -> Dames (6) | AN30: =CONCATENATE("Heren (",COUNTA(AO31:AO38),")") -> Heren (6) | AR30: =CONCATENATE("Dames (",COUNTA(AS31:AS38),")") -> Dames (1) | AU30: =CONCATENATE("Heren (",COUNTA(AV31:AV38),")") -> Heren (1) | AY30: =CONCATENATE("Dames (",COUNTA(AZ31:AZ38),")") -> Dames (5) | BB30: =CONCATENATE("Heren (",COUNTA(BC31:BC38),")") -> Heren (4)
B31: {=_xlfn._xlws.FILTER(Spelerslijst!$B:$B,Spelerslijst!$G:$G=B$29,"")} | C31: {=_xlfn._xlws.FILTER(Spelerslijst!$H:$H,Spelerslijst!$G:$G=B$29,"")} | D31: {=_xlfn._xlws.FILTER(Spelerslijst!$D:$D,Spelerslijst!$G:$G=B$29,"")} | E31: {=_xlfn._xlws.FILTER(Spelerslijst!$L:$L,Spelerslijst!$Q:$Q=B$29,"")} | F31: {=_xlfn._xlws.FILTER(Spelerslijst!$R:$R,Spelerslijst!$Q:$Q=B$29,"")} | G31: {=_xlfn._xlws.FILTER(Spelerslijst!$N:$N,Spelerslijst!$Q:$Q=B$29,"")} | I31: {=_xlfn._xlws.FILTER(Spelerslijst!$B:$B,Spelerslijst!$G:$G=I$29,"")} | J31: {=_xlfn._xlws.FILTER(Spelerslijst!$H:$H,Spelerslijst!$G:$G=I$29,"")} | K31: {=_xlfn._xlws.FILTER(Spelerslijst!$D:$D,Spelerslijst!$G:$G=I$29,"")} | L31: {=_xlfn._xlws.FILTER(Spelerslijst!$L:$L,Spelerslijst!$Q:$Q=I$29,"")} | M31: {=_xlfn._xlws.FILTER(Spelerslijst!$R:$R,Spelerslijst!$Q:$Q=I$29,"")} | N31: {=_xlfn._xlws.FILTER(Spelerslijst!$N:$N,Spelerslijst!$Q:$Q=I$29,"")} | P31: {=_xlfn._xlws.FILTER(Spelerslijst!$B:$B,Spelerslijst!$G:$G=P$29,"")} -> Esther Ardon | Q31: {=_xlfn._xlws.FILTER(Spelerslijst!$H:$H,Spelerslijst!$G:$G=P$29,"")} -> S3 | R31: {=_xlfn._xlws.FILTER(Spelerslijst!$D:$D,Spelerslijst!$G:$G=P$29,"")} -> 28 | S31: {=_xlfn._xlws.FILTER(Spelerslijst!$L:$L,Spelerslijst!$Q:$Q=P$29,"")} -> Emiel Houwerzijl | T31: {=_xlfn._xlws.FILTER(Spelerslijst!$R:$R,Spelerslijst!$Q:$Q=P$29,"")} -> S3 | U31: {=_xlfn._xlws.FILTER(Spelerslijst!$N:$N,Spelerslijst!$Q:$Q=P$29,"")} -> 30 | W31: {=_xlfn._xlws.FILTER(Spelerslijst!$B:$B,Spelerslijst!$G:$G=W$29,"")} -> ~Dame S1S2 | X31: {=_xlfn._xlws.FILTER(Spelerslijst!$H:$H,Spelerslijst!$G:$G=W$29,"")} -> 0 | Y31: {=_xlfn._xlws.FILTER(Spelerslijst!$D:$D,Spelerslijst!$G:$G=W$29,"")} -> 24 | Z31: {=_xlfn._xlws.FILTER(Spelerslijst!$L:$L,Spelerslijst!$Q:$Q=W$29,"")} -> ~Heer S1S2 | AA31: {=_xlfn._xlws.FILTER(Spelerslijst!$R:$R,Spelerslijst!$Q:$Q=W$29,"")} -> 0 | AB31: {=_xlfn._xlws.FILTER(Spelerslijst!$N:$N,Spelerslijst!$Q:$Q=W$29,"")} -> 24 | AD31: {=_xlfn._xlws.FILTER(Spelerslijst!$B:$B,Spelerslijst!$G:$G=AD$29,"")} -> Anniek Pierse | AE31: {=_xlfn._xlws.FILTER(Spelerslijst!$H:$H,Spelerslijst!$G:$G=AD$29,"")} -> S7 | AF31: {=_xlfn._xlws.FILTER(Spelerslijst!$D:$D,Spelerslijst!$G:$G=AD$29,"")} -> 22 | AG31: {=_xlfn._xlws.FILTER(Spelerslijst!$L:$L,Spelerslijst!$Q:$Q=AD$29,"")} -> Joram Flach | AH31: {=_xlfn._xlws.FILTER(Spelerslijst!$R:$R,Spelerslijst!$Q:$Q=AD$29,"")} -> S5 | AI31: {=_xlfn._xlws.FILTER(Spelerslijst!$N:$N,Spelerslijst!$Q:$Q=AD$29,"")} -> 25 | AK31: {=_xlfn._xlws.FILTER(Spelerslijst!$B:$B,Spelerslijst!$G:$G=AK$29,"")} -> Amber Boeije | AL31: {=_xlfn._xlws.FILTER(Spelerslijst!$H:$H,Spelerslijst!$G:$G=AK$29,"")} -> A3 | AM31: {=_xlfn._xlws.FILTER(Spelerslijst!$D:$D,Spelerslijst!$G:$G=AK$29,"")} -> 19 | AN31: {=_xlfn._xlws.FILTER(Spelerslijst!$L:$L,Spelerslijst!$Q:$Q=AK$29,"")} -> Ché Kooper | AO31: {=_xlfn._xlws.FILTER(Spelerslijst!$R:$R,Spelerslijst!$Q:$Q=AK$29,"")} -> S6 | AP31: {=_xlfn._xlws.FILTER(Spelerslijst!$N:$N,Spelerslijst!$Q:$Q=AK$29,"")} -> 22 | AR31: {=_xlfn._xlws.FILTER(Spelerslijst!$B:$B,Spelerslijst!$G:$G=AR$29,"")} | AS31: {=_xlfn._xlws.FILTER(Spelerslijst!$H:$H,Spelerslijst!$G:$G=AR$29,"")} | AT31: {=_xlfn._xlws.FILTER(Spelerslijst!$D:$D,Spelerslijst!$G:$G=AR$29,"")} | AU31: {=_xlfn._xlws.FILTER(Spelerslijst!$L:$L,Spelerslijst!$Q:$Q=AR$29,"")} | AV31: {=_xlfn._xlws.FILTER(Spelerslijst!$R:$R,Spelerslijst!$Q:$Q=AR$29,"")} | AW31: {=_xlfn._xlws.FILTER(Spelerslijst!$N:$N,Spelerslijst!$Q:$Q=AR$29,"")} | AY31: {=_xlfn._xlws.FILTER(Spelerslijst!$B:$B,Spelerslijst!$G:$G=AY$29,"")} -> Dorien in 't Veld | AZ31: {=_xlfn._xlws.FILTER(Spelerslijst!$H:$H,Spelerslijst!$G:$G=AY$29,"")} -> MW1 | BA31: {=_xlfn._xlws.FILTER(Spelerslijst!$D:$D,Spelerslijst!$G:$G=AY$29,"")} -> 39 | BB31: {=_xlfn._xlws.FILTER(Spelerslijst!$L:$L,Spelerslijst!$Q:$Q=AY$29,"")} -> Hans Ploeg | BC31: {=_xlfn._xlws.FILTER(Spelerslijst!$R:$R,Spelerslijst!$Q:$Q=AY$29,"")} -> MW1 | BD31: {=_xlfn._xlws.FILTER(Spelerslijst!$N:$N,Spelerslijst!$Q:$Q=AY$29,"")} -> 36
P32: Hilde Visser | Q32: AR | R32: 34 | S32: Jan Booy | T32: S3 | U32: 34 | W32: ~Dame S1S2 | X32: 0 | Y32: 24 | Z32: ~Heer S1S2 | AA32: 0 | AB32: 24 | AD32: Jany Lacroes | AE32: S5 | AF32: 26 | AG32: Laurens Verhagen | AH32: A3 | AI32: 20 | AK32: Angela Friebel | AL32: S6 | AM32: 22 | AN32: David Kuijper | AO32: S6 | AP32: 21 | AY32: Kim Heesterbeek | AZ32: MW1 | BA32: 37 | BB32: Michiel 't Jong | BC32: MW1 | BD32: 43
P33: Lieke Ploeg | Q33: S4 | R33: 38 | S33: Lex van Gent | T33: S3 | U33: 29 | W33: Anouk de Jongh | X33: A2 | Y33: 19 | Z33: Luuk Baars | AA33: S5 | AB33: 23 | AD33: Lara Schram | AE33: S5 | AF33: 24 | AG33: Mark Schindler | AH33: S5 | AI33: 25 | AK33: Jennifer Herremans | AL33: S6 | AM33: 21 | AN33: Jens de Vlaming | AO33: S6 | AP33: 21 | AY33: Kim van der Starre-Scheurwater | AZ33: MW1 | BA33: 35 | BB33: Ronald Riet | BC33: MW1 | BD33: 41
P34: Linda Ardon | Q34: S3 | R34: 32 | S34: Roy de Vlaming | T34: S3 | U34: 40 | W34: Carlijn Lievaart | X34: S5 | Y34: 20 | Z34: Tijmen Fasbender | AA34: S5 | AB34: 21 | AD34: Laura Koote | AE34: S7 | AF34: 22 | AG34: Quinten van Driel | AH34: S5 | AI34: 24 | AK34: Kimberley Witman | AL34: S6 | AM34: 20 | AN34: Ruben Dubbeld | AO34: S6 | AP34: 24 | AY34: Liesbeth Brand | AZ34: MW1 | BA34: 34 | BB34: Wilco Kooij | BC34: MW1 | BD34: 49
P35: Merel van Gurp | Q35: S3 | R35: 32 | S35: Thomas Isarin | T35: S3 | U35: 36 | W35: Elena Quarré | X35: A2 | Y35: 19 | Z35: Tim Seevinck | AA35: Stopt | AB35: 21 | AD35: Marlies Valk | AE35: S5 | AF35: 21 | AG35: Rick van de Wijgaart | AH35: S5 | AI35: 21 | AK35: Sanne Dubbeld | AL35: S6 | AM35: 22 | AN35: Thijs Boon | AO35: S6 | AP35: 21 | AY35: Tamara van Opstal-Haksteen | AZ35: MW1 | BA35: 36
P36: Robin Leijdsman | Q36: S3 | R36: 28 | W36: Kim Dommisse | X36: S2 | Y36: 23 | AD36: Nadia de Wit | AE36: S7 | AF36: 23 | AK36: Tessa Dubbeld | AL36: - | AM36: 24 | AN36: Wouter Koornneef | AO36: A2 | AP36: 19
W37: Laura Mol | X37: 0 | Y37: #N/A | AD37: Syrah de Wit | AE37: S7 | AF37: 23
B39: {=_xlfn._xlws.FILTER(Staf!$C:$C,Staf!$B:$B=Teams!B29,"")} | C39: {=_xlfn._xlws.FILTER(Staf!$A:$A,Staf!$B:$B=Teams!B29,"")} | I39: {=_xlfn._xlws.FILTER(Staf!$C:$C,Staf!$B:$B=Teams!I29,"")} | J39: {=_xlfn._xlws.FILTER(Staf!$A:$A,Staf!$B:$B=Teams!I29,"")} | P39: {=_xlfn._xlws.FILTER(Staf!$C:$C,Staf!$B:$B=Teams!P29,"")} -> Begeleider | Q39: {=_xlfn._xlws.FILTER(Staf!$A:$A,Staf!$B:$B=Teams!P29,"")} -> Kim Ardon | W39: {=_xlfn._xlws.FILTER(Staf!$C:$C,Staf!$B:$B=Teams!W29,"")} -> Trainer/Coach | X39: {=_xlfn._xlws.FILTER(Staf!$A:$A,Staf!$B:$B=Teams!W29,"")} -> Vacature | AD39: {=_xlfn._xlws.FILTER(Staf!$C:$C,Staf!$B:$B=Teams!AD29,"")} -> Trainer/Coach | AE39: {=_xlfn._xlws.FILTER(Staf!$A:$A,Staf!$B:$B=Teams!AD29,"")} -> Vacature | AK39: {=_xlfn._xlws.FILTER(Staf!$C:$C,Staf!$B:$B=Teams!AK29,"")} -> Trainer/Coach | AL39: {=_xlfn._xlws.FILTER(Staf!$A:$A,Staf!$B:$B=Teams!AK29,"")} -> Monique Kooper | AR39: {=_xlfn._xlws.FILTER(Staf!$C:$C,Staf!$B:$B=Teams!AR29,"")} | AS39: {=_xlfn._xlws.FILTER(Staf!$A:$A,Staf!$B:$B=Teams!AR29,"")} | AY39: {=_xlfn._xlws.FILTER(Staf!$C:$C,Staf!$B:$B=Teams!AY29,"")} | AZ39: {=_xlfn._xlws.FILTER(Staf!$A:$A,Staf!$B:$B=Teams!AY29,"")}
W40: Trainer/Coach | X40: Vacature
A43: A-Junioren | B43: A1 | G43: =AVERAGE(D45:D55,G45:G55) -> #DIV/0! | I43: A2 | N43: =AVERAGE(K45:K55,N45:N55) -> #DIV/0! | P43: A3 | U43: =AVERAGE(R45:R55,U45:U55) -> 16.727273 | W43: A4 | AB43: =AVERAGE(Y45:Y55,AB45:AB55) -> #DIV/0! | AD43: A5 | AI43: =AVERAGE(AF45:AF55,AI45:AI55) -> #DIV/0!
B44: =CONCATENATE("Dames (",COUNTA(C45:C53),")") -> Dames (1) | E44: =CONCATENATE("Heren (",COUNTA(F45:F53),")") -> Heren (1) | I44: =CONCATENATE("Dames (",COUNTA(J45:J53),")") -> Dames (1) | L44: =CONCATENATE("Heren (",COUNTA(M45:M53),")") -> Heren (1) | P44: =CONCATENATE("Dames (",COUNTA(Q45:Q53),")") -> Dames (6) | S44: =CONCATENATE("Heren (",COUNTA(T45:T53),")") -> Heren (5) | W44: =CONCATENATE("Dames (",COUNTA(X45:X53),")") -> Dames (1) | Z44: =CONCATENATE("Heren (",COUNTA(AA45:AA53),")") -> Heren (1) | AD44: =CONCATENATE("Dames (",COUNTA(AE45:AE53),")") -> Dames (1) | AG44: =CONCATENATE("Heren (",COUNTA(AH45:AH53),")") -> Heren (1)
B45: {=_xlfn._xlws.FILTER(Spelerslijst!$B:$B,Spelerslijst!$G:$G=B$43,"")} | C45: {=_xlfn._xlws.FILTER(Spelerslijst!$H:$H,Spelerslijst!$G:$G=B$43,"")} | D45: {=_xlfn._xlws.FILTER(Spelerslijst!$D:$D,Spelerslijst!$G:$G=B$43,"")} | E45: {=_xlfn._xlws.FILTER(Spelerslijst!$L:$L,Spelerslijst!$Q:$Q=B$43,"")} | F45: {=_xlfn._xlws.FILTER(Spelerslijst!$R:$R,Spelerslijst!$Q:$Q=B$43,"")} | G45: {=_xlfn._xlws.FILTER(Spelerslijst!$N:$N,Spelerslijst!$Q:$Q=B$43,"")} | I45: {=_xlfn._xlws.FILTER(Spelerslijst!$B:$B,Spelerslijst!$G:$G=I$43,"")} | J45: {=_xlfn._xlws.FILTER(Spelerslijst!$H:$H,Spelerslijst!$G:$G=I$43,"")} | K45: {=_xlfn._xlws.FILTER(Spelerslijst!$D:$D,Spelerslijst!$G:$G=I$43,"")} | L45: {=_xlfn._xlws.FILTER(Spelerslijst!$L:$L,Spelerslijst!$Q:$Q=I$43,"")} | M45: {=_xlfn._xlws.FILTER(Spelerslijst!$R:$R,Spelerslijst!$Q:$Q=I$43,"")} | N45: {=_xlfn._xlws.FILTER(Spelerslijst!$N:$N,Spelerslijst!$Q:$Q=I$43,"")} | P45: {=_xlfn._xlws.FILTER(Spelerslijst!$B:$B,Spelerslijst!$G:$G=P$43,"")} -> Julia Bozuwa | Q45: {=_xlfn._xlws.FILTER(Spelerslijst!$H:$H,Spelerslijst!$G:$G=P$43,"")} -> A3 | R45: {=_xlfn._xlws.FILTER(Spelerslijst!$D:$D,Spelerslijst!$G:$G=P$43,"")} -> 17 | S45: {=_xlfn._xlws.FILTER(Spelerslijst!$L:$L,Spelerslijst!$Q:$Q=P$43,"")} -> Casper Boshoven | T45: {=_xlfn._xlws.FILTER(Spelerslijst!$R:$R,Spelerslijst!$Q:$Q=P$43,"")} -> B3 | U45: {=_xlfn._xlws.FILTER(Spelerslijst!$N:$N,Spelerslijst!$Q:$Q=P$43,"")} -> 16 | W45: {=_xlfn._xlws.FILTER(Spelerslijst!$B:$B,Spelerslijst!$G:$G=W$43,"")} | X45: {=_xlfn._xlws.FILTER(Spelerslijst!$H:$H,Spelerslijst!$G:$G=W$43,"")} | Y45: {=_xlfn._xlws.FILTER(Spelerslijst!$D:$D,Spelerslijst!$G:$G=W$43,"")} | Z45: {=_xlfn._xlws.FILTER(Spelerslijst!$L:$L,Spelerslijst!$Q:$Q=W$43,"")} | AA45: {=_xlfn._xlws.FILTER(Spelerslijst!$R:$R,Spelerslijst!$Q:$Q=W$43,"")} | AB45: {=_xlfn._xlws.FILTER(Spelerslijst!$N:$N,Spelerslijst!$Q:$Q=W$43,"")} | AD45: {=_xlfn._xlws.FILTER(Spelerslijst!$B:$B,Spelerslijst!$G:$G=AD$43,"")} | AE45: {=_xlfn._xlws.FILTER(Spelerslijst!$H:$H,Spelerslijst!$G:$G=AD$43,"")} | AF45: {=_xlfn._xlws.FILTER(Spelerslijst!$D:$D,Spelerslijst!$G:$G=AD$43,"")} | AG45: {=_xlfn._xlws.FILTER(Spelerslijst!$L:$L,Spelerslijst!$Q:$Q=AD$43,"")} | AH45: {=_xlfn._xlws.FILTER(Spelerslijst!$R:$R,Spelerslijst!$Q:$Q=AD$43,"")} | AI45: {=_xlfn._xlws.FILTER(Spelerslijst!$N:$N,Spelerslijst!$Q:$Q=AD$43,"")}
P46: Lianne Bouwknegt | Q46: A3 | R46: 17 | S46: Matthijs de Jongh | T46: A3 | U46: 17
P47: Robin Zwanenburg | Q47: B3 | R47: 15 | S47: Menno Pille | T47: A3 | U47: 17
P48: Tessa van Everdingen | Q48: A3 | R48: 18 | S48: Raoul Kuijper | T48: B3 | U48: 16
P49: Vivienne Versnel | Q49: A3 | R49: 19 | S49: Tommie Koornneef | T49: A3 | U49: 17
P50: Zoë Kamerman | Q50: B3 | R50: 15
...

Sheet Spelerslijst
A1: Rel.nr | B1: Naam & Initialen) | C1: Roepnaam | D1: Leeftijd Peildatum | E1: Geb datum | F1: Team op Peildatum | G1: Team 24-25 | H1: Team 23-24 | I1: AR | K1: Rel.nr | L1: Naam & Initialen | M1: Roepnaam | N1: Leeftijd Peildatum | O1: Geb datum | P1: Team op Peildatum | Q1: Team 24-25 | R1: Team 23-24 | S1: AR
B2: ~Dame S1S2 | D2: =VLOOKUP(YEAR(Tabel1[[#This Row],[Geb datum]]),Tabel8[#All],2,FALSE) -> 24 | E2: 36526 | F2: =VLOOKUP(YEAR(Tabel1[[#This Row],[Geb datum]]),Tabel8[#All],3,FALSE) -> S | G2: S4 | K2: NLZ21F1 | L2: Abel van de Ven | M2: Abel | N2: =VLOOKUP(YEAR(Tabel3[[#This Row],[Geb datum]]),Tabel8[#All],2,FALSE) -> 10 | O2: 41668 | P2: =VLOOKUP(YEAR(Tabel3[[#This Row],[Geb datum]]),Tabel8[#All],3,FALSE) -> D | Q2: D1 | R2: D2
B3: ~Dame S1S2 | D3: =VLOOKUP(YEAR(Tabel1[[#This Row],[Geb datum]]),Tabel8[#All],2,FALSE) -> 24 | E3: 36526 | F3: =VLOOKUP(YEAR(Tabel1[[#This Row],[Geb datum]]),Tabel8[#All],3,FALSE) -> S | G3: S4 | K3: NMV71X5 | L3: Amos Alberts | M3: Amos | N3: =VLOOKUP(YEAR(Tabel3[[#This Row],[Geb datum]]),Tabel8[#All],2,FALSE) -> 7 | O3: 42901 | P3: =VLOOKUP(YEAR(Tabel3[[#This Row],[Geb datum]]),Tabel8[#All],3,FALSE) -> F | Q3: F1 | R3: F1
A4: NMV61M3 | B4: Alisa Stomp | C4: Alisa | D4: =VLOOKUP(YEAR(Tabel1[[#This Row],[Geb datum]]),Tabel8[#All],2,FALSE) -> 7 | E4: 42919 | F4: =VLOOKUP(YEAR(Tabel1[[#This Row],[Geb datum]]),Tabel8[#All],3,FALSE) -> F | G4: F1 | H4: F1 | K4: NFW92M3 | L4: Antjan Laban | M4: Antjan | N4: =VLOOKUP(YEAR(Tabel3[[#This Row],[Geb datum]]),Tabel8[#All],2,FALSE) -> 44 | O4: 29340 | P4: =VLOOKUP(YEAR(Tabel3[[#This Row],[Geb datum]]),Tabel8[#All],3,FALSE) -> S | Q4: AR | R4: S4
A5: NLB70T7 | B5: Amber Boeije | C5: Amber | D5: =VLOOKUP(YEAR(Tabel1[[#This Row],[Geb datum]]),Tabel8[#All],2,FALSE) -> 19 | E5: 38480 | F5: =VLOOKUP(YEAR(Tabel1[[#This Row],[Geb datum]]),Tabel8[#All],3,FALSE) -> S | G5: S6 | H5: A3 | K5: NFW26G8 | L5: Arjan Noels | M5: Arjan | N5: =VLOOKUP(YEAR(Tabel3[[#This Row],[Geb datum]]),Tabel8[#All],2,FALSE) -> 44 | O5: 29523 | P5: =VLOOKUP(YEAR(Tabel3[[#This Row],[Geb datum]]),Tabel8[#All],3,FALSE) -> S | Q5: Stopt | R5: S4
A6: NLH27P1 | B6: Amber de Haas | C6: Amber | D6: =VLOOKUP(YEAR(Tabel1[[#This Row],[Geb datum]]),Tabel8[#All],2,FALSE) -> 17 | E6: 39114 | F6: =VLOOKUP(YEAR(Tabel1[[#This Row],[Geb datum]]),Tabel8[#All],3,FALSE) -> A | G6: A1A2 | H6: A1 | K6: NMV76G1 | L6: Art Malschaert | M6: Art | N6: =VLOOKUP(YEAR(Tabel3[[#This Row],[Geb datum]]),Tabel8[#All],2,FALSE) -> 7 | O6: 42955 | P6: =VLOOKUP(YEAR(Tabel3[[#This Row],[Geb datum]]),Tabel8[#All],3,FALSE) -> F | Q6: Stopt | R6: F2
A7: NLB70X5 | B7: Angela Friebel | C7: Angela | D7: =VLOOKUP(YEAR(Tabel1[[#This Row],[Geb datum]]),Tabel8[#All],2,FALSE) -> 22 | E7: 37541 | F7: =VLOOKUP(YEAR(Tabel1[[#This Row],[Geb datum]]),Tabel8[#All],3,FALSE) -> S | G7: S6 | H7: S6 | K7: NMB99X9 | L7: Ayden van den Bosch | M7: Ayden | N7: =VLOOKUP(YEAR(Tabel3[[#This Row],[Geb datum]]),Tabel8[#All],2,FALSE) -> 10 | O7: 41706 | P7: =VLOOKUP(YEAR(Tabel3[[#This Row],[Geb datum]]),Tabel8[#All],3,FALSE) -> D | Q7: D3 | R7: E1
A8: NMS40B0 | B8: Aniek van den Bergh | C8: Aniek | D8: =VLOOKUP(YEAR(Tabel1[[#This Row],[Geb datum]]),Tabel8[#All],2,FALSE) -> 9 | E8: 42308 | F8: =VLOOKUP(YEAR(Tabel1[[#This Row],[Geb datum]]),Tabel8[#All],3,FALSE) -> E | G8: E2 | H8: E5 | K8: NFS90V6 | L8: Bart de Wit | M8: Bart | N8: =VLOOKUP(YEAR(Tabel3[[#This Row],[Geb datum]]),Tabel8[#All],2,FALSE) -> 45 | O8: 29031 | P8: =VLOOKUP(YEAR(Tabel3[[#This Row],[Geb datum]]),Tabel8[#All],3,FALSE) -> S | Q8: Stopt | R8: S4
A9: NKD19X7 | B9: Anne Driesprong | C9: Anne | D9: =VLOOKUP(YEAR(Tabel1[[#This Row],[Geb datum]]),Tabel8[#All],2,FALSE) -> 24 | E9: 36727 | F9: =VLOOKUP(YEAR(Tabel1[[#This Row],[Geb datum]]),Tabel8[#All],3,FALSE) -> S | G9: AR | H9: AR | K9: NKD19Y4 | L9: Bart Driesprong | M9: Bart | N9: =VLOOKUP(YEAR(Tabel3[[#This Row],[Geb datum]]),Tabel8[#All],2,FALSE) -> 26 | O9: 36077 | P9: =VLOOKUP(YEAR(Tabel3[[#This Row],[Geb datum]]),Tabel8[#All],3,FALSE) -> S | Q9: S1S2 | R9: S1
A10: NMW65S8 | B10: Annelieke Smouter | C10: Annelieke | D10: =VLOOKUP(YEAR(Tabel1[[#This Row],[Geb datum]]),Tabel8[#All],2,FALSE) -> 25 | E10: 36522 | F10: =VLOOKUP(YEAR(Tabel1[[#This Row],[Geb datum]]),Tabel8[#All],3,FALSE) -> S | G10: ? | K10: NJH39X4 | L10: Bart van der Brugge | M10: Bart | N10: =VLOOKUP(YEAR(Tabel3[[#This Row],[Geb datum]]),Tabel8[#All],2,FALSE) -> 29 | O10: 34900 | P10: =VLOOKUP(YEAR(Tabel3[[#This Row],[Geb datum]]),Tabel8[#All],3,FALSE) -> S | Q10: AR | R10: AR
A11: NMW83F1 | B11: Anne-Sophie Lotgerink | C11: Anne-Sophie | D11: =VLOOKUP(YEAR(Tabel1[[#This Row],[Geb datum]]),Tabel8[#All],2,FALSE) -> 12 | E11: 40912 | F11: =VLOOKUP(YEAR(Tabel1[[#This Row],[Geb datum]]),Tabel8[#All],3,FALSE) -> C | G11: C3 | H11: D4 | K11: NGW10M4 | L11: Bas de Jong | M11: Bas | N11: =VLOOKUP(YEAR(Tabel3[[#This Row],[Geb datum]]),Tabel8[#All],2,FALSE) -> 34 | O11: 33019 | P11: =VLOOKUP(YEAR(Tabel3[[#This Row],[Geb datum]]),Tabel8[#All],3,FALSE) -> S | Q11: AR | R11: S4
A12: NKJ29C1 | B12: Anniek Pierse | C12: Anniek | D12: =VLOOKUP(YEAR(Tabel1[[#This Row],[Geb datum]]),Tabel8[#All],2,FALSE) -> 22 | E12: 37324 | F12: =VLOOKUP(YEAR(Tabel1[[#This Row],[Geb datum]]),Tabel8[#All],3,FALSE) -> S | G12: S5 | H12: S7 | K12: NKX66V9 | L12: Bert Seevinck | M12: Bert | N12: =VLOOKUP(YEAR(Tabel3[[#This Row],[Geb datum]]),Tabel8[#All],2,FALSE) -> 63 | O12: 22358 | P12: =VLOOKUP(YEAR(Tabel3[[#This Row],[Geb datum]]),Tabel8[#All],3,FALSE) -> S | Q12: AR | R12: AR
A13: NLZ39C9 | B13: Anouk Bakker | C13: Anouk | D13: =VLOOKUP(YEAR(Tabel1[[#This Row],[Geb datum]]),Tabel8[#All],2,FALSE) -> 12 | E13: 41214 | F13: =VLOOKUP(YEAR(Tabel1[[#This Row],[Geb datum]]),Tabel8[#All],3,FALSE) -> C | G13: C2 | H13: D1 | K13: NJF95S5 | L13: Bob Mans | M13: Bob | N13: =VLOOKUP(YEAR(Tabel3[[#This Row],[Geb datum]]),Tabel8[#All],2,FALSE) -> 28 | O13: 35372 | P13: =VLOOKUP(YEAR(Tabel3[[#This Row],[Geb datum]]),Tabel8[#All],3,FALSE) -> S | Q13: S1S2 | R13: S2
A14: NKT92K1 | B14: Anouk de Jongh | C14: Anouk | D14: =VLOOKUP(YEAR(Tabel1[[#This Row],[Geb datum]]),Tabel8[#All],2,FALSE) -> 19 | E14: 38597 | F14: =VLOOKUP(YEAR(Tabel1[[#This Row],[Geb datum]]),Tabel8[#All],3,FALSE) -> S | G14: S4 | H14: A2 | K14: NMZ29TO | L14: Branley van Wingerden | M14: Branley | N14: =VLOOKUP(YEAR(Tabel3[[#This Row],[Geb datum]]),Tabel8[#All],2,FALSE) -> 5 | O14: 43485 | P14: =VLOOKUP(YEAR(Tabel3[[#This Row],[Geb datum]]),Tabel8[#All],3,FALSE) -> K | Q14: K | R14: Nieuw
A15: NFW41S7 | B15: Barbara Camphens-Moerman | C15: Barbara | D15: =VLOOKUP(YEAR(Tabel1[[#This Row],[Geb datum]]),Tabel8[#All],2,FALSE) -> 43 | E15: 29885 | F15: =VLOOKUP(YEAR(Tabel1[[#This Row],[Geb datum]]),Tabel8[#All],3,FALSE) -> S | G15: AR | H15: S4 | K15: NMQ44L0 | L15: Cas Tieleman | M15: Cas | N15: =VLOOKUP(YEAR(Tabel3[[#This Row],[Geb datum]]),Tabel8[#All],2,FALSE) -> 20 | O15: 38220 | P15: =VLOOKUP(YEAR(Tabel3[[#This Row],[Geb datum]]),Tabel8[#All],3,FALSE) -> S | Q15: Stopt | R15: S6
A16: NKS24S7 | B16: Bente van Wijngaarden | C16: Bente | D16: =VLOOKUP(YEAR(Tabel1[[#This Row],[Geb datum]]),Tabel8[#All],2,FALSE) -> 18 | E16: 38928 | F16: =VLOOKUP(YEAR(Tabel1[[#This Row],[Geb datum]]),Tabel8[#All],3,FALSE) -> A | G16: Stopt | H16: A3 | K16: NMQ65B3 | L16: Cas Uljee | M16: Cas | N16: =VLOOKUP(YEAR(Tabel3[[#This Row],[Geb datum]]),Tabel8[#All],2,FALSE) -> 11 | O16: 41365 | P16: =VLOOKUP(YEAR(Tabel3[[#This Row],[Geb datum]]),Tabel8[#All],3,FALSE) -> D | Q16: D2 | R16: D3
A17: NLP78D3 | B17: Benthe van der Linden | C17: Benthe | D17: =VLOOKUP(YEAR(Tabel1[[#This Row],[Geb datum]]),Tabel8[#All],2,FALSE) -> 16 | E17: 39629 | F17: =VLOOKUP(YEAR(Tabel1[[#This Row],[Geb datum]]),Tabel8[#All],3,FALSE) -> A | G17: A1A2 | H17: B2 | K17: NMJ10P4 | L17: Casper Boshoven | M17: Casper | N17: =VLOOKUP(YEAR(Tabel3[[#This Row],[Geb datum]]),Tabel8[#All],2,FALSE) -> 16 | O17: 39676 | P17: =VLOOKUP(YEAR(Tabel3[[#This Row],[Geb datum]]),Tabel8[#All],3,FALSE) -> A | Q17: A3 | R17: B3
A18: NMZ00X1 | B18: Benthe van Dijl | C18: Benthe | D18: =VLOOKUP(YEAR(Tabel1[[#This Row],[Geb datum]]),Tabel8[#All],2,FALSE) -> 10 | E18: 41845 | F18: =VLOOKUP(YEAR(Tabel1[[#This Row],[Geb datum]]),Tabel8[#All],3,FALSE) -> D | G18: D4 | H18: nieuw | K18: NJZ26Z2 | L18: Ché Kooper | M18: Ché | N18: =VLOOKUP(YEAR(Tabel3[[#This Row],[Geb datum]]),Tabel8[#All],2,FALSE) -> 22 | O18: 37566 | P18: =VLOOKUP(YEAR(Tabel3[[#This Row],[Geb datum]]),Tabel8[#All],3,FALSE) -> S | Q18: S6 | R18: S6
A19: NKR88F7 | B19: Bridget ter Horst | C19: Bridget | D19: =VLOOKUP(YEAR(Tabel1[[#This Row],[Geb datum]]),Tabel8[#All],2,FALSE) -> 21 | E19: 37771 | F19: =VLOOKUP(YEAR(Tabel1[[#This Row],[Geb datum]]),Tabel8[#All],3,FALSE) -> S | G19: Stopt | H19: S2 | K19: NMX21V8 | L19: Ciprian Minzararu | M19: Ciprian | N19: =VLOOKUP(YEAR(Tabel3[[#This Row],[Geb datum]]),Tabel8[#All],2,FALSE) -> 8 | O19: 42507 | P19: =VLOOKUP(YEAR(Tabel3[[#This Row],[Geb datum]]),Tabel8[#All],3,FALSE) -> E | Q19: Stopt | R19: F2
A20: NML00R5 | B20: Bryanna Bos | C20: Bryanna | D20: =VLOOKUP(YEAR(Tabel1[[#This Row],[Geb datum]]),Tabel8[#All],2,FALSE) -> 14 | E20: 40373 | F20: =VLOOKUP(YEAR(Tabel1[[#This Row],[Geb datum]]),Tabel8[#All],3,FALSE) -> B | G20: Stopt | H20: C4 | K20: NMX53X3 | L20: Collin Koppelaar | M20: Collin | N20: =VLOOKUP(YEAR(Tabel3[[#This Row],[Geb datum]]),Tabel8[#All],2,FALSE) -> 10 | O20: 41735 | P20: =VLOOKUP(YEAR(Tabel3[[#This Row],[Geb datum]]),Tabel8[#All],3,FALSE) -> D | Q20: D4 | R20: D4
A21: NLB70Z9 | B21: Carlijn Lievaart | C21: Carlijn | D21: =VLOOKUP(YEAR(Tabel1[[#This Row],[Geb datum]]),Tabel8[#All],2,FALSE) -> 20 | E21: 38267 | F21: =VLOOKUP(YEAR(Tabel1[[#This Row],[Geb datum]]),Tabel8[#All],3,FALSE) -> S | G21: S4 | H21: S5 | L21: Daan vd Weijde | M21: Daan | N21: =VLOOKUP(YEAR(Tabel3[[#This Row],[Geb datum]]),Tabel8[#All],2,FALSE) -> 13 | O21: 40846 | P21: =VLOOKUP(YEAR(Tabel3[[#This Row],[Geb datum]]),Tabel8[#All],3,FALSE) -> C | Q21: C3 | R21: Nieuw
A22: NLN05N7 | B22: Carmen van der Klooster | C22: Carmen | D22: =VLOOKUP(YEAR(Tabel1[[#This Row],[Geb datum]]),Tabel8[#All],2,FALSE) -> 16 | E22: 39760 | F22: =VLOOKUP(YEAR(Tabel1[[#This Row],[Geb datum]]),Tabel8[#All],3,FALSE) -> A | G22: A1A2 | H22: B1 | K22: NLS75Y4 | L22: Dani Heersping | M22: Dani | N22: =VLOOKUP(YEAR(Tabel3[[#This Row],[Geb datum]]),Tabel8[#All],2,FALSE) -> 16 | O22: 39753 | P22: =VLOOKUP(YEAR(Tabel3[[#This Row],[Geb datum]]),Tabel8[#All],3,FALSE) -> A | Q22: A1A2 | R22: B2
A23: NKX56Q9 | B23: Damaris Everaarts | C23: Damaris | D23: =VLOOKUP(YEAR(Tabel1[[#This Row],[Geb datum]]),Tabel8[#All],2,FALSE) -> 45 | E23: 28948 | F23: =VLOOKUP(YEAR(Tabel1[[#This Row],[Geb datum]]),Tabel8[#All],3,FALSE) -> S | G23: AR | H23: AR | K23: NKY88T2 | L23: Daniel den Uijl | M23: Daniel | N23: =VLOOKUP(YEAR(Tabel3[[#This Row],[Geb datum]]),Tabel8[#All],2,FALSE) -> 21 | O23: 37832 | P23: =VLOOKUP(YEAR(Tabel3[[#This Row],[Geb datum]]),Tabel8[#All],3,FALSE) -> S | Q23: S1S2 | R23: S2
A24: NLP77Z4 | B24: Danique van der Klooster | C24: Danique | D24: =VLOOKUP(YEAR(Tabel1[[#This Row],[Geb datum]]),Tabel8[#All],2,FALSE) -> 14 | E24: 40239 | F24: =VLOOKUP(YEAR(Tabel1[[#This Row],[Geb datum]]),Tabel8[#All],3,FALSE) -> B | G24: B1B2 | H24: C1 | K24: NKW21H5 | L24: David Kuijper | M24: David | N24: =VLOOKUP(YEAR(Tabel3[[#This Row],[Geb datum]]),Tabel8[#All],2,FALSE) -> 21 | O24: 37971 | P24: =VLOOKUP(YEAR(Tabel3[[#This Row],[Geb datum]]),Tabel8[#All],3,FALSE) -> S | Q24: S6 | R24: S6
A25: NLP78L9 | B25: Danique van der Wiel | C25: Danique | D25: =VLOOKUP(YEAR(Tabel1[[#This Row],[Geb datum]]),Tabel8[#All],2,FALSE) -> 14 | E25: 40538 | F25: =VLOOKUP(YEAR(Tabel1[[#This Row],[Geb datum]]),Tabel8[#All],3,FALSE) -> B | G25: B3 | H25: C3 | K25: NMG85H5 | L25: Diederik Hovestadt | M25: Diederik | N25: =VLOOKUP(YEAR(Tabel3[[#This Row],[Geb datum]]),Tabel8[#All],2,FALSE) -> 15 | O25: 40112 | P25: =VLOOKUP(YEAR(Tabel3[[#This Row],[Geb datum]]),Tabel8[#All],3,FALSE) -> B | Q25: B1B2 | R25: C2
A26: NMN23K7 | B26: Davina Moniz | C26: Davina | D26: =VLOOKUP(YEAR(Tabel1[[#This Row],[Geb datum]]),Tabel8[#All],2,FALSE) -> 11 | E26: 41398 | F26: =VLOOKUP(YEAR(Tabel1[[#This Row],[Geb datum]]),Tabel8[#All],3,FALSE) -> D | G26: D1 | H26: D1 | K26: NMB42C6 | L26: Djess van Heeren | M26: Djess | N26: =VLOOKUP(YEAR(Tabel3[[#This Row],[Geb datum]]),Tabel8[#All],2,FALSE) -> 14 | O26: 40253 | P26: =VLOOKUP(YEAR(Tabel3[[#This Row],[Geb datum]]),Tabel8[#All],3,FALSE) -> B | Q26: B4 | R26: C4
A27: NFW15S4 | B27: Debita Zwanenburg-Moerman | C27: Debita | D27: 47 | E27: 28329 | F27: S | G27: AR | H27: AR | K27: NFW26Q8 | L27: Egbert Vos | M27: Egbert | N27: =VLOOKUP(YEAR(Tabel3[[#This Row],[Geb datum]]),Tabel8[#All],2,FALSE) -> 43 | O27: 29725 | P27: =VLOOKUP(YEAR(Tabel3[[#This Row],[Geb datum]]),Tabel8[#All],3,FALSE) -> S | Q27: Stopt | R27: MW1
A28: NLX25R5 | B28: Demi Engelfriet | C28: Demi | D28: =VLOOKUP(YEAR(Tabel1[[#This Row],[Geb datum]]),Tabel8[#All],2,FALSE) -> 14 | E28: 40327 | F28: =VLOOKUP(YEAR(Tabel1[[#This Row],[Geb datum]]),Tabel8[#All],3,FALSE) -> B | G28: B1B2 | H28: C1 | K28: NMZ29R6 | L28: Elroy van Wingerden | M28: Elroy | N28: =VLOOKUP(YEAR(Tabel3[[#This Row],[Geb datum]]),Tabel8[#All],2,FALSE) -> 7 | O28: 42831 | P28: =VLOOKUP(YEAR(Tabel3[[#This Row],[Geb datum]]),Tabel8[#All],3,FALSE) -> F | Q28: F2 | R28: Nieuw
A29: NMB60Y4 | B29: Demi Lindhout | C29: Demi | D29: =VLOOKUP(YEAR(Tabel1[[#This Row],[Geb datum]]),Tabel8[#All],2,FALSE) -> 14 | E29: 40189 | F29: =VLOOKUP(YEAR(Tabel1[[#This Row],[Geb datum]]),Tabel8[#All],3,FALSE) -> B | G29: B1B2 | H29: C1 | K29: NJC26C8 | L29: Emiel Houwerzijl | M29: Emiel | N29: =VLOOKUP(YEAR(Tabel3[[#This Row],[Geb datum]]),Tabel8[#All],2,FALSE) -> 30 | O29: 34464 | P29: =VLOOKUP(YEAR(Tabel3[[#This Row],[Geb datum]]),Tabel8[#All],3,FALSE) -> S | Q29: S3 | R29: S3
A30: NKG59L6 | B30: Demi van Dijk | C30: Demi | D30: =VLOOKUP(YEAR(Tabel1[[#This Row],[Geb datum]]),Tabel8[#All],2,FALSE) -> 23 | E30: 36938 | F30: =VLOOKUP(YEAR(Tabel1[[#This Row],[Geb datum]]),Tabel8[#All],3,FALSE) -> S | G30: S1S2 | H30: S2 | K30: NFW40B5 | L30: Erwin Belder | M30: Erwin | N30: =VLOOKUP(YEAR(Tabel3[[#This Row],[Geb datum]]),Tabel8[#All],2,FALSE) -> 47 | O30: 28259 | P30: =VLOOKUP(YEAR(Tabel3[[#This Row],[Geb datum]]),Tabel8[#All],3,FALSE) -> S | Q30: NSL | R30: NSL
A31: NJC15T9 | B31: Diana Visser-Michelsen | C31: Diana | D31: =VLOOKUP(YEAR(Tabel1[[#This Row],[Geb datum]]),Tabel8[#All],2,FALSE) -> 32 | E31: 33777 | F31: =VLOOKUP(YEAR(Tabel1[[#This Row],[Geb datum]]),Tabel8[#All],3,FALSE) -> S | G31: Stopt | H31: S4 | K31: NMJ72R4 | L31: Falco Bemer | M31: Falco | N31: =VLOOKUP(YEAR(Tabel3[[#This Row],[Geb datum]]),Tabel8[#All],2,FALSE) -> 11 | O31: 41299 | P31: =VLOOKUP(YEAR(Tabel3[[#This Row],[Geb datum]]),Tabel8[#All],3,FALSE) -> D | Q31: D1 | R31: D2
A32: NMR70L4 | B32: Diede van den Boogaart | C32: Diede | D32: =VLOOKUP(YEAR(Tabel1[[#This Row],[Geb datum]]),Tabel8[#All],2,FALSE) -> 6 | E32: 43409 | F32: =VLOOKUP(YEAR(Tabel1[[#This Row],[Geb datum]]),Tabel8[#All],3,FALSE) -> F | G32: Stopt | H32: K | L32: Finn de Haseth | M32: Finn | N32: =VLOOKUP(YEAR(Tabel3[[#This Row],[Geb datum]]),Tabel8[#All],2,FALSE) -> 12 | O32: 41017 | P32: =VLOOKUP(YEAR(Tabel3[[#This Row],[Geb datum]]),Tabel8[#All],3,FALSE) -> C | Q32: C3 | R32: Nieuw
A33: NKR20L5 | B33: Djuna Seevinck | C33: Djuna | D33: =VLOOKUP(YEAR(Tabel1[[#This Row],[Geb datum]]),Tabel8[#All],2,FALSE) -> 23 | E33: 37246 | F33: =VLOOKUP(YEAR(Tabel1[[#This Row],[Geb datum]]),Tabel8[#All],3,FALSE) -> S | G33: - | H33: - | L33: Finn Ploeg | M33: Finn | N33: =VLOOKUP(YEAR(Tabel3[[#This Row],[Geb datum]]),Tabel8[#All],2,FALSE) -> 5 | O33: 43532 | P33: =VLOOKUP(YEAR(Tabel3[[#This Row],[Geb datum]]),Tabel8[#All],3,FALSE) -> K | Q33: F2 | R33: Nieuw
A34: NLT96R9 | B34: Doeska Voorbij | C34: Doeska | D34: =VLOOKUP(YEAR(Tabel1[[#This Row],[Geb datum]]),Tabel8[#All],2,FALSE) -> 16 | E34: 39751 | F34: =VLOOKUP(YEAR(Tabel1[[#This Row],[Geb datum]]),Tabel8[#All],3,FALSE) -> A | G34: A1A2 | H34: B1 | K34: NMG03C4 | L34: Finn Verboom | M34: Finn | N34: =VLOOKUP(YEAR(Tabel3[[#This Row],[Geb datum]]),Tabel8[#All],2,FALSE) -> 12 | O34: 40974 | P34: =VLOOKUP(YEAR(Tabel3[[#This Row],[Geb datum]]),Tabel8[#All],3,FALSE) -> C | Q34: Stopt | R34: D1
A35: NFW28D3 | B35: Dorien in 't Veld | C35: Dorien | D35: =VLOOKUP(YEAR(Tabel1[[#This Row],[Geb datum]]),Tabel8[#All],2,FALSE) -> 39 | E35: 31086 | F35: =VLOOKUP(YEAR(Tabel1[[#This Row],[Geb datum]]),Tabel8[#All],3,FALSE) -> S | G35: MW1 | H35: MW1 | K35: NJG52P6 | L35: Freek de Peuter | M35: Freek | N35: =VLOOKUP(YEAR(Tabel3[[#This Row],[Geb datum]]),Tabel8[#All],2,FALSE) -> 28 | O35: 35270 | P35: =VLOOKUP(YEAR(Tabel3[[#This Row],[Geb datum]]),Tabel8[#All],3,FALSE) -> S | Q35: AR | R35: AR
A36: NLB70S0 | B36: Elena Quarré | C36: Elena | D36: =VLOOKUP(YEAR(Tabel1[[#This Row],[Geb datum]]),Tabel8[#All],2,FALSE) -> 19 | E36: 38509 | F36: =VLOOKUP(YEAR(Tabel1[[#This Row],[Geb datum]]),Tabel8[#All],3,FALSE) -> S | G36: S4 | H36: A2 | K36: NLV80M3 | L36: Freek Laban | M36: Freek | N36: =VLOOKUP(YEAR(Tabel3[[#This Row],[Geb datum]]),Tabel8[#All],2,FALSE) -> 12 | O36: 41044 | P36: =VLOOKUP(YEAR(Tabel3[[#This Row],[Geb datum]]),Tabel8[#All],3,FALSE) -> C | Q36: C1 | R36: C2
A37: NMN23N8 | B37: Eline Veenendaal | C37: Eline | D37: =VLOOKUP(YEAR(Tabel1[[#This Row],[Geb datum]]),Tabel8[#All],2,FALSE) -> 15 | E37: 40075 | F37: =VLOOKUP(YEAR(Tabel1[[#This Row],[Geb datum]]),Tabel8[#All],3,FALSE) -> B | G37: B4 | H37: C4 | K37: NLG58X4 | L37: Freek van Dongen | M37: Freek | N37: =VLOOKUP(YEAR(Tabel3[[#This Row],[Geb datum]]),Tabel8[#All],2,FALSE) -> 17 | O37: 39196 | P37: =VLOOKUP(YEAR(Tabel3[[#This Row],[Geb datum]]),Tabel8[#All],3,FALSE) -> A | Q37: A1A2 | R37: A2
A38: NMX01Q3 | B38: Elize Bohms | C38: Elize | D38: =VLOOKUP(YEAR(Tabel1[[#This Row],[Geb datum]]),Tabel8[#All],2,FALSE) -> 12 | E38: 41223 | F38: =VLOOKUP(YEAR(Tabel1[[#This Row],[Geb datum]]),Tabel8[#All],3,FALSE) -> C | G38: Stopt | H38: D4 | K38: NMN23L4 | L38: Fynn Kuling | M38: Fynn | N38: =VLOOKUP(YEAR(Tabel3[[#This Row],[Geb datum]]),Tabel8[#All],2,FALSE) -> 11 | O38: 41375 | P38: =VLOOKUP(YEAR(Tabel3[[#This Row],[Geb datum]]),Tabel8[#All],3,FALSE) -> D | Q38: D2 | R38: D3
A39: NLL20G1 | B39: Elize van de Burgt | C39: Elize | D39: =VLOOKUP(YEAR(Tabel1[[#This Row],[Geb datum]]),Tabel8[#All],2,FALSE) -> 16 | E39: 39804 | F39: =VLOOKUP(YEAR(Tabel1[[#This Row],[Geb datum]]),Tabel8[#All],3,FALSE) -> A | G39: A1A2 | H39: B2 | K39: NMW39Z4 | L39: Gideon Verberkt | M39: Gideon | N39: =VLOOKUP(YEAR(Tabel3[[#This Row],[Geb datum]]),Tabel8[#All],2,FALSE) -> 9 | O39: 42011 | P39: =VLOOKUP(YEAR(Tabel3[[#This Row],[Geb datum]]),Tabel8[#All],3,FALSE) -> E | Q39: E2 | R39: E5
A40: NMY80F4 | B40: Elske Niehof | C40: Eslke | D40: =VLOOKUP(YEAR(Tabel1[[#This Row],[Geb datum]]),Tabel8[#All],2,FALSE) -> 11 | E40: 41344 | F40: =VLOOKUP(YEAR(Tabel1[[#This Row],[Geb datum]]),Tabel8[#All],3,FALSE) -> D | G40: D4 | H40: nieuw | K40: NGG54S2 | L40: Hans Ploeg | M40: Hans | N40: =VLOOKUP(YEAR(Tabel3[[#This Row],[Geb datum]]),Tabel8[#All],2,FALSE) -> 36 | O40: 32170 | P40: =VLOOKUP(YEAR(Tabel3[[#This Row],[Geb datum]]),Tabel8[#All],3,FALSE) -> S | Q40: MW1 | R40: MW1
...

Sheet Staf
A1: Naam | B1: Team | C1: Functie | D1: eigen team | E1: team vorig jaar | F1: Niveau
A2: Jens Lohuis | B2: - | C2: Trainer/Coach | D2: A1/A2 | E2: E3
A3: Joël Wietses | B3: - | C3: Trainer/Coach | D3: A1/A2 | E3: E3
A4: Jarno Valk | B4: - | C4: Trainer/Coach | D4: A1/A2 | E4: D3 | F4: Startend - KT2
A5: Joram Flach | B5: - | C5: Trainer/Coach | D5: S7 | E5: D1 | F5: Medior
A6: Kimberly Jacobs | B6: - | C6: Trainer/Coach | D6: X | E6: C3 | F6: Medior
A7: Mark Schindler | B7: - | C7: Trainer/Coach | D7: S7 | E7: D3 | F7: Junior
A8: Rick van de Wijgaart | B8: - | C8: Trainer/Coach | D8: S7 | E8: D3 | F8: Startend - KT2
A9: Tessa Dubbeld | B9: - | C9: Trainer/Coach | D9: S6 | E9: C2
A10: Vacature | B10: - | C10: Trainer/Coach | E10: E5
A11: Vacature | B11: - | C11: Trainer/Coach | E11: E5
A12: Demi | B12: - | C12: Trainer/Coach
A13: Julia Kleingeld | B13: - | C13: Trainer/Coach
A14: Egbert Vos | B14: - | C14: Assistent-trainer | D14: X | E14: D1 | F14: Senior
A15: Michel Sas | B15: - | C15: Teambegeleider | D15: X | E15: B1
A16: Lenny van den Bergh | B16: - | C16: Ondersteuning | E16: E5 | F16: Startend - KT2
A17: Rob van Dongen | B17: A1A2 | C17: Trainer/Coach A1 | D17: X | E17: A1
A18: Ruben Blokland | B18: A1A2 | C18: Trainer/Coach A1 | D18: X | E18: A1 | F18: Senior
A19: Olivier Klink | B19: A1A2 | C19: Trainer/Coach A2 | D19: S1S2 | E19: A2 | F19: Medior - KT3
A20: Tim van Gent | B20: A1A2 | C20: Trainer/Coach A2 | D20: S1S2 | E20: A2 | F20: Junior
A21: Alex van de Klooster | B21: A1A2 | C21: Teambegeleider
A22: David Kuijper | B22: A3 | C22: Trainer/Coach | E22: A3
A23: Ruben Dubbeld | B23: A3 | C23: Trainer/Coach | E23: A3
A24: Jasper Kleingeld | B24: B1B2 | C24: Trainer/Coach B1 | D24: X | E24: C1 | F24: Senior
A25: Mees Oppe | B25: B1B2 | C25: Trainer/Coach B1 | D25: DeetosSnel 1 | E25: C1 | F25: Junior - KT2
A26: Daniël den Uijl | B26: B1B2 | C26: Trainer/Coach B2 | E26: B2
A27: Eva Teerds | B27: B1B2 | C27: Trainer/Coach B2 | E27: B2
A28: Vacature | B28: B1B2 | C28: Trainer/Coach B2
A29: Michel Sas | B29: B1B2 | C29: Teambegeleider
A30: Martijn van der Wiel | B30: B3 | C30: Trainer/Coach | D30: X | E30: C3 | F30: Medior
A31: Vacature | B31: B3 | C31: Trainer/Coach
A32: Laura Mol | B32: B4 | C32: Trainer/Coach | E32: B3
A33: Maud van Wensen | B33: B4 | C33: Trainer/Coach | D33: A1/A2 | E33: B3 | F33: Junior - KT2
A34: Nog in te vullen | B34: B4 | C34: Teambegeleider
A35: Antjan Laban | B35: C1 | C35: Trainer/Coach | D35: X | E35: C2 | F35: Senior
A36: Milou Oppe | B36: C1 | C36: Trainer/Coach | D36: S1/S2 | E36: B1 | F36: Junior - KT2
A37: Kimberley Witman | B37: C2 | C37: Trainer/Coach
A38: Robert Koster | B38: C2 | C38: Trainer/Coach | D38: X | E38: B3 | F38: Senior
A39: Senne Koster | B39: C2 | C39: Trainer/Coach
A40: Nadia de Wit | B40: C3 | C40: Trainer/Coach | D40: S7 | E40: C4 | F40: Junior
...

Sheet SCENARIO-KEUZE
B2: SPELERS - TEAMS
C3: Situatie | D3: Scenario 1 | E3: Scenario 2 | F3: Scenario 3 | G3: Keuze + argumentatie | H3: Consequenties | L3: TRAINERSINDELING | M3: Optie 1 | N3: Optie 2 | O3: Optie 3 | P3: Andere kandidaten | Q3: Keuze + argumentatie
L29: Ingevuld
L30: Opties / ideeën
L31: Open
B48: Ingevuld
B49: Opties
B50: Open

Sheet Aandachtpunten
A1: Categorie | B1: Aandachtspunten | C1: Onderwerp | D1: Antwoord | E1: Actiehouder | F1: Wanneer | G1: Status
A2: E/D | B2: Merlijn de Wit | C2: Stopt | D2: Definitief? Ja
A3: S1S2 | B3: Vera Klootwijk / Jaimy van Arkel | C3: Blijft?
A4: S1S2 | B4: Djuna | C4: Komt ze ooit nog terug
A5: S1S2 | B5: Iza Wolleswinkel | C5: Selectie?
A6: S1S2 | B6: Robin Domisse | C6: Blijft?
A7: S5S6 | B7: Elena - minimaal S5 .. Mogelijk plekje S1S2
A9: S4 | B9: Wat gaat Naakie doen?
B10: Collin van Vitesse (misschien S1S2)
A11: A1B1 | B11: Lars Visser | C11: Wat gaan alle Vissers doen?
B12: Onno den Dekker - Als A1 niet dan B1?
B13: Tijn Camphens - (ook) nog een jaar B1?
B14: Benthe van der Linden, stopt?
B15: Esmee / Tess samen of niet naar B2 | D15: Definitief naar C1
A16: C1C2 | B16: Finn Verboom - wat gaan we doen | C16: Stopt?
A17: E | B17: Sanae door naar D is fanatiek | D17: Zeker
A18: E | B18: Ralph nog een jaartje in E houden voor ontwikkeling
A19: E | B19: Gaat Suze stoppen?
B20: Joep en Sepp bij elkaar?
B61: Scenario 1. - nu
B62: Scenario 2 - Evie Groen door en Pippa naar D4
B63: Scenario 3 - Manon, Noortje en Evie naar C4 -met 17 kids + wedstrijdlid

Sheet Count
B2: Dames | C2: Aantal | E2: Heren | F2: Aantal | H2: Totaal
B3: K | C3: =COUNTIF(Spelerslijst!F:F,Count!B3) -> 1 | E3: K | F3: =COUNTIF(Spelerslijst!P:P,Count!E3) -> 4 | H3: =Tabel7[[#This Row],[Aantal]]+Tabel9[[#This Row],[Aantal]] -> 5
B4: F | C4: =COUNTIF(Spelerslijst!F:F,Count!B4) -> 8 | E4: F | F4: =COUNTIF(Spelerslijst!P:P,Count!E4) -> 7 | H4: =Tabel7[[#This Row],[Aantal]]+Tabel9[[#This Row],[Aantal]] -> 15 | J4: 2 | L4: F1 | M4: F2
B5: E | C5: =COUNTIF(Spelerslijst!F:F,Count!B5) -> 15 | E5: E | F5: =COUNTIF(Spelerslijst!P:P,Count!E5) -> 7 | H5: =Tabel7[[#This Row],[Aantal]]+Tabel9[[#This Row],[Aantal]] -> 22 | J5: 4 | L5: E1 | M5: E2 | N5: E3 | O5: E4
B6: D | C6: =COUNTIF(Spelerslijst!F:F,Count!B6) -> 20 | E6: D | F6: =COUNTIF(Spelerslijst!P:P,Count!E6) -> 21 | H6: =Tabel7[[#This Row],[Aantal]]+Tabel9[[#This Row],[Aantal]] -> 41 | J6: 4 | L6: D1 | M6: D2 | N6: D3 | O6: D4
B7: C | C7: =COUNTIF(Spelerslijst!F:F,Count!B7) -> 18 | E7: C | F7: =COUNTIF(Spelerslijst!P:P,Count!E7) -> 15 | H7: =Tabel7[[#This Row],[Aantal]]+Tabel9[[#This Row],[Aantal]] -> 33 | J7: 3 | L7: C1 | M7: C2 | N7: C3
B8: B | C8: =COUNTIF(Spelerslijst!F:F,Count!B8) -> 25 | E8: B | F8: =COUNTIF(Spelerslijst!P:P,Count!E8) -> 15 | H8: =Tabel7[[#This Row],[Aantal]]+Tabel9[[#This Row],[Aantal]] -> 40 | J8: 4 | L8: B1 | M8: B2 | N8: B3 | O8: B4
B9: A | C9: =COUNTIF(Spelerslijst!F:F,Count!B9) -> 14 | E9: A | F9: =COUNTIF(Spelerslijst!P:P,Count!E9) -> 18 | H9: =Tabel7[[#This Row],[Aantal]]+Tabel9[[#This Row],[Aantal]] -> 32 | J9: 3 | L9: A1 | M9: A2 | N9: A3
B10: S | C10: =COUNTIF(Spelerslijst!F:F,Count!B10) -> 64 | E10: S | F10: =COUNTIF(Spelerslijst!P:P,Count!E10) -> 64 | H10: =Tabel7[[#This Row],[Aantal]]+Tabel9[[#This Row],[Aantal]] -> 128 | J10: 8 | L10: 1 | M10: 2 | N10: 3 | O10: 4 | P10: 5 | Q10: 6 | R10: 7 | S10: MW1

Sheet Teams-deelversie
A2: Selecties | B2: S1S2 | E2: S5S6 | H2: A1A2 | K2: B1B2
B3: Dames | C3: Heren | E3: Dames | F3: Heren | H3: Dames | I3: Heren | K3: Dames | L3: Heren
B4: {=_xlfn._xlws.FILTER(Spelerslijst!$B:$B,Spelerslijst!$G:$G=B$2,"")} -> Demi van Dijk | C4: {=_xlfn._xlws.FILTER(Spelerslijst!$L:$L,Spelerslijst!$Q:$Q=B$2,"")} -> Bart Driesprong | E4: {=_xlfn._xlws.FILTER(Spelerslijst!$B:$B,Spelerslijst!$G:$G=E$2,"")} | F4: {=_xlfn._xlws.FILTER(Spelerslijst!$L:$L,Spelerslijst!$Q:$Q=E$2,"")} | H4: {=_xlfn._xlws.FILTER(Spelerslijst!$B:$B,Spelerslijst!$G:$G=H$2,"")} -> Amber de Haas | I4: {=_xlfn._xlws.FILTER(Spelerslijst!$L:$L,Spelerslijst!$Q:$Q=H$2,"")} -> Dani Heersping | K4: {=_xlfn._xlws.FILTER(Spelerslijst!$B:$B,Spelerslijst!$G:$G=K$2,"")} -> Danique van der Klooster | L4: {=_xlfn._xlws.FILTER(Spelerslijst!$L:$L,Spelerslijst!$Q:$Q=K$2,"")} -> Diederik Hovestadt
B5: Eva Teerds | C5: Bob Mans | H5: Benthe van der Linden | I5: Freek van Dongen | K5: Demi Engelfriet | L5: Jarno Bemer
B6: Iza Wolleswinkel | C6: Daniel den Uijl | H6: Carmen van der Klooster | I6: Jack Zwanenburg | K6: Demi Lindhout | L6: Jasper Sempel
B7: Lindi Fasbender | C7: Jens Lohuis | H7: Doeska Voorbij | I7: Jarno Valk | K7: Feline van de Burgt | L7: Jonas van de Ven
B8: Loïs Fernhout | C8: Joël Wietses | H8: Elize van de Burgt | I8: Jordi Vaartmans | K8: Floor Lohuis | L8: Kian Vliet
B9: Maud van Wensen | C9: Joeri van Dijk | H9: Lisa Reuvers | I9: Lars Visser | K9: Floortje Jongkind | L9: Niek Sas
B10: Meike Driesprong | C10: Jordan Timmer | H10: Merel Manduapessy | I10: Maarten Sas | K10: Githa Bemer | L10: Onno den Dekker
B11: Milou Oppe | C11: Marijn Klink | H11: Sophie Kilsdonk | I11: Niek Driesprong | K11: Julia Kleingeld | L11: Thomas Vos
B12: Robin Dommisse | C12: Olivier Klink | H12: Stella Verboom | I12: Seth van de Burgt | K12: Noa Stomp | L12: Timo Pichel
B13: Roos Groeneweg | C13: Robin van Kalkeren | I13: Tijn Bäcker
B14: Sara Boshoven | C14: Senne Koster | I14: Tijn Camphens
B15: Xanne Klink | C15: Tim van Gent | I15: Tycho Vliet
B17: {=_xlfn._xlws.FILTER(Staf!$C:$C,Staf!$B:$B='Teams-deelversie'!B2,"")} -> Trainer/Coach S1 | C17: {=_xlfn._xlws.FILTER(Staf!$A:$A,Staf!$B:$B='Teams-deelversie'!B2,"")} -> Bo van Hoof | E17: {=_xlfn._xlws.FILTER(Staf!$C:$C,Staf!$B:$B='Teams-deelversie'!E2,"")} | H17: {=_xlfn._xlws.FILTER(Staf!$C:$C,Staf!$B:$B='Teams-deelversie'!H2,"")} -> Trainer/Coach A1 | I17: {=_xlfn._xlws.FILTER(Staf!$A:$A,Staf!$B:$B='Teams-deelversie'!H2,"")} -> Rob van Dongen | K17: {=_xlfn._xlws.FILTER(Staf!$C:$C,Staf!$B:$B='Teams-deelversie'!K2,"")} -> Trainer/Coach B1 | L17: {=_xlfn._xlws.FILTER(Staf!$A:$A,Staf!$B:$B='Teams-deelversie'!K2,"")} -> Jasper Kleingeld
B18: Trainer/Coach S2 | C18: Arthyn Muller | H18: Trainer/Coach A1 | I18: Ruben Blokland | K18: Trainer/Coach B1 | L18: Mees Oppe
B19: Teambegeleider S1 | C19: Dionne Broere | H19: Trainer/Coach A2 | I19: Olivier Klink | K19: Trainer/Coach B2 | L19: Daniël den Uijl
B20: Teambegeleider S2 | C20: Fred Lichteveld | H20: Trainer/Coach A2 | I20: Tim van Gent | K20: Trainer/Coach B2 | L20: Eva Teerds
B21: Analist S1 | C21: Joris van den Neucker | H21: Teambegeleider | I21: Alex van de Klooster | K21: Trainer/Coach B2 | L21: Vacature
B22: Fysio | C22: Ruben Kamerbeek | K22: Teambegeleider | L22: Michel Sas
B23: Verzorger | C23: Theo Anrochte
A26: Senioren | B26: S1 | E26: S2 | H26: S3 | K26: S4 | N26: S5 | Q26: S6 | T26: S7 | AA26: MW1
B27: Dames | C27: Heren | E27: Dames | F27: Heren | H27: Dames | I27: Heren | K27: Dames | L27: Heren | N27: Dames | O27: Heren | Q27: Dames | R27: Heren | T27: Dames | W27: Heren | AA27: Dames | AB27: Heren
B28: {=_xlfn._xlws.FILTER(Spelerslijst!$B:$B,Spelerslijst!$G:$G=B$26,"")} | C28: {=_xlfn._xlws.FILTER(Spelerslijst!$L:$L,Spelerslijst!$Q:$Q=B$26,"")} | E28: {=_xlfn._xlws.FILTER(Spelerslijst!$B:$B,Spelerslijst!$G:$G=E$26,"")} | F28: {=_xlfn._xlws.FILTER(Spelerslijst!$L:$L,Spelerslijst!$Q:$Q=E$26,"")} | H28: {=_xlfn._xlws.FILTER(Spelerslijst!$B:$B,Spelerslijst!$G:$G=H$26,"")} -> Esther Ardon | I28: {=_xlfn._xlws.FILTER(Spelerslijst!$L:$L,Spelerslijst!$Q:$Q=H$26,"")} -> Emiel Houwerzijl | K28: {=_xlfn._xlws.FILTER(Spelerslijst!$B:$B,Spelerslijst!$G:$G=K$26,"")} -> ~Dame S1S2 | L28: {=_xlfn._xlws.FILTER(Spelerslijst!$L:$L,Spelerslijst!$Q:$Q=K$26,"")} -> ~Heer S1S2 | N28: {=_xlfn._xlws.FILTER(Spelerslijst!$B:$B,Spelerslijst!$G:$G=N$26,"")} -> Anniek Pierse | O28: {=_xlfn._xlws.FILTER(Spelerslijst!$L:$L,Spelerslijst!$Q:$Q=N$26,"")} -> Joram Flach | Q28: {=_xlfn._xlws.FILTER(Spelerslijst!$B:$B,Spelerslijst!$G:$G=Q$26,"")} -> Amber Boeije | R28: {=_xlfn._xlws.FILTER(Spelerslijst!$L:$L,Spelerslijst!$Q:$Q=Q$26,"")} -> Ché Kooper | T28: {=_xlfn._xlws.FILTER(Spelerslijst!$B:$B,Spelerslijst!$G:$G=T$26,"")} | W28: {=_xlfn._xlws.FILTER(Spelerslijst!$L:$L,Spelerslijst!$Q:$Q=T$26,"")} | AA28: {=_xlfn._xlws.FILTER(Spelerslijst!$B:$B,Spelerslijst!$G:$G=AA$26,"")} -> Dorien in 't Veld | AB28: {=_xlfn._xlws.FILTER(Spelerslijst!$L:$L,Spelerslijst!$Q:$Q=AA$26,"")} -> Hans Ploeg
H29: Hilde Visser | I29: Jan Booy | K29: ~Dame S1S2 | L29: ~Heer S1S2 | N29: Jany Lacroes | O29: Laurens Verhagen | Q29: Angela Friebel | R29: David Kuijper | AA29: Kim Heesterbeek | AB29: Michiel 't Jong
H30: Lieke Ploeg | I30: Lex van Gent | K30: Anouk de Jongh | L30: Luuk Baars | N30: Lara Schram | O30: Mark Schindler | Q30: Jennifer Herremans | R30: Jens de Vlaming | AA30: Kim van der Starre-Scheurwater | AB30: Ronald Riet
H31: Linda Ardon | I31: Roy de Vlaming | K31: Carlijn Lievaart | L31: Tijmen Fasbender | N31: Laura Koote | O31: Quinten van Driel | Q31: Kimberley Witman | R31: Ruben Dubbeld | AA31: Liesbeth Brand | AB31: Wilco Kooij
H32: Merel van Gurp | I32: Thomas Isarin | K32: Elena Quarré | L32: Tim Seevinck | N32: Marlies Valk | O32: Rick van de Wijgaart | Q32: Sanne Dubbeld | R32: Thijs Boon | AA32: Tamara van Opstal-Haksteen
H33: Robin Leijdsman | K33: Kim Dommisse | N33: Nadia de Wit | Q33: Tessa Dubbeld | R33: Wouter Koornneef
K34: Laura Mol | N34: Syrah de Wit
B36: {=_xlfn._xlws.FILTER(Staf!$C:$C,Staf!$B:$B='Teams-deelversie'!B26,"")} | E36: {=_xlfn._xlws.FILTER(Staf!$C:$C,Staf!$B:$B='Teams-deelversie'!E26,"")} | H36: {=_xlfn._xlws.FILTER(Staf!$C:$C,Staf!$B:$B='Teams-deelversie'!H26,"")} -> Begeleider | I36: {=_xlfn._xlws.FILTER(Staf!$A:$A,Staf!$B:$B='Teams-deelversie'!H26,"")} -> Kim Ardon | K36: {=_xlfn._xlws.FILTER(Staf!$C:$C,Staf!$B:$B='Teams-deelversie'!K26,"")} -> Trainer/Coach | L36: {=_xlfn._xlws.FILTER(Staf!$A:$A,Staf!$B:$B='Teams-deelversie'!K26,"")} -> Vacature | N36: {=_xlfn._xlws.FILTER(Staf!$C:$C,Staf!$B:$B='Teams-deelversie'!N26,"")} -> Trainer/Coach | O36: {=_xlfn._xlws.FILTER(Staf!$A:$A,Staf!$B:$B='Teams-deelversie'!N26,"")} -> Vacature | Q36: {=_xlfn._xlws.FILTER(Staf!$C:$C,Staf!$B:$B='Teams-deelversie'!Q26,"")} -> Trainer/Coach | R36: {=_xlfn._xlws.FILTER(Staf!$A:$A,Staf!$B:$B='Teams-deelversie'!Q26,"")} -> Monique Kooper | T36: {=_xlfn._xlws.FILTER(Staf!$C:$C,Staf!$B:$B='Teams-deelversie'!T26,"")} | U36: {=_xlfn._xlws.FILTER(Staf!$A:$A,Staf!$B:$B='Teams-deelversie'!T26,"")} | AA36: {=_xlfn._xlws.FILTER(Staf!$C:$C,Staf!$B:$B='Teams-deelversie'!AA26,"")}
K37: Trainer/Coach | L37: Vacature
A39: A-Junioren | B39: A1 | E39: A2 | H39: A3 | K39: A4 | N39: A5
B40: Dames | C40: Heren | E40: Dames | F40: Heren | H40: Dames | I40: Heren | K40: Dames | L40: Heren | N40: Dames | O40: Heren
B41: {=_xlfn._xlws.FILTER(Spelerslijst!$B:$B,Spelerslijst!$G:$G=B$39,"")} | C41: {=_xlfn._xlws.FILTER(Spelerslijst!$L:$L,Spelerslijst!$Q:$Q=B$39,"")} | E41: {=_xlfn._xlws.FILTER(Spelerslijst!$B:$B,Spelerslijst!$G:$G=E$39,"")} | F41: {=_xlfn._xlws.FILTER(Spelerslijst!$L:$L,Spelerslijst!$Q:$Q=E$39,"")} | H41: {=_xlfn._xlws.FILTER(Spelerslijst!$B:$B,Spelerslijst!$G:$G=H$39,"")} -> Julia Bozuwa | I41: {=_xlfn._xlws.FILTER(Spelerslijst!$L:$L,Spelerslijst!$Q:$Q=H$39,"")} -> Casper Boshoven | K41: {=_xlfn._xlws.FILTER(Spelerslijst!$B:$B,Spelerslijst!$G:$G=K$39,"")} | L41: {=_xlfn._xlws.FILTER(Spelerslijst!$L:$L,Spelerslijst!$Q:$Q=K$39,"")} | N41: {=_xlfn._xlws.FILTER(Spelerslijst!$B:$B,Spelerslijst!$G:$G=N$39,"")} | O41: {=_xlfn._xlws.FILTER(Spelerslijst!$L:$L,Spelerslijst!$Q:$Q=N$39,"")}
H42: Lianne Bouwknegt | I42: Matthijs de Jongh
H43: Robin Zwanenburg | I43: Menno Pille
H44: Tessa van Everdingen | I44: Raoul Kuijper
H45: Vivienne Versnel | I45: Tommie Koornneef
H46: Zoë Kamerman
...

Sheet Stoppers
A1: Rel.nr | B1: Naam & Initialen) | C1: Roepnaam | D1: Leeftijd Peildatum | E1: Geb datum | F1: Team op Peildatum | G1: Team 20-21 | I1: Rel.nr | J1: Naam & Initialen) | K1: Roepnaam | L1: Leeftijd Peildatum | M1: Geb datum | N1: Team op Peildatum | O1: Team 20-21
A2: {=_xlfn._xlws.FILTER(Spelerslijst!A:A,Spelerslijst!$G:$G="Stopt","")} -> NKS24S7 | B2: {=_xlfn._xlws.FILTER(Spelerslijst!B:B,Spelerslijst!$G:$G="Stopt","")} -> Bente van Wijngaarden | C2: {=_xlfn._xlws.FILTER(Spelerslijst!C:C,Spelerslijst!$G:$G="Stopt","")} -> Bente | D2: {=_xlfn._xlws.FILTER(Spelerslijst!D:D,Spelerslijst!$G:$G="Stopt","")} -> 18 | E2: {=_xlfn._xlws.FILTER(Spelerslijst!E:E,Spelerslijst!$G:$G="Stopt","")} -> 38928 | F2: {=_xlfn._xlws.FILTER(Spelerslijst!F:F,Spelerslijst!$G:$G="Stopt","")} -> A | G2: {=_xlfn._xlws.FILTER(Spelerslijst!G:G,Spelerslijst!$G:$G="Stopt","")} -> Stopt | I2: {=_xlfn._xlws.FILTER(Spelerslijst!K:K,Spelerslijst!$Q:$Q="Stopt","")} -> NFW26G8 | J2: {=_xlfn._xlws.FILTER(Spelerslijst!L:L,Spelerslijst!$Q:$Q="Stopt","")} -> Arjan Noels | K2: {=_xlfn._xlws.FILTER(Spelerslijst!M:M,Spelerslijst!$Q:$Q="Stopt","")} -> Arjan | L2: {=_xlfn._xlws.FILTER(Spelerslijst!N:N,Spelerslijst!$Q:$Q="Stopt","")} -> 44 | M2: {=_xlfn._xlws.FILTER(Spelerslijst!O:O,Spelerslijst!$Q:$Q="Stopt","")} -> 29523 | N2: {=_xlfn._xlws.FILTER(Spelerslijst!P:P,Spelerslijst!$Q:$Q="Stopt","")} -> S | O2: {=_xlfn._xlws.FILTER(Spelerslijst!Q:Q,Spelerslijst!$Q:$Q="Stopt","")} -> Stopt
A3: NKR88F7 | B3: Bridget ter Horst | C3: Bridget | D3: 21 | E3: 37771 | F3: S | G3: Stopt | I3: NMV76G1 | J3: Art Malschaert | K3: Art | L3: 7 | M3: 42955 | N3: F | O3: Stopt
A4: NML00R5 | B4: Bryanna Bos | C4: Bryanna | D4: 14 | E4: 40373 | F4: B | G4: Stopt | I4: NFS90V6 | J4: Bart de Wit | K4: Bart | L4: 45 | M4: 29031 | N4: S | O4: Stopt
A5: NJC15T9 | B5: Diana Visser-Michelsen | C5: Diana | D5: 32 | E5: 33777 | F5: S | G5: Stopt | I5: NMQ44L0 | J5: Cas Tieleman | K5: Cas | L5: 20 | M5: 38220 | N5: S | O5: Stopt
A6: NMR70L4 | B6: Diede van den Boogaart | C6: Diede | D6: 6 | E6: 43409 | F6: F | G6: Stopt | I6: NMX21V8 | J6: Ciprian Minzararu | K6: Ciprian | L6: 8 | M6: 42507 | N6: E | O6: Stopt
A7: NMX01Q3 | B7: Elize Bohms | C7: Elize | D7: 12 | E7: 41223 | F7: C | G7: Stopt | I7: NFW26Q8 | J7: Egbert Vos | K7: Egbert | L7: 43 | M7: 29725 | N7: S | O7: Stopt
A8: NMQ57Y5 | B8: Feliz Lanser | C8: Feliz | D8: 9 | E8: 42333 | F8: E | G8: Stopt | I8: NMG03C4 | J8: Finn Verboom | K8: Finn | L8: 12 | M8: 40974 | N8: C | O8: Stopt
A9: NLL19T4 | B9: Mila de Wit | C9: Mila | D9: 17 | E9: 39433 | F9: A | G9: Stopt | I9: NJB54T5 | J9: Jaimy van Arkel | K9: Jaimy | L9: 27 | M9: 35451 | N9: S | O9: Stopt
A10: NMT10Q1 | B10: Mirjam de Wit | C10: Mirjam | D10: 44 | E10: 29257 | F10: S | G10: Stopt | I10: NFW14Y3 | J10: Jan-Peter Verwaal | K10: Jan-Peter | L10: 55 | M10: 25273 | N10: S | O10: Stopt
A11: NJK27R4 | B11: Sanne van Andel | C11: Sanne | D11: 36 | E11: 32143 | F11: S | G11: Stopt | I11: NML47R6 | J11: Maarten Rutten | K11: Maarten | L11: 14 | M11: 40227 | N11: B | O11: Stopt
A12: NKL40B9 | B12: Vera Klootwijk | C12: Vera | D12: 22 | E12: 37410 | F12: S | G12: Stopt | I12: NMJ57G2 | J12: Merlijn de Wit | K12: Merlijn | L12: 10 | M12: 41801 | N12: D | O12: Stopt
I13: NFZ85W0 | J13: Peter Batenburg | K13: Peter | L13: 42 | M13: 30083 | N13: S | O13: Stopt
I14: NJH51W3 | J14: Peter Berendsen | K14: Peter | L14: 27 | M14: 35488 | N14: S | O14: Stopt
I15: NFW13G4 | J15: Sebastiaan Belder | K15: Sebastiaan | L15: 44 | M15: 29221 | N15: S | O15: Stopt
I16: NGT16K5 | J16: Stefan Naaktgeboren | K16: Stefan | L16: 33 | M16: 33241 | N16: S | O16: Stopt
I17: NMS76D7 | J17: Vince van der Hoeven | K17: Vince | L17: 12 | M17: 41263 | N17: C | O17: Stopt

Sheet vraagtekens
A1: Rel.nr | B1: Naam & Initialen) | C1: Roepnaam | D1: Leeftijd Peildatum | E1: Geb datum | F1: Team op Peildatum | G1: Team 20-21 | I1: Rel.nr | J1: Naam & Initialen) | K1: Roepnaam | L1: Leeftijd Peildatum | M1: Geb datum | N1: Team op Peildatum | O1: Team 20-21
A2: {=_xlfn._xlws.FILTER(Spelerslijst!A:A,Spelerslijst!$G:$G="?","")} -> NMW65S8 | B2: {=_xlfn._xlws.FILTER(Spelerslijst!B:B,Spelerslijst!$G:$G="?","")} -> Annelieke Smouter | C2: {=_xlfn._xlws.FILTER(Spelerslijst!C:C,Spelerslijst!$G:$G="?","")} -> Annelieke | D2: {=_xlfn._xlws.FILTER(Spelerslijst!D:D,Spelerslijst!$G:$G="?","")} -> 25 | E2: {=_xlfn._xlws.FILTER(Spelerslijst!E:E,Spelerslijst!$G:$G="?","")} -> 36522 | F2: {=_xlfn._xlws.FILTER(Spelerslijst!F:F,Spelerslijst!$G:$G="?","")} -> S | G2: {=_xlfn._xlws.FILTER(Spelerslijst!G:G,Spelerslijst!$G:$G="?","")} -> ? | I2: {=_xlfn._xlws.FILTER(Spelerslijst!K:K,Spelerslijst!$Q:$Q="?","")} | J2: {=_xlfn._xlws.FILTER(Spelerslijst!L:L,Spelerslijst!$Q:$Q="?","")} | K2: {=_xlfn._xlws.FILTER(Spelerslijst!M:M,Spelerslijst!$Q:$Q="?","")} | L2: {=_xlfn._xlws.FILTER(Spelerslijst!N:N,Spelerslijst!$Q:$Q="?","")} | M2: {=_xlfn._xlws.FILTER(Spelerslijst!O:O,Spelerslijst!$Q:$Q="?","")} | N2: {=_xlfn._xlws.FILTER(Spelerslijst!P:P,Spelerslijst!$Q:$Q="?","")} | O2: {=_xlfn._xlws.FILTER(Spelerslijst!Q:Q,Spelerslijst!$Q:$Q="?","")}
A3: NKX20W8 | B3: Flore Steenks | C3: Flore | D3: 20 | E3: 38263 | F3: S | G3: ?
A4: NGG54V3 | B4: Hanneke Batenburg | C4: Hanneke | D4: 37 | E4: 32050 | F4: S | G4: ?
A5: NJC72L4 | B5: Nada Hussein | C5: Nada | D5: 34 | E5: 32945 | F5: S | G5: ?
A6: NJQ72J4 | B6: Simone van Zwoll | C6: Simone | D6: 30 | E6: 34635 | F6: S | G6: ?

Sheet check bond 160124
A1: Check V | B1: Check M | C1: Check | D1: Relatiecode | E1: Volledige naam (2) | F1: Roepnaam | G1: Geboortedatum | H1: Lidmaatschapcode | I1: Status | J1: Geslacht
A2: =_xlfn.IFNA(VLOOKUP(D2,Spelerslijst!A:B,1,FALSE),FALSE) -> FALSE | B2: =_xlfn.IFNA(VLOOKUP(D2,Spelerslijst!K:L,1,FALSE),FALSE) -> NFS90V6 | C2: =IF(AND(A2=FALSE,B2=FALSE),"Onbekend","") | D2: NFS90V6 | E2: Bart de Wit | F2: Bart | G2: 29031 | H2: 200 | I2: definitief | J2: M
A3: =_xlfn.IFNA(VLOOKUP(D3,Spelerslijst!A:B,1,FALSE),FALSE) -> FALSE | B3: =_xlfn.IFNA(VLOOKUP(D3,Spelerslijst!K:L,1,FALSE),FALSE) -> NFV13V8 | C3: =IF(AND(A3=FALSE,B3=FALSE),"Onbekend","") | D3: NFV13V8 | E3: Ronald Riet | F3: Ronald | G3: 30397 | H3: 203 | I3: definitief | J3: M
A4: =_xlfn.IFNA(VLOOKUP(D4,Spelerslijst!A:B,1,FALSE),FALSE) -> FALSE | B4: =_xlfn.IFNA(VLOOKUP(D4,Spelerslijst!K:L,1,FALSE),FALSE) -> NFW13Y0 | C4: =IF(AND(A4=FALSE,B4=FALSE),"Onbekend","") | D4: NFW13Y0 | E4: Marco van Kalkeren | F4: Marco | G4: 25227 | H4: 203 | I4: definitief | J4: M
A5: =_xlfn.IFNA(VLOOKUP(D5,Spelerslijst!A:B,1,FALSE),FALSE) -> FALSE | B5: =_xlfn.IFNA(VLOOKUP(D5,Spelerslijst!K:L,1,FALSE),FALSE) -> NFW14Y3 | C5: =IF(AND(A5=FALSE,B5=FALSE),"Onbekend","") | D5: NFW14Y3 | E5: Jan-Peter Verwaal | F5: Jan-Peter | G5: 25273 | H5: 202 | I5: definitief | J5: M
A6: =_xlfn.IFNA(VLOOKUP(D6,Spelerslijst!A:B,1,FALSE),FALSE) -> FALSE | B6: =_xlfn.IFNA(VLOOKUP(D6,Spelerslijst!K:L,1,FALSE),FALSE) -> NFW15F3 | C6: =IF(AND(A6=FALSE,B6=FALSE),"Onbekend","") | D6: NFW15F3 | E6: Johan van der Wall | F6: Johan | G6: 24003 | H6: 202 | I6: definitief | J6: M
A7: =_xlfn.IFNA(VLOOKUP(D7,Spelerslijst!A:B,1,FALSE),FALSE) -> NFW15S4 | B7: =_xlfn.IFNA(VLOOKUP(D7,Spelerslijst!K:L,1,FALSE),FALSE) -> FALSE | C7: =IF(AND(A7=FALSE,B7=FALSE),"Onbekend","") | D7: NFW15S4 | E7: Debita Moerman | F7: Debita | G7: 28329 | H7: 202 | I7: definitief | J7: V
